[2024-07-30T11:31:54.730+0000] {local_task_job_runner.py:120} INFO - ::group::Pre task execution logs
[2024-07-30T11:31:54.758+0000] {taskinstance.py:2076} INFO - Dependencies all met for dep_context=non-requeueable deps ti=<TaskInstance: enrich_prod.oneforall.join_data manual__2024-07-30T11:31:17.990749+00:00 [queued]>
[2024-07-30T11:31:54.770+0000] {taskinstance.py:2076} INFO - Dependencies all met for dep_context=requeueable deps ti=<TaskInstance: enrich_prod.oneforall.join_data manual__2024-07-30T11:31:17.990749+00:00 [queued]>
[2024-07-30T11:31:54.771+0000] {taskinstance.py:2306} INFO - Starting attempt 1 of 1
[2024-07-30T11:31:54.795+0000] {taskinstance.py:2330} INFO - Executing <Task(PythonOperator): oneforall.join_data> on 2024-07-30 11:31:17.990749+00:00
[2024-07-30T11:31:54.804+0000] {warnings.py:112} WARNING - /home/***/.local/lib/python3.12/site-packages/***/task/task_runner/standard_task_runner.py:62: DeprecationWarning: This process (pid=3952) is multi-threaded, use of fork() may lead to deadlocks in the child.
  pid = os.fork()

[2024-07-30T11:31:54.805+0000] {standard_task_runner.py:64} INFO - Started process 3954 to run task
[2024-07-30T11:31:54.806+0000] {standard_task_runner.py:90} INFO - Running: ['***', 'tasks', 'run', 'enrich_prod', 'oneforall.join_data', 'manual__2024-07-30T11:31:17.990749+00:00', '--job-id', '681', '--raw', '--subdir', 'DAGS_FOLDER/gps/custom_dags/enrich.py', '--cfg-path', '/tmp/tmpne0ufv85']
[2024-07-30T11:31:54.809+0000] {standard_task_runner.py:91} INFO - Job 681: Subtask oneforall.join_data
[2024-07-30T11:31:54.855+0000] {task_command.py:426} INFO - Running <TaskInstance: enrich_prod.oneforall.join_data manual__2024-07-30T11:31:17.990749+00:00 [running]> on host 7d7c82e77e1e
[2024-07-30T11:31:54.962+0000] {taskinstance.py:2648} INFO - Exporting env vars: AIRFLOW_CTX_DAG_EMAIL='richmond.kongo@orange.com,assane.diop@orange.com,cyrille1.danho@orange.com,mohamed2.sylla@orange.com,amadou.diomande@orange.com,Jonas.kouame@orange.com,armand.kablan@orange.com,anicet.azombade@orange.com,etienne.kouadio@orange.com,bertine.kouakou@orange.com,florentine.kouakou@orange.com,ange.phaceli@orange.com,soulegame.soro@orange.com,innocent.yengo@orange.com' AIRFLOW_CTX_DAG_OWNER='***' AIRFLOW_CTX_DAG_ID='enrich_prod' AIRFLOW_CTX_TASK_ID='oneforall.join_data' AIRFLOW_CTX_EXECUTION_DATE='2024-07-30T11:31:17.990749+00:00' AIRFLOW_CTX_TRY_NUMBER='1' AIRFLOW_CTX_DAG_RUN_ID='manual__2024-07-30T11:31:17.990749+00:00'
[2024-07-30T11:31:54.963+0000] {taskinstance.py:430} INFO - ::endgroup::
[2024-07-30T11:31:55.147+0000] {enrich.py:172} INFO - merge bdd and CA
[2024-07-30T11:31:55.153+0000] {enrich.py:175} INFO - add opex
[2024-07-30T11:31:55.153+0000] {taskinstance.py:441} INFO - ::group::Post task execution logs
[2024-07-30T11:31:55.153+0000] {taskinstance.py:2905} ERROR - Task failed with exception
Traceback (most recent call last):
  File "/home/airflow/.local/lib/python3.12/site-packages/airflow/models/taskinstance.py", line 465, in _execute_task
    result = _execute_callable(context=context, **execute_callable_kwargs)
             ^^^^^^^^^^^^^^^^^^^^^^^^^^^^^^^^^^^^^^^^^^^^^^^^^^^^^^^^^^^^^
  File "/home/airflow/.local/lib/python3.12/site-packages/airflow/models/taskinstance.py", line 432, in _execute_callable
    return execute_callable(context=context, **execute_callable_kwargs)
           ^^^^^^^^^^^^^^^^^^^^^^^^^^^^^^^^^^^^^^^^^^^^^^^^^^^^^^^^^^^^
  File "/home/airflow/.local/lib/python3.12/site-packages/airflow/models/baseoperator.py", line 401, in wrapper
    return func(self, *args, **kwargs)
           ^^^^^^^^^^^^^^^^^^^^^^^^^^^
  File "/home/airflow/.local/lib/python3.12/site-packages/airflow/operators/python.py", line 235, in execute
    return_value = self.execute_callable()
                   ^^^^^^^^^^^^^^^^^^^^^^^
  File "/home/airflow/.local/lib/python3.12/site-packages/airflow/operators/python.py", line 252, in execute_callable
    return self.python_callable(*self.op_args, **self.op_kwargs)
           ^^^^^^^^^^^^^^^^^^^^^^^^^^^^^^^^^^^^^^^^^^^^^^^^^^^^^
  File "/opt/airflow/dags/gps/custom_dags/enrich.py", line 111, in gen_oneforall
    data = oneforall(
          ^^^^^^^^^^
  File "/opt/airflow/dags/gps/common/enrich.py", line 176, in oneforall
    bdd_ca_ihs = bdd_ca.merge(ihs, left_on=[ "autre code", "mois"], right_on=[ "site id ihs", "mois"], how="left")
                              ^^^
UnboundLocalError: cannot access local variable 'ihs' where it is not associated with a value
[2024-07-30T11:31:55.164+0000] {taskinstance.py:1206} INFO - Marking task as FAILED. dag_id=enrich_prod, task_id=oneforall.join_data, run_id=manual__2024-07-30T11:31:17.990749+00:00, execution_date=20240730T113117, start_date=20240730T113154, end_date=20240730T113155
[2024-07-30T11:31:55.179+0000] {warnings.py:112} WARNING - /home/***/.local/lib/python3.12/site-packages/***/utils/email.py:154: RemovedInAirflow3Warning: Fetching SMTP credentials from configuration variables will be deprecated in a future release. Please set credentials using a connection instead.
  send_mime_email(e_from=mail_from, e_to=recipients, mime_msg=msg, conn_id=conn_id, dryrun=dryrun)

[2024-07-30T11:31:55.180+0000] {configuration.py:1053} WARNING - section/key [smtp/smtp_user] not found in config
[2024-07-30T11:31:55.180+0000] {email.py:271} INFO - Email alerting: attempt 1
[2024-07-30T11:31:55.188+0000] {configuration.py:1053} WARNING - section/key [smtp/smtp_user] not found in config
[2024-07-30T11:31:55.189+0000] {email.py:271} INFO - Email alerting: attempt 1
[2024-07-30T11:31:55.190+0000] {taskinstance.py:879} ERROR - Failed to send email to: ['richmond.kongo@orange.com', 'assane.diop@orange.com', 'cyrille1.danho@orange.com', 'mohamed2.sylla@orange.com', 'amadou.diomande@orange.com', 'Jonas.kouame@orange.com', 'armand.kablan@orange.com', 'anicet.azombade@orange.com', 'etienne.kouadio@orange.com', 'bertine.kouakou@orange.com', 'florentine.kouakou@orange.com', 'ange.phaceli@orange.com', 'soulegame.soro@orange.com', 'innocent.yengo@orange.com']
Traceback (most recent call last):
  File "/home/airflow/.local/lib/python3.12/site-packages/airflow/models/taskinstance.py", line 2479, in _run_raw_task
    self._execute_task_with_callbacks(context, test_mode, session=session)
  File "/home/airflow/.local/lib/python3.12/site-packages/airflow/models/taskinstance.py", line 2676, in _execute_task_with_callbacks
    result = self._execute_task(context, task_orig)
             ^^^^^^^^^^^^^^^^^^^^^^^^^^^^^^^^^^^^^^
  File "/home/airflow/.local/lib/python3.12/site-packages/airflow/models/taskinstance.py", line 2701, in _execute_task
    return _execute_task(self, context, task_orig)
           ^^^^^^^^^^^^^^^^^^^^^^^^^^^^^^^^^^^^^^^
  File "/home/airflow/.local/lib/python3.12/site-packages/airflow/models/taskinstance.py", line 465, in _execute_task
    result = _execute_callable(context=context, **execute_callable_kwargs)
             ^^^^^^^^^^^^^^^^^^^^^^^^^^^^^^^^^^^^^^^^^^^^^^^^^^^^^^^^^^^^^
  File "/home/airflow/.local/lib/python3.12/site-packages/airflow/models/taskinstance.py", line 432, in _execute_callable
    return execute_callable(context=context, **execute_callable_kwargs)
           ^^^^^^^^^^^^^^^^^^^^^^^^^^^^^^^^^^^^^^^^^^^^^^^^^^^^^^^^^^^^
  File "/home/airflow/.local/lib/python3.12/site-packages/airflow/models/baseoperator.py", line 401, in wrapper
    return func(self, *args, **kwargs)
           ^^^^^^^^^^^^^^^^^^^^^^^^^^^
  File "/home/airflow/.local/lib/python3.12/site-packages/airflow/operators/python.py", line 235, in execute
    return_value = self.execute_callable()
                   ^^^^^^^^^^^^^^^^^^^^^^^
  File "/home/airflow/.local/lib/python3.12/site-packages/airflow/operators/python.py", line 252, in execute_callable
    return self.python_callable(*self.op_args, **self.op_kwargs)
           ^^^^^^^^^^^^^^^^^^^^^^^^^^^^^^^^^^^^^^^^^^^^^^^^^^^^^
  File "/opt/airflow/dags/gps/custom_dags/enrich.py", line 111, in gen_oneforall
    data = oneforall(
          ^^^^^^^^^^
  File "/opt/airflow/dags/gps/common/enrich.py", line 176, in oneforall
    bdd_ca_ihs = bdd_ca.merge(ihs, left_on=[ "autre code", "mois"], right_on=[ "site id ihs", "mois"], how="left")
                              ^^^
UnboundLocalError: cannot access local variable 'ihs' where it is not associated with a value

During handling of the above exception, another exception occurred:

Traceback (most recent call last):
  File "/home/airflow/.local/lib/python3.12/site-packages/airflow/models/taskinstance.py", line 1063, in _email_alert
    send_email(task.email, subject, html_content)
  File "/home/airflow/.local/lib/python3.12/site-packages/airflow/utils/email.py", line 80, in send_email
    return backend(
           ^^^^^^^^
  File "/home/airflow/.local/lib/python3.12/site-packages/airflow/utils/email.py", line 154, in send_email_smtp
    send_mime_email(e_from=mail_from, e_to=recipients, mime_msg=msg, conn_id=conn_id, dryrun=dryrun)
  File "/home/airflow/.local/lib/python3.12/site-packages/airflow/utils/email.py", line 273, in send_mime_email
    smtp_conn = _get_smtp_connection(smtp_host, smtp_port, smtp_timeout, smtp_ssl)
                ^^^^^^^^^^^^^^^^^^^^^^^^^^^^^^^^^^^^^^^^^^^^^^^^^^^^^^^^^^^^^^^^^^
  File "/home/airflow/.local/lib/python3.12/site-packages/airflow/utils/email.py", line 317, in _get_smtp_connection
    return smtplib.SMTP(host=host, port=port, timeout=timeout)
           ^^^^^^^^^^^^^^^^^^^^^^^^^^^^^^^^^^^^^^^^^^^^^^^^^^^
  File "/usr/local/lib/python3.12/smtplib.py", line 255, in __init__
    (code, msg) = self.connect(host, port)
                  ^^^^^^^^^^^^^^^^^^^^^^^^
  File "/usr/local/lib/python3.12/smtplib.py", line 341, in connect
    self.sock = self._get_socket(host, port, self.timeout)
                ^^^^^^^^^^^^^^^^^^^^^^^^^^^^^^^^^^^^^^^^^^
  File "/usr/local/lib/python3.12/smtplib.py", line 312, in _get_socket
    return socket.create_connection((host, port), timeout,
           ^^^^^^^^^^^^^^^^^^^^^^^^^^^^^^^^^^^^^^^^^^^^^^^
  File "/usr/local/lib/python3.12/socket.py", line 853, in create_connection
    raise exceptions[0]
  File "/usr/local/lib/python3.12/socket.py", line 838, in create_connection
    sock.connect(sa)
ConnectionRefusedError: [Errno 111] Connection refused

During handling of the above exception, another exception occurred:

Traceback (most recent call last):
  File "/home/airflow/.local/lib/python3.12/site-packages/airflow/models/taskinstance.py", line 877, in _handle_failure
    task_instance.email_alert(error, failure_context["task"])
  File "/home/airflow/.local/lib/python3.12/site-packages/airflow/models/taskinstance.py", line 3163, in email_alert
    _email_alert(task_instance=self, exception=exception, task=task)
  File "/home/airflow/.local/lib/python3.12/site-packages/airflow/models/taskinstance.py", line 1065, in _email_alert
    send_email(task.email, subject, html_content_err)
  File "/home/airflow/.local/lib/python3.12/site-packages/airflow/utils/email.py", line 80, in send_email
    return backend(
           ^^^^^^^^
  File "/home/airflow/.local/lib/python3.12/site-packages/airflow/utils/email.py", line 154, in send_email_smtp
    send_mime_email(e_from=mail_from, e_to=recipients, mime_msg=msg, conn_id=conn_id, dryrun=dryrun)
  File "/home/airflow/.local/lib/python3.12/site-packages/airflow/utils/email.py", line 273, in send_mime_email
    smtp_conn = _get_smtp_connection(smtp_host, smtp_port, smtp_timeout, smtp_ssl)
                ^^^^^^^^^^^^^^^^^^^^^^^^^^^^^^^^^^^^^^^^^^^^^^^^^^^^^^^^^^^^^^^^^^
  File "/home/airflow/.local/lib/python3.12/site-packages/airflow/utils/email.py", line 317, in _get_smtp_connection
    return smtplib.SMTP(host=host, port=port, timeout=timeout)
           ^^^^^^^^^^^^^^^^^^^^^^^^^^^^^^^^^^^^^^^^^^^^^^^^^^^
  File "/usr/local/lib/python3.12/smtplib.py", line 255, in __init__
    (code, msg) = self.connect(host, port)
                  ^^^^^^^^^^^^^^^^^^^^^^^^
  File "/usr/local/lib/python3.12/smtplib.py", line 341, in connect
    self.sock = self._get_socket(host, port, self.timeout)
                ^^^^^^^^^^^^^^^^^^^^^^^^^^^^^^^^^^^^^^^^^^
  File "/usr/local/lib/python3.12/smtplib.py", line 312, in _get_socket
    return socket.create_connection((host, port), timeout,
           ^^^^^^^^^^^^^^^^^^^^^^^^^^^^^^^^^^^^^^^^^^^^^^^
  File "/usr/local/lib/python3.12/socket.py", line 853, in create_connection
    raise exceptions[0]
  File "/usr/local/lib/python3.12/socket.py", line 838, in create_connection
    sock.connect(sa)
ConnectionRefusedError: [Errno 111] Connection refused
[2024-07-30T11:31:55.209+0000] {standard_task_runner.py:110} ERROR - Failed to execute job 681 for task oneforall.join_data (cannot access local variable 'ihs' where it is not associated with a value; 3954)
[2024-07-30T11:31:55.260+0000] {local_task_job_runner.py:243} INFO - Task exited with return code 1
[2024-07-30T11:31:55.269+0000] {local_task_job_runner.py:222} INFO - ::endgroup::
