[2024-07-22T16:29:38.117+0000] {local_task_job_runner.py:120} INFO - ::group::Pre task execution logs
[2024-07-22T16:29:38.142+0000] {taskinstance.py:2076} INFO - Dependencies all met for dep_context=non-requeueable deps ti=<TaskInstance: motower_daily_prod.extract_congestion scheduled__2024-07-08T06:00:00+00:00 [queued]>
[2024-07-22T16:29:38.152+0000] {taskinstance.py:2076} INFO - Dependencies all met for dep_context=requeueable deps ti=<TaskInstance: motower_daily_prod.extract_congestion scheduled__2024-07-08T06:00:00+00:00 [queued]>
[2024-07-22T16:29:38.153+0000] {taskinstance.py:2306} INFO - Starting attempt 1 of 1
[2024-07-22T16:29:38.161+0000] {taskinstance.py:2330} INFO - Executing <Task(PythonOperator): extract_congestion> on 2024-07-08 06:00:00+00:00
[2024-07-22T16:29:38.170+0000] {warnings.py:112} WARNING - /home/***/.local/lib/python3.12/site-packages/***/task/task_runner/standard_task_runner.py:62: DeprecationWarning: This process (pid=434) is multi-threaded, use of fork() may lead to deadlocks in the child.
  pid = os.fork()

[2024-07-22T16:29:38.171+0000] {standard_task_runner.py:64} INFO - Started process 436 to run task
[2024-07-22T16:29:38.171+0000] {standard_task_runner.py:90} INFO - Running: ['***', 'tasks', 'run', 'motower_daily_prod', 'extract_congestion', 'scheduled__2024-07-08T06:00:00+00:00', '--job-id', '34', '--raw', '--subdir', 'DAGS_FOLDER/gps/custom_dags/motower_daily.py', '--cfg-path', '/tmp/tmpv55lg8tj']
[2024-07-22T16:29:38.173+0000] {standard_task_runner.py:91} INFO - Job 34: Subtask extract_congestion
[2024-07-22T16:29:38.211+0000] {task_command.py:426} INFO - Running <TaskInstance: motower_daily_prod.extract_congestion scheduled__2024-07-08T06:00:00+00:00 [running]> on host 5e959f2258db
[2024-07-22T16:29:38.283+0000] {taskinstance.py:2648} INFO - Exporting env vars: AIRFLOW_CTX_DAG_EMAIL='richmond.kongo@orange.com,assane.diop@orange.com,cyrille1.danho@orange.com,mohamed2.sylla@orange.com,amadou.diomande@orange.com,Jonas.kouame@orange.com,armand.kablan@orange.com,anicet.azombade@orange.com,etienne.kouadio@orange.com,bertine.kouakou@orange.com,florentine.kouakou@orange.com,ange.phaceli@orange.com,soulegame.soro@orange.com,innocent.yengo@orange.com' AIRFLOW_CTX_DAG_OWNER='***' AIRFLOW_CTX_DAG_ID='motower_daily_prod' AIRFLOW_CTX_TASK_ID='extract_congestion' AIRFLOW_CTX_EXECUTION_DATE='2024-07-08T06:00:00+00:00' AIRFLOW_CTX_TRY_NUMBER='1' AIRFLOW_CTX_DAG_RUN_ID='scheduled__2024-07-08T06:00:00+00:00'
[2024-07-22T16:29:38.284+0000] {taskinstance.py:430} INFO - ::endgroup::
[2024-07-22T16:29:38.297+0000] {extract.py:127} INFO - Getting data of the table ks_hebdo_tdb_radio_drsi 
[2024-07-22T16:29:38.297+0000] {extract.py:128} INFO - where date is 2024-07-07
[2024-07-22T16:29:38.298+0000] {extract.py:99} INFO - get data to date 27 and year 2024
[2024-07-22T16:29:38.302+0000] {warnings.py:112} WARNING - /opt/***/dags/gps/common/extract.py:100: UserWarning: pandas only supports SQLAlchemy connectable (engine/connection) or database string URI or sqlite3 DBAPI2 connection. Other DBAPI2 objects are not tested. Please consider using SQLAlchemy.
  df_ = pd.read_sql_query(sql_query, conn, params=params)

[2024-07-22T16:29:38.338+0000] {rwminio.py:19} INFO - start to save data
[2024-07-22T16:29:38.340+0000] {connectionpool.py:872} WARNING - Retrying (Retry(total=4, connect=None, read=None, redirect=None, status=None)) after connection broken by 'NewConnectionError('<urllib3.connection.HTTPConnection object at 0x7286302bfcb0>: Failed to establish a new connection: [Errno 111] Connection refused')': /motower?location=
[2024-07-22T16:29:38.742+0000] {connectionpool.py:872} WARNING - Retrying (Retry(total=3, connect=None, read=None, redirect=None, status=None)) after connection broken by 'NewConnectionError('<urllib3.connection.HTTPConnection object at 0x72862baad130>: Failed to establish a new connection: [Errno 111] Connection refused')': /motower?location=
[2024-07-22T16:29:39.544+0000] {connectionpool.py:872} WARNING - Retrying (Retry(total=2, connect=None, read=None, redirect=None, status=None)) after connection broken by 'NewConnectionError('<urllib3.connection.HTTPConnection object at 0x72862baad640>: Failed to establish a new connection: [Errno 111] Connection refused')': /motower?location=
[2024-07-22T16:29:41.146+0000] {connectionpool.py:872} WARNING - Retrying (Retry(total=1, connect=None, read=None, redirect=None, status=None)) after connection broken by 'NewConnectionError('<urllib3.connection.HTTPConnection object at 0x72862baad910>: Failed to establish a new connection: [Errno 111] Connection refused')': /motower?location=
[2024-07-22T16:29:44.349+0000] {connectionpool.py:872} WARNING - Retrying (Retry(total=0, connect=None, read=None, redirect=None, status=None)) after connection broken by 'NewConnectionError('<urllib3.connection.HTTPConnection object at 0x72862baaddc0>: Failed to establish a new connection: [Errno 111] Connection refused')': /motower?location=
[2024-07-22T16:29:44.351+0000] {rwminio.py:36} ERROR - Error saving data to Minio with error: HTTPConnectionPool(host='minio', port=80): Max retries exceeded with url: /motower?location= (Caused by NewConnectionError('<urllib3.connection.HTTPConnection object at 0x72862baae240>: Failed to establish a new connection: [Errno 111] Connection refused'))
[2024-07-22T16:29:44.352+0000] {python.py:237} INFO - Done. Returned value was: None
[2024-07-22T16:29:44.352+0000] {taskinstance.py:441} INFO - ::group::Post task execution logs
[2024-07-22T16:29:44.372+0000] {taskinstance.py:1206} INFO - Marking task as SUCCESS. dag_id=motower_daily_prod, task_id=extract_congestion, run_id=scheduled__2024-07-08T06:00:00+00:00, execution_date=20240708T060000, start_date=20240722T162938, end_date=20240722T162944
[2024-07-22T16:29:44.408+0000] {local_task_job_runner.py:243} INFO - Task exited with return code 0
[2024-07-22T16:29:44.433+0000] {taskinstance.py:3503} INFO - 0 downstream tasks scheduled from follow-on schedule check
[2024-07-22T16:29:44.435+0000] {local_task_job_runner.py:222} INFO - ::endgroup::
