[2024-07-22T16:40:01.715+0000] {local_task_job_runner.py:120} INFO - ::group::Pre task execution logs
[2024-07-22T16:40:02.010+0000] {taskinstance.py:2076} INFO - Dependencies all met for dep_context=non-requeueable deps ti=<TaskInstance: motower_daily_prod.sensor_congestion scheduled__2024-07-10T06:00:00+00:00 [queued]>
[2024-07-22T16:40:02.017+0000] {taskinstance.py:2076} INFO - Dependencies all met for dep_context=requeueable deps ti=<TaskInstance: motower_daily_prod.sensor_congestion scheduled__2024-07-10T06:00:00+00:00 [queued]>
[2024-07-22T16:40:02.018+0000] {taskinstance.py:2306} INFO - Starting attempt 1 of 1
[2024-07-22T16:40:02.027+0000] {taskinstance.py:2330} INFO - Executing <Task(PythonSensor): sensor_congestion> on 2024-07-10 06:00:00+00:00
[2024-07-22T16:40:02.036+0000] {warnings.py:112} WARNING - /home/***/.local/lib/python3.12/site-packages/***/task/task_runner/standard_task_runner.py:62: DeprecationWarning: This process (pid=571) is multi-threaded, use of fork() may lead to deadlocks in the child.
  pid = os.fork()

[2024-07-22T16:40:02.038+0000] {standard_task_runner.py:64} INFO - Started process 577 to run task
[2024-07-22T16:40:02.038+0000] {standard_task_runner.py:90} INFO - Running: ['***', 'tasks', 'run', 'motower_daily_prod', 'sensor_congestion', 'scheduled__2024-07-10T06:00:00+00:00', '--job-id', '36', '--raw', '--subdir', 'DAGS_FOLDER/gps/custom_dags/motower_daily.py', '--cfg-path', '/tmp/tmp8l5m64ms']
[2024-07-22T16:40:02.040+0000] {standard_task_runner.py:91} INFO - Job 36: Subtask sensor_congestion
[2024-07-22T16:40:02.078+0000] {task_command.py:426} INFO - Running <TaskInstance: motower_daily_prod.sensor_congestion scheduled__2024-07-10T06:00:00+00:00 [running]> on host 5e959f2258db
[2024-07-22T16:40:02.155+0000] {taskinstance.py:2648} INFO - Exporting env vars: AIRFLOW_CTX_DAG_EMAIL='richmond.kongo@orange.com,assane.diop@orange.com,cyrille1.danho@orange.com,mohamed2.sylla@orange.com,amadou.diomande@orange.com,Jonas.kouame@orange.com,armand.kablan@orange.com,anicet.azombade@orange.com,etienne.kouadio@orange.com,bertine.kouakou@orange.com,florentine.kouakou@orange.com,ange.phaceli@orange.com,soulegame.soro@orange.com,innocent.yengo@orange.com' AIRFLOW_CTX_DAG_OWNER='***' AIRFLOW_CTX_DAG_ID='motower_daily_prod' AIRFLOW_CTX_TASK_ID='sensor_congestion' AIRFLOW_CTX_EXECUTION_DATE='2024-07-10T06:00:00+00:00' AIRFLOW_CTX_TRY_NUMBER='1' AIRFLOW_CTX_DAG_RUN_ID='scheduled__2024-07-10T06:00:00+00:00'
[2024-07-22T16:40:02.156+0000] {taskinstance.py:430} INFO - ::endgroup::
[2024-07-22T16:40:02.167+0000] {python.py:75} INFO - Poking callable: <function check_data_in_table at 0x72864ff79800>
[2024-07-22T16:40:02.171+0000] {extract.py:127} INFO - Getting data of the table ks_hebdo_tdb_radio_drsi 
[2024-07-22T16:40:02.171+0000] {extract.py:128} INFO - where date is 2024-07-09
[2024-07-22T16:40:02.171+0000] {extract.py:99} INFO - get data to date 28 and year 2024
[2024-07-22T16:40:02.176+0000] {warnings.py:112} WARNING - /opt/***/dags/gps/common/extract.py:100: UserWarning: pandas only supports SQLAlchemy connectable (engine/connection) or database string URI or sqlite3 DBAPI2 connection. Other DBAPI2 objects are not tested. Please consider using SQLAlchemy.
  df_ = pd.read_sql_query(sql_query, conn, params=params)

[2024-07-22T16:55:34.343+0000] {local_task_job_runner.py:313} WARNING - State of this instance has been externally set to restarting. Terminating instance.
[2024-07-22T16:55:34.344+0000] {local_task_job_runner.py:222} INFO - ::endgroup::
[2024-07-22T16:55:34.345+0000] {process_utils.py:132} INFO - Sending 15 to group 577. PIDs of all processes in the group: [577]
[2024-07-22T16:55:34.346+0000] {process_utils.py:87} INFO - Sending the signal 15 to group 577
[2024-07-22T16:55:34.346+0000] {taskinstance.py:2611} ERROR - Received SIGTERM. Terminating subprocesses.
[2024-07-22T16:55:34.346+0000] {taskinstance.py:441} INFO - ::group::Post task execution logs
[2024-07-22T16:55:34.356+0000] {taskinstance.py:2905} ERROR - Task failed with exception
Traceback (most recent call last):
  File "/home/airflow/.local/lib/python3.12/site-packages/airflow/models/taskinstance.py", line 465, in _execute_task
    result = _execute_callable(context=context, **execute_callable_kwargs)
             ^^^^^^^^^^^^^^^^^^^^^^^^^^^^^^^^^^^^^^^^^^^^^^^^^^^^^^^^^^^^^
  File "/home/airflow/.local/lib/python3.12/site-packages/airflow/models/taskinstance.py", line 432, in _execute_callable
    return execute_callable(context=context, **execute_callable_kwargs)
           ^^^^^^^^^^^^^^^^^^^^^^^^^^^^^^^^^^^^^^^^^^^^^^^^^^^^^^^^^^^^
  File "/home/airflow/.local/lib/python3.12/site-packages/airflow/models/baseoperator.py", line 401, in wrapper
    return func(self, *args, **kwargs)
           ^^^^^^^^^^^^^^^^^^^^^^^^^^^
  File "/home/airflow/.local/lib/python3.12/site-packages/airflow/sensors/base.py", line 292, in execute
    time.sleep(self._get_next_poke_interval(started_at, run_duration, poke_count))
  File "/home/airflow/.local/lib/python3.12/site-packages/airflow/models/taskinstance.py", line 2613, in signal_handler
    raise AirflowTaskTerminated("Task received SIGTERM signal")
airflow.exceptions.AirflowTaskTerminated: Task received SIGTERM signal
[2024-07-22T16:55:34.359+0000] {taskinstance.py:1206} INFO - Marking task as UP_FOR_RETRY. dag_id=motower_daily_prod, task_id=sensor_congestion, run_id=scheduled__2024-07-10T06:00:00+00:00, execution_date=20240710T060000, start_date=20240722T164002, end_date=20240722T165534
[2024-07-22T16:55:34.398+0000] {process_utils.py:80} INFO - Process psutil.Process(pid=577, status='terminated', exitcode=2, started='16:40:01') (577) terminated with exit code 2
[2024-07-26T11:56:21.450+0000] {local_task_job_runner.py:120} INFO - ::group::Pre task execution logs
[2024-07-26T11:56:21.477+0000] {taskinstance.py:2076} INFO - Dependencies all met for dep_context=non-requeueable deps ti=<TaskInstance: motower_daily_prod.sensor_congestion scheduled__2024-07-10T06:00:00+00:00 [queued]>
[2024-07-26T11:56:21.486+0000] {taskinstance.py:2076} INFO - Dependencies all met for dep_context=requeueable deps ti=<TaskInstance: motower_daily_prod.sensor_congestion scheduled__2024-07-10T06:00:00+00:00 [queued]>
[2024-07-26T11:56:21.487+0000] {taskinstance.py:2306} INFO - Starting attempt 1 of 1
[2024-07-26T11:56:21.499+0000] {taskinstance.py:2330} INFO - Executing <Task(PythonSensor): sensor_congestion> on 2024-07-10 06:00:00+00:00
[2024-07-26T11:56:21.511+0000] {warnings.py:112} WARNING - /home/***/.local/lib/python3.12/site-packages/***/task/task_runner/standard_task_runner.py:62: DeprecationWarning: This process (pid=3185) is multi-threaded, use of fork() may lead to deadlocks in the child.
  pid = os.fork()

[2024-07-26T11:56:21.512+0000] {standard_task_runner.py:64} INFO - Started process 3189 to run task
[2024-07-26T11:56:21.512+0000] {standard_task_runner.py:90} INFO - Running: ['***', 'tasks', 'run', 'motower_daily_prod', 'sensor_congestion', 'scheduled__2024-07-10T06:00:00+00:00', '--job-id', '3958', '--raw', '--subdir', 'DAGS_FOLDER/gps/custom_dags/motower_daily.py', '--cfg-path', '/tmp/tmp95z4_471']
[2024-07-26T11:56:21.514+0000] {standard_task_runner.py:91} INFO - Job 3958: Subtask sensor_congestion
[2024-07-26T11:56:21.562+0000] {task_command.py:426} INFO - Running <TaskInstance: motower_daily_prod.sensor_congestion scheduled__2024-07-10T06:00:00+00:00 [running]> on host b3845fb494d4
[2024-07-26T11:56:21.641+0000] {taskinstance.py:2648} INFO - Exporting env vars: AIRFLOW_CTX_DAG_EMAIL='richmond.kongo@orange.com,assane.diop@orange.com,cyrille1.danho@orange.com,mohamed2.sylla@orange.com,amadou.diomande@orange.com,Jonas.kouame@orange.com,armand.kablan@orange.com,anicet.azombade@orange.com,etienne.kouadio@orange.com,bertine.kouakou@orange.com,florentine.kouakou@orange.com,ange.phaceli@orange.com,soulegame.soro@orange.com,innocent.yengo@orange.com' AIRFLOW_CTX_DAG_OWNER='***' AIRFLOW_CTX_DAG_ID='motower_daily_prod' AIRFLOW_CTX_TASK_ID='sensor_congestion' AIRFLOW_CTX_EXECUTION_DATE='2024-07-10T06:00:00+00:00' AIRFLOW_CTX_TRY_NUMBER='1' AIRFLOW_CTX_DAG_RUN_ID='scheduled__2024-07-10T06:00:00+00:00'
[2024-07-26T11:56:21.643+0000] {taskinstance.py:430} INFO - ::endgroup::
[2024-07-26T11:56:21.655+0000] {python.py:75} INFO - Poking callable: <function check_data_in_table at 0x745e34f736a0>
[2024-07-26T11:56:21.659+0000] {extract.py:126} INFO - Getting data of the table ks_hebdo_tdb_radio_drsi 
[2024-07-26T11:56:21.659+0000] {extract.py:127} INFO - where date is 2024-07-09
[2024-07-26T11:56:21.660+0000] {extract.py:98} INFO - get data to date 28 and year 2024
[2024-07-26T11:56:21.664+0000] {warnings.py:112} WARNING - /opt/***/dags/gps/common/extract.py:99: UserWarning: pandas only supports SQLAlchemy connectable (engine/connection) or database string URI or sqlite3 DBAPI2 connection. Other DBAPI2 objects are not tested. Please consider using SQLAlchemy.
  df_ = pd.read_sql_query(sql_query, conn, params=params)

[2024-07-26T11:56:46.731+0000] {local_task_job_runner.py:313} WARNING - State of this instance has been externally set to None. Terminating instance.
[2024-07-26T11:56:46.732+0000] {local_task_job_runner.py:222} INFO - ::endgroup::
[2024-07-26T11:56:46.734+0000] {process_utils.py:132} INFO - Sending 15 to group 3189. PIDs of all processes in the group: [3189]
[2024-07-26T11:56:46.734+0000] {process_utils.py:87} INFO - Sending the signal 15 to group 3189
[2024-07-26T11:56:46.734+0000] {taskinstance.py:2611} ERROR - Received SIGTERM. Terminating subprocesses.
[2024-07-26T11:56:46.734+0000] {taskinstance.py:441} INFO - ::group::Post task execution logs
[2024-07-26T11:56:46.742+0000] {taskinstance.py:2905} ERROR - Task failed with exception
Traceback (most recent call last):
  File "/home/airflow/.local/lib/python3.12/site-packages/airflow/models/taskinstance.py", line 465, in _execute_task
    result = _execute_callable(context=context, **execute_callable_kwargs)
             ^^^^^^^^^^^^^^^^^^^^^^^^^^^^^^^^^^^^^^^^^^^^^^^^^^^^^^^^^^^^^
  File "/home/airflow/.local/lib/python3.12/site-packages/airflow/models/taskinstance.py", line 432, in _execute_callable
    return execute_callable(context=context, **execute_callable_kwargs)
           ^^^^^^^^^^^^^^^^^^^^^^^^^^^^^^^^^^^^^^^^^^^^^^^^^^^^^^^^^^^^
  File "/home/airflow/.local/lib/python3.12/site-packages/airflow/models/baseoperator.py", line 401, in wrapper
    return func(self, *args, **kwargs)
           ^^^^^^^^^^^^^^^^^^^^^^^^^^^
  File "/home/airflow/.local/lib/python3.12/site-packages/airflow/sensors/base.py", line 292, in execute
    time.sleep(self._get_next_poke_interval(started_at, run_duration, poke_count))
  File "/home/airflow/.local/lib/python3.12/site-packages/airflow/models/taskinstance.py", line 2613, in signal_handler
    raise AirflowTaskTerminated("Task received SIGTERM signal")
airflow.exceptions.AirflowTaskTerminated: Task received SIGTERM signal
[2024-07-26T11:56:46.744+0000] {taskinstance.py:1206} INFO - Marking task as FAILED. dag_id=motower_daily_prod, task_id=sensor_congestion, run_id=scheduled__2024-07-10T06:00:00+00:00, execution_date=20240710T060000, start_date=20240726T115621, end_date=20240726T115646
[2024-07-26T11:56:46.758+0000] {warnings.py:112} WARNING - /home/***/.local/lib/python3.12/site-packages/***/utils/email.py:154: RemovedInAirflow3Warning: Fetching SMTP credentials from configuration variables will be deprecated in a future release. Please set credentials using a connection instead.
  send_mime_email(e_from=mail_from, e_to=recipients, mime_msg=msg, conn_id=conn_id, dryrun=dryrun)

[2024-07-26T11:56:46.759+0000] {configuration.py:1053} WARNING - section/key [smtp/smtp_user] not found in config
[2024-07-26T11:56:46.759+0000] {email.py:271} INFO - Email alerting: attempt 1
[2024-07-26T11:56:46.766+0000] {configuration.py:1053} WARNING - section/key [smtp/smtp_user] not found in config
[2024-07-26T11:56:46.766+0000] {email.py:271} INFO - Email alerting: attempt 1
[2024-07-26T11:56:46.767+0000] {taskinstance.py:879} ERROR - Failed to send email to: ['richmond.kongo@orange.com', 'assane.diop@orange.com', 'cyrille1.danho@orange.com', 'mohamed2.sylla@orange.com', 'amadou.diomande@orange.com', 'Jonas.kouame@orange.com', 'armand.kablan@orange.com', 'anicet.azombade@orange.com', 'etienne.kouadio@orange.com', 'bertine.kouakou@orange.com', 'florentine.kouakou@orange.com', 'ange.phaceli@orange.com', 'soulegame.soro@orange.com', 'innocent.yengo@orange.com']
Traceback (most recent call last):
  File "/home/airflow/.local/lib/python3.12/site-packages/airflow/models/taskinstance.py", line 2479, in _run_raw_task
    self._execute_task_with_callbacks(context, test_mode, session=session)
  File "/home/airflow/.local/lib/python3.12/site-packages/airflow/models/taskinstance.py", line 2676, in _execute_task_with_callbacks
    result = self._execute_task(context, task_orig)
             ^^^^^^^^^^^^^^^^^^^^^^^^^^^^^^^^^^^^^^
  File "/home/airflow/.local/lib/python3.12/site-packages/airflow/models/taskinstance.py", line 2701, in _execute_task
    return _execute_task(self, context, task_orig)
           ^^^^^^^^^^^^^^^^^^^^^^^^^^^^^^^^^^^^^^^
  File "/home/airflow/.local/lib/python3.12/site-packages/airflow/models/taskinstance.py", line 465, in _execute_task
    result = _execute_callable(context=context, **execute_callable_kwargs)
             ^^^^^^^^^^^^^^^^^^^^^^^^^^^^^^^^^^^^^^^^^^^^^^^^^^^^^^^^^^^^^
  File "/home/airflow/.local/lib/python3.12/site-packages/airflow/models/taskinstance.py", line 432, in _execute_callable
    return execute_callable(context=context, **execute_callable_kwargs)
           ^^^^^^^^^^^^^^^^^^^^^^^^^^^^^^^^^^^^^^^^^^^^^^^^^^^^^^^^^^^^
  File "/home/airflow/.local/lib/python3.12/site-packages/airflow/models/baseoperator.py", line 401, in wrapper
    return func(self, *args, **kwargs)
           ^^^^^^^^^^^^^^^^^^^^^^^^^^^
  File "/home/airflow/.local/lib/python3.12/site-packages/airflow/sensors/base.py", line 292, in execute
    time.sleep(self._get_next_poke_interval(started_at, run_duration, poke_count))
  File "/home/airflow/.local/lib/python3.12/site-packages/airflow/models/taskinstance.py", line 2613, in signal_handler
    raise AirflowTaskTerminated("Task received SIGTERM signal")
airflow.exceptions.AirflowTaskTerminated: Task received SIGTERM signal

During handling of the above exception, another exception occurred:

Traceback (most recent call last):
  File "/home/airflow/.local/lib/python3.12/site-packages/airflow/models/taskinstance.py", line 1063, in _email_alert
    send_email(task.email, subject, html_content)
  File "/home/airflow/.local/lib/python3.12/site-packages/airflow/utils/email.py", line 80, in send_email
    return backend(
           ^^^^^^^^
  File "/home/airflow/.local/lib/python3.12/site-packages/airflow/utils/email.py", line 154, in send_email_smtp
    send_mime_email(e_from=mail_from, e_to=recipients, mime_msg=msg, conn_id=conn_id, dryrun=dryrun)
  File "/home/airflow/.local/lib/python3.12/site-packages/airflow/utils/email.py", line 273, in send_mime_email
    smtp_conn = _get_smtp_connection(smtp_host, smtp_port, smtp_timeout, smtp_ssl)
                ^^^^^^^^^^^^^^^^^^^^^^^^^^^^^^^^^^^^^^^^^^^^^^^^^^^^^^^^^^^^^^^^^^
  File "/home/airflow/.local/lib/python3.12/site-packages/airflow/utils/email.py", line 317, in _get_smtp_connection
    return smtplib.SMTP(host=host, port=port, timeout=timeout)
           ^^^^^^^^^^^^^^^^^^^^^^^^^^^^^^^^^^^^^^^^^^^^^^^^^^^
  File "/usr/local/lib/python3.12/smtplib.py", line 255, in __init__
    (code, msg) = self.connect(host, port)
                  ^^^^^^^^^^^^^^^^^^^^^^^^
  File "/usr/local/lib/python3.12/smtplib.py", line 341, in connect
    self.sock = self._get_socket(host, port, self.timeout)
                ^^^^^^^^^^^^^^^^^^^^^^^^^^^^^^^^^^^^^^^^^^
  File "/usr/local/lib/python3.12/smtplib.py", line 312, in _get_socket
    return socket.create_connection((host, port), timeout,
           ^^^^^^^^^^^^^^^^^^^^^^^^^^^^^^^^^^^^^^^^^^^^^^^
  File "/usr/local/lib/python3.12/socket.py", line 853, in create_connection
    raise exceptions[0]
  File "/usr/local/lib/python3.12/socket.py", line 838, in create_connection
    sock.connect(sa)
ConnectionRefusedError: [Errno 111] Connection refused

During handling of the above exception, another exception occurred:

Traceback (most recent call last):
  File "/home/airflow/.local/lib/python3.12/site-packages/airflow/models/taskinstance.py", line 877, in _handle_failure
    task_instance.email_alert(error, failure_context["task"])
  File "/home/airflow/.local/lib/python3.12/site-packages/airflow/models/taskinstance.py", line 3163, in email_alert
    _email_alert(task_instance=self, exception=exception, task=task)
  File "/home/airflow/.local/lib/python3.12/site-packages/airflow/models/taskinstance.py", line 1065, in _email_alert
    send_email(task.email, subject, html_content_err)
  File "/home/airflow/.local/lib/python3.12/site-packages/airflow/utils/email.py", line 80, in send_email
    return backend(
           ^^^^^^^^
  File "/home/airflow/.local/lib/python3.12/site-packages/airflow/utils/email.py", line 154, in send_email_smtp
    send_mime_email(e_from=mail_from, e_to=recipients, mime_msg=msg, conn_id=conn_id, dryrun=dryrun)
  File "/home/airflow/.local/lib/python3.12/site-packages/airflow/utils/email.py", line 273, in send_mime_email
    smtp_conn = _get_smtp_connection(smtp_host, smtp_port, smtp_timeout, smtp_ssl)
                ^^^^^^^^^^^^^^^^^^^^^^^^^^^^^^^^^^^^^^^^^^^^^^^^^^^^^^^^^^^^^^^^^^
  File "/home/airflow/.local/lib/python3.12/site-packages/airflow/utils/email.py", line 317, in _get_smtp_connection
    return smtplib.SMTP(host=host, port=port, timeout=timeout)
           ^^^^^^^^^^^^^^^^^^^^^^^^^^^^^^^^^^^^^^^^^^^^^^^^^^^
  File "/usr/local/lib/python3.12/smtplib.py", line 255, in __init__
    (code, msg) = self.connect(host, port)
                  ^^^^^^^^^^^^^^^^^^^^^^^^
  File "/usr/local/lib/python3.12/smtplib.py", line 341, in connect
    self.sock = self._get_socket(host, port, self.timeout)
                ^^^^^^^^^^^^^^^^^^^^^^^^^^^^^^^^^^^^^^^^^^
  File "/usr/local/lib/python3.12/smtplib.py", line 312, in _get_socket
    return socket.create_connection((host, port), timeout,
           ^^^^^^^^^^^^^^^^^^^^^^^^^^^^^^^^^^^^^^^^^^^^^^^
  File "/usr/local/lib/python3.12/socket.py", line 853, in create_connection
    raise exceptions[0]
  File "/usr/local/lib/python3.12/socket.py", line 838, in create_connection
    sock.connect(sa)
ConnectionRefusedError: [Errno 111] Connection refused
[2024-07-26T11:56:46.770+0000] {alerting.py:71} INFO - send alert mail to richmond.kongo@orange.com, assane.diop@orange.com, cyrille1.danho@orange.com, mohamed2.sylla@orange.com, amadou.diomande@orange.com, Jonas.kouame@orange.com, armand.kablan@orange.com, anicet.azombade@orange.com, etienne.kouadio@orange.com, bertine.kouakou@orange.com, florentine.kouakou@orange.com, ange.phaceli@orange.com, soulegame.soro@orange.com, innocent.yengo@orange.com
[2024-07-26T11:56:46.770+0000] {alerting.py:30} INFO - Sending mail ... 
[2024-07-26T11:56:46.771+0000] {alerting.py:38} ERROR - Failed to send email: please run connect() first
[2024-07-26T11:56:46.784+0000] {standard_task_runner.py:110} ERROR - Failed to execute job 3958 for task sensor_congestion ((psycopg2.errors.UniqueViolation) duplicate key value violates unique constraint "dag_run_pkey"
DETAIL:  Key (id)=(684) already exists.

[SQL: INSERT INTO dag_run (id, dag_id, queued_at, execution_date, start_date, end_date, state, run_id, creating_job_id, external_trigger, run_type, conf, data_interval_start, data_interval_end, last_scheduling_decision, dag_hash, log_template_id, updated_at, clear_number) VALUES (%(id)s, %(dag_id)s, %(queued_at)s, %(execution_date)s, %(start_date)s, %(end_date)s, %(state)s, %(run_id)s, %(creating_job_id)s, %(external_trigger)s, %(run_type)s, %(conf)s, %(data_interval_start)s, %(data_interval_end)s, %(last_scheduling_decision)s, %(dag_hash)s, %(log_template_id)s, %(updated_at)s, %(clear_number)s)]
[parameters: {'id': 684, 'dag_id': 'motower_daily_prod', 'queued_at': datetime.datetime(2024, 7, 26, 11, 56, 20, 461472, tzinfo=Timezone('UTC')), 'execution_date': datetime.datetime(2024, 7, 10, 6, 0, tzinfo=Timezone('UTC')), 'start_date': datetime.datetime(2024, 7, 26, 11, 56, 20, 474074, tzinfo=Timezone('UTC')), 'end_date': None, 'state': 'running', 'run_id': 'scheduled__2024-07-10T06:00:00+00:00', 'creating_job_id': 3306, 'external_trigger': False, 'run_type': 'scheduled', 'conf': <psycopg2.extensions.Binary object at 0x745e34cf72a0>, 'data_interval_start': datetime.datetime(2024, 7, 10, 6, 0, tzinfo=Timezone('UTC')), 'data_interval_end': datetime.datetime(2024, 7, 11, 6, 0, tzinfo=Timezone('UTC')), 'last_scheduling_decision': datetime.datetime(2024, 7, 26, 11, 56, 20, 683737, tzinfo=Timezone('UTC')), 'dag_hash': '1978d5c11531bbf2a4016da340f35782', 'log_template_id': 2, 'updated_at': datetime.datetime(2024, 7, 26, 11, 56, 20, 694904, tzinfo=Timezone('UTC')), 'clear_number': 0}]
(Background on this error at: https://sqlalche.me/e/14/gkpj); 3189)
[2024-07-26T11:56:46.826+0000] {process_utils.py:80} INFO - Process psutil.Process(pid=3189, status='terminated', exitcode=1, started='11:56:20') (3189) terminated with exit code 1
