[2024-07-22T16:29:21.998+0000] {local_task_job_runner.py:120} INFO - ::group::Pre task execution logs
[2024-07-22T16:29:22.026+0000] {taskinstance.py:2076} INFO - Dependencies all met for dep_context=non-requeueable deps ti=<TaskInstance: motower_daily_prod.extract_congestion scheduled__2024-07-06T06:00:00+00:00 [queued]>
[2024-07-22T16:29:22.035+0000] {taskinstance.py:2076} INFO - Dependencies all met for dep_context=requeueable deps ti=<TaskInstance: motower_daily_prod.extract_congestion scheduled__2024-07-06T06:00:00+00:00 [queued]>
[2024-07-22T16:29:22.036+0000] {taskinstance.py:2306} INFO - Starting attempt 1 of 1
[2024-07-22T16:29:22.046+0000] {taskinstance.py:2330} INFO - Executing <Task(PythonOperator): extract_congestion> on 2024-07-06 06:00:00+00:00
[2024-07-22T16:29:22.054+0000] {warnings.py:112} WARNING - /home/***/.local/lib/python3.12/site-packages/***/task/task_runner/standard_task_runner.py:62: DeprecationWarning: This process (pid=428) is multi-threaded, use of fork() may lead to deadlocks in the child.
  pid = os.fork()

[2024-07-22T16:29:22.055+0000] {standard_task_runner.py:64} INFO - Started process 430 to run task
[2024-07-22T16:29:22.056+0000] {standard_task_runner.py:90} INFO - Running: ['***', 'tasks', 'run', 'motower_daily_prod', 'extract_congestion', 'scheduled__2024-07-06T06:00:00+00:00', '--job-id', '32', '--raw', '--subdir', 'DAGS_FOLDER/gps/custom_dags/motower_daily.py', '--cfg-path', '/tmp/tmp4a22d67g']
[2024-07-22T16:29:22.057+0000] {standard_task_runner.py:91} INFO - Job 32: Subtask extract_congestion
[2024-07-22T16:29:22.100+0000] {task_command.py:426} INFO - Running <TaskInstance: motower_daily_prod.extract_congestion scheduled__2024-07-06T06:00:00+00:00 [running]> on host 5e959f2258db
[2024-07-22T16:29:22.172+0000] {taskinstance.py:2648} INFO - Exporting env vars: AIRFLOW_CTX_DAG_EMAIL='richmond.kongo@orange.com,assane.diop@orange.com,cyrille1.danho@orange.com,mohamed2.sylla@orange.com,amadou.diomande@orange.com,Jonas.kouame@orange.com,armand.kablan@orange.com,anicet.azombade@orange.com,etienne.kouadio@orange.com,bertine.kouakou@orange.com,florentine.kouakou@orange.com,ange.phaceli@orange.com,soulegame.soro@orange.com,innocent.yengo@orange.com' AIRFLOW_CTX_DAG_OWNER='***' AIRFLOW_CTX_DAG_ID='motower_daily_prod' AIRFLOW_CTX_TASK_ID='extract_congestion' AIRFLOW_CTX_EXECUTION_DATE='2024-07-06T06:00:00+00:00' AIRFLOW_CTX_TRY_NUMBER='1' AIRFLOW_CTX_DAG_RUN_ID='scheduled__2024-07-06T06:00:00+00:00'
[2024-07-22T16:29:22.173+0000] {taskinstance.py:430} INFO - ::endgroup::
[2024-07-22T16:29:22.187+0000] {extract.py:127} INFO - Getting data of the table ks_hebdo_tdb_radio_drsi 
[2024-07-22T16:29:22.187+0000] {extract.py:128} INFO - where date is 2024-07-05
[2024-07-22T16:29:22.188+0000] {extract.py:99} INFO - get data to date 27 and year 2024
[2024-07-22T16:29:22.192+0000] {warnings.py:112} WARNING - /opt/***/dags/gps/common/extract.py:100: UserWarning: pandas only supports SQLAlchemy connectable (engine/connection) or database string URI or sqlite3 DBAPI2 connection. Other DBAPI2 objects are not tested. Please consider using SQLAlchemy.
  df_ = pd.read_sql_query(sql_query, conn, params=params)

[2024-07-22T16:29:22.231+0000] {rwminio.py:19} INFO - start to save data
[2024-07-22T16:29:22.234+0000] {connectionpool.py:872} WARNING - Retrying (Retry(total=4, connect=None, read=None, redirect=None, status=None)) after connection broken by 'NewConnectionError('<urllib3.connection.HTTPConnection object at 0x72862baad130>: Failed to establish a new connection: [Errno 111] Connection refused')': /motower?location=
[2024-07-22T16:29:22.635+0000] {connectionpool.py:872} WARNING - Retrying (Retry(total=3, connect=None, read=None, redirect=None, status=None)) after connection broken by 'NewConnectionError('<urllib3.connection.HTTPConnection object at 0x72862baad3a0>: Failed to establish a new connection: [Errno 111] Connection refused')': /motower?location=
[2024-07-22T16:29:23.437+0000] {connectionpool.py:872} WARNING - Retrying (Retry(total=2, connect=None, read=None, redirect=None, status=None)) after connection broken by 'NewConnectionError('<urllib3.connection.HTTPConnection object at 0x72862baad700>: Failed to establish a new connection: [Errno 111] Connection refused')': /motower?location=
[2024-07-22T16:29:25.039+0000] {connectionpool.py:872} WARNING - Retrying (Retry(total=1, connect=None, read=None, redirect=None, status=None)) after connection broken by 'NewConnectionError('<urllib3.connection.HTTPConnection object at 0x72862baad910>: Failed to establish a new connection: [Errno 111] Connection refused')': /motower?location=
[2024-07-22T16:29:28.241+0000] {connectionpool.py:872} WARNING - Retrying (Retry(total=0, connect=None, read=None, redirect=None, status=None)) after connection broken by 'NewConnectionError('<urllib3.connection.HTTPConnection object at 0x72862baadf40>: Failed to establish a new connection: [Errno 111] Connection refused')': /motower?location=
[2024-07-22T16:29:28.243+0000] {rwminio.py:36} ERROR - Error saving data to Minio with error: HTTPConnectionPool(host='minio', port=80): Max retries exceeded with url: /motower?location= (Caused by NewConnectionError('<urllib3.connection.HTTPConnection object at 0x72862baadfd0>: Failed to establish a new connection: [Errno 111] Connection refused'))
[2024-07-22T16:29:28.243+0000] {python.py:237} INFO - Done. Returned value was: None
[2024-07-22T16:29:28.243+0000] {taskinstance.py:441} INFO - ::group::Post task execution logs
[2024-07-22T16:29:28.253+0000] {taskinstance.py:1206} INFO - Marking task as SUCCESS. dag_id=motower_daily_prod, task_id=extract_congestion, run_id=scheduled__2024-07-06T06:00:00+00:00, execution_date=20240706T060000, start_date=20240722T162922, end_date=20240722T162928
[2024-07-22T16:29:28.322+0000] {local_task_job_runner.py:243} INFO - Task exited with return code 0
[2024-07-22T16:29:28.342+0000] {taskinstance.py:3503} INFO - 0 downstream tasks scheduled from follow-on schedule check
[2024-07-22T16:29:28.343+0000] {local_task_job_runner.py:222} INFO - ::endgroup::
