[2024-07-22T16:56:55.617+0000] {local_task_job_runner.py:120} INFO - ::group::Pre task execution logs
[2024-07-22T16:56:55.932+0000] {taskinstance.py:2076} INFO - Dependencies all met for dep_context=non-requeueable deps ti=<TaskInstance: motower_daily_prod.gen_congestion_task scheduled__2024-06-25T06:00:00+00:00 [queued]>
[2024-07-22T16:56:55.944+0000] {taskinstance.py:2076} INFO - Dependencies all met for dep_context=requeueable deps ti=<TaskInstance: motower_daily_prod.gen_congestion_task scheduled__2024-06-25T06:00:00+00:00 [queued]>
[2024-07-22T16:56:55.945+0000] {taskinstance.py:2306} INFO - Starting attempt 1 of 1
[2024-07-22T16:56:55.960+0000] {taskinstance.py:2330} INFO - Executing <Task(PythonOperator): gen_congestion_task> on 2024-06-25 06:00:00+00:00
[2024-07-22T16:56:55.974+0000] {warnings.py:112} WARNING - /home/***/.local/lib/python3.12/site-packages/***/task/task_runner/standard_task_runner.py:62: DeprecationWarning: This process (pid=872) is multi-threaded, use of fork() may lead to deadlocks in the child.
  pid = os.fork()

[2024-07-22T16:56:55.975+0000] {standard_task_runner.py:64} INFO - Started process 889 to run task
[2024-07-22T16:56:55.980+0000] {standard_task_runner.py:90} INFO - Running: ['***', 'tasks', 'run', 'motower_daily_prod', 'gen_congestion_task', 'scheduled__2024-06-25T06:00:00+00:00', '--job-id', '64', '--raw', '--subdir', 'DAGS_FOLDER/gps/custom_dags/motower_daily.py', '--cfg-path', '/tmp/tmpcna3odhz']
[2024-07-22T16:56:55.982+0000] {standard_task_runner.py:91} INFO - Job 64: Subtask gen_congestion_task
[2024-07-22T16:56:56.051+0000] {task_command.py:426} INFO - Running <TaskInstance: motower_daily_prod.gen_congestion_task scheduled__2024-06-25T06:00:00+00:00 [running]> on host 5e959f2258db
[2024-07-22T16:56:56.163+0000] {taskinstance.py:2648} INFO - Exporting env vars: AIRFLOW_CTX_DAG_EMAIL='richmond.kongo@orange.com,assane.diop@orange.com,cyrille1.danho@orange.com,mohamed2.sylla@orange.com,amadou.diomande@orange.com,Jonas.kouame@orange.com,armand.kablan@orange.com,anicet.azombade@orange.com,etienne.kouadio@orange.com,bertine.kouakou@orange.com,florentine.kouakou@orange.com,ange.phaceli@orange.com,soulegame.soro@orange.com,innocent.yengo@orange.com' AIRFLOW_CTX_DAG_OWNER='***' AIRFLOW_CTX_DAG_ID='motower_daily_prod' AIRFLOW_CTX_TASK_ID='gen_congestion_task' AIRFLOW_CTX_EXECUTION_DATE='2024-06-25T06:00:00+00:00' AIRFLOW_CTX_TRY_NUMBER='1' AIRFLOW_CTX_DAG_RUN_ID='scheduled__2024-06-25T06:00:00+00:00'
[2024-07-22T16:56:56.165+0000] {taskinstance.py:430} INFO - ::endgroup::
[2024-07-22T16:56:56.185+0000] {connectionpool.py:872} WARNING - Retrying (Retry(total=4, connect=None, read=None, redirect=None, status=None)) after connection broken by 'NewConnectionError('<urllib3.connection.HTTPConnection object at 0x728630492db0>: Failed to establish a new connection: [Errno 111] Connection refused')': /motower?location=
[2024-07-22T16:56:56.587+0000] {connectionpool.py:872} WARNING - Retrying (Retry(total=3, connect=None, read=None, redirect=None, status=None)) after connection broken by 'NewConnectionError('<urllib3.connection.HTTPConnection object at 0x728630493230>: Failed to establish a new connection: [Errno 111] Connection refused')': /motower?location=
[2024-07-22T16:56:57.389+0000] {connectionpool.py:872} WARNING - Retrying (Retry(total=2, connect=None, read=None, redirect=None, status=None)) after connection broken by 'NewConnectionError('<urllib3.connection.HTTPConnection object at 0x728630493470>: Failed to establish a new connection: [Errno 111] Connection refused')': /motower?location=
[2024-07-22T16:56:58.991+0000] {connectionpool.py:872} WARNING - Retrying (Retry(total=1, connect=None, read=None, redirect=None, status=None)) after connection broken by 'NewConnectionError('<urllib3.connection.HTTPConnection object at 0x728630493a70>: Failed to establish a new connection: [Errno 111] Connection refused')': /motower?location=
[2024-07-22T16:57:02.194+0000] {connectionpool.py:872} WARNING - Retrying (Retry(total=0, connect=None, read=None, redirect=None, status=None)) after connection broken by 'NewConnectionError('<urllib3.connection.HTTPConnection object at 0x728630493b00>: Failed to establish a new connection: [Errno 111] Connection refused')': /motower?location=
[2024-07-22T16:57:02.195+0000] {taskinstance.py:441} INFO - ::group::Post task execution logs
[2024-07-22T16:57:02.196+0000] {taskinstance.py:2905} ERROR - Task failed with exception
Traceback (most recent call last):
  File "/home/airflow/.local/lib/python3.12/site-packages/urllib3/connection.py", line 203, in _new_conn
    sock = connection.create_connection(
           ^^^^^^^^^^^^^^^^^^^^^^^^^^^^^
  File "/home/airflow/.local/lib/python3.12/site-packages/urllib3/util/connection.py", line 85, in create_connection
    raise err
  File "/home/airflow/.local/lib/python3.12/site-packages/urllib3/util/connection.py", line 73, in create_connection
    sock.connect(sa)
ConnectionRefusedError: [Errno 111] Connection refused

The above exception was the direct cause of the following exception:

Traceback (most recent call last):
  File "/home/airflow/.local/lib/python3.12/site-packages/urllib3/connectionpool.py", line 791, in urlopen
    response = self._make_request(
               ^^^^^^^^^^^^^^^^^^^
  File "/home/airflow/.local/lib/python3.12/site-packages/urllib3/connectionpool.py", line 497, in _make_request
    conn.request(
  File "/home/airflow/.local/lib/python3.12/site-packages/urllib3/connection.py", line 395, in request
    self.endheaders()
  File "/usr/local/lib/python3.12/http/client.py", line 1331, in endheaders
    self._send_output(message_body, encode_chunked=encode_chunked)
  File "/usr/local/lib/python3.12/http/client.py", line 1091, in _send_output
    self.send(msg)
  File "/usr/local/lib/python3.12/http/client.py", line 1035, in send
    self.connect()
  File "/home/airflow/.local/lib/python3.12/site-packages/urllib3/connection.py", line 243, in connect
    self.sock = self._new_conn()
                ^^^^^^^^^^^^^^^^
  File "/home/airflow/.local/lib/python3.12/site-packages/urllib3/connection.py", line 218, in _new_conn
    raise NewConnectionError(
urllib3.exceptions.NewConnectionError: <urllib3.connection.HTTPConnection object at 0x7286304c8110>: Failed to establish a new connection: [Errno 111] Connection refused

The above exception was the direct cause of the following exception:

Traceback (most recent call last):
  File "/home/airflow/.local/lib/python3.12/site-packages/airflow/models/taskinstance.py", line 465, in _execute_task
    result = _execute_callable(context=context, **execute_callable_kwargs)
             ^^^^^^^^^^^^^^^^^^^^^^^^^^^^^^^^^^^^^^^^^^^^^^^^^^^^^^^^^^^^^
  File "/home/airflow/.local/lib/python3.12/site-packages/airflow/models/taskinstance.py", line 432, in _execute_callable
    return execute_callable(context=context, **execute_callable_kwargs)
           ^^^^^^^^^^^^^^^^^^^^^^^^^^^^^^^^^^^^^^^^^^^^^^^^^^^^^^^^^^^^
  File "/home/airflow/.local/lib/python3.12/site-packages/airflow/models/baseoperator.py", line 401, in wrapper
    return func(self, *args, **kwargs)
           ^^^^^^^^^^^^^^^^^^^^^^^^^^^
  File "/home/airflow/.local/lib/python3.12/site-packages/airflow/operators/python.py", line 235, in execute
    return_value = self.execute_callable()
                   ^^^^^^^^^^^^^^^^^^^^^^^
  File "/home/airflow/.local/lib/python3.12/site-packages/airflow/operators/python.py", line 252, in execute_callable
    return self.python_callable(*self.op_args, **self.op_kwargs)
           ^^^^^^^^^^^^^^^^^^^^^^^^^^^^^^^^^^^^^^^^^^^^^^^^^^^^^
  File "/opt/airflow/dags/gps/custom_dags/motower_daily.py", line 84, in clean_congestion
    data = cleaning_congestion(CLIENT, kwargs['ingest_date'])
           ^^^^^^^^^^^^^^^^^^^^^^^^^^^^^^^^^^^^^^^^^^^^^^^^^^
  File "/opt/airflow/dags/gps/common/motower_daily.py", line 289, in cleaning_congestion
    if not client.bucket_exists(objet["bucket"]):
           ^^^^^^^^^^^^^^^^^^^^^^^^^^^^^^^^^^^^^
  File "/home/airflow/.local/lib/python3.12/site-packages/minio/api.py", line 696, in bucket_exists
    self._execute("HEAD", bucket_name)
  File "/home/airflow/.local/lib/python3.12/site-packages/minio/api.py", line 437, in _execute
    region = self._get_region(bucket_name)
             ^^^^^^^^^^^^^^^^^^^^^^^^^^^^^
  File "/home/airflow/.local/lib/python3.12/site-packages/minio/api.py", line 494, in _get_region
    response = self._url_open(
               ^^^^^^^^^^^^^^^
  File "/home/airflow/.local/lib/python3.12/site-packages/minio/api.py", line 302, in _url_open
    response = self._http.urlopen(
               ^^^^^^^^^^^^^^^^^^^
  File "/home/airflow/.local/lib/python3.12/site-packages/urllib3/poolmanager.py", line 443, in urlopen
    response = conn.urlopen(method, u.request_uri, **kw)
               ^^^^^^^^^^^^^^^^^^^^^^^^^^^^^^^^^^^^^^^^^
  File "/home/airflow/.local/lib/python3.12/site-packages/urllib3/connectionpool.py", line 875, in urlopen
    return self.urlopen(
           ^^^^^^^^^^^^^
  File "/home/airflow/.local/lib/python3.12/site-packages/urllib3/connectionpool.py", line 875, in urlopen
    return self.urlopen(
           ^^^^^^^^^^^^^
  File "/home/airflow/.local/lib/python3.12/site-packages/urllib3/connectionpool.py", line 875, in urlopen
    return self.urlopen(
           ^^^^^^^^^^^^^
  [Previous line repeated 2 more times]
  File "/home/airflow/.local/lib/python3.12/site-packages/urllib3/connectionpool.py", line 845, in urlopen
    retries = retries.increment(
              ^^^^^^^^^^^^^^^^^^
  File "/home/airflow/.local/lib/python3.12/site-packages/urllib3/util/retry.py", line 515, in increment
    raise MaxRetryError(_pool, url, reason) from reason  # type: ignore[arg-type]
    ^^^^^^^^^^^^^^^^^^^^^^^^^^^^^^^^^^^^^^^^^^^^^^^^^^^
urllib3.exceptions.MaxRetryError: HTTPConnectionPool(host='minio', port=80): Max retries exceeded with url: /motower?location= (Caused by NewConnectionError('<urllib3.connection.HTTPConnection object at 0x7286304c8110>: Failed to establish a new connection: [Errno 111] Connection refused'))
[2024-07-22T16:57:02.209+0000] {taskinstance.py:1206} INFO - Marking task as FAILED. dag_id=motower_daily_prod, task_id=gen_congestion_task, run_id=scheduled__2024-06-25T06:00:00+00:00, execution_date=20240625T060000, start_date=20240722T165655, end_date=20240722T165702
[2024-07-22T16:57:02.225+0000] {warnings.py:112} WARNING - /home/***/.local/lib/python3.12/site-packages/***/utils/email.py:154: RemovedInAirflow3Warning: Fetching SMTP credentials from configuration variables will be deprecated in a future release. Please set credentials using a connection instead.
  send_mime_email(e_from=mail_from, e_to=recipients, mime_msg=msg, conn_id=conn_id, dryrun=dryrun)

[2024-07-22T16:57:02.225+0000] {configuration.py:1053} WARNING - section/key [smtp/smtp_user] not found in config
[2024-07-22T16:57:02.225+0000] {email.py:271} INFO - Email alerting: attempt 1
[2024-07-22T16:57:02.234+0000] {configuration.py:1053} WARNING - section/key [smtp/smtp_user] not found in config
[2024-07-22T16:57:02.235+0000] {email.py:271} INFO - Email alerting: attempt 1
[2024-07-22T16:57:02.235+0000] {taskinstance.py:879} ERROR - Failed to send email to: ['richmond.kongo@orange.com', 'assane.diop@orange.com', 'cyrille1.danho@orange.com', 'mohamed2.sylla@orange.com', 'amadou.diomande@orange.com', 'Jonas.kouame@orange.com', 'armand.kablan@orange.com', 'anicet.azombade@orange.com', 'etienne.kouadio@orange.com', 'bertine.kouakou@orange.com', 'florentine.kouakou@orange.com', 'ange.phaceli@orange.com', 'soulegame.soro@orange.com', 'innocent.yengo@orange.com']
Traceback (most recent call last):
  File "/home/airflow/.local/lib/python3.12/site-packages/urllib3/connection.py", line 203, in _new_conn
    sock = connection.create_connection(
           ^^^^^^^^^^^^^^^^^^^^^^^^^^^^^
  File "/home/airflow/.local/lib/python3.12/site-packages/urllib3/util/connection.py", line 85, in create_connection
    raise err
  File "/home/airflow/.local/lib/python3.12/site-packages/urllib3/util/connection.py", line 73, in create_connection
    sock.connect(sa)
ConnectionRefusedError: [Errno 111] Connection refused

The above exception was the direct cause of the following exception:

Traceback (most recent call last):
  File "/home/airflow/.local/lib/python3.12/site-packages/urllib3/connectionpool.py", line 791, in urlopen
    response = self._make_request(
               ^^^^^^^^^^^^^^^^^^^
  File "/home/airflow/.local/lib/python3.12/site-packages/urllib3/connectionpool.py", line 497, in _make_request
    conn.request(
  File "/home/airflow/.local/lib/python3.12/site-packages/urllib3/connection.py", line 395, in request
    self.endheaders()
  File "/usr/local/lib/python3.12/http/client.py", line 1331, in endheaders
    self._send_output(message_body, encode_chunked=encode_chunked)
  File "/usr/local/lib/python3.12/http/client.py", line 1091, in _send_output
    self.send(msg)
  File "/usr/local/lib/python3.12/http/client.py", line 1035, in send
    self.connect()
  File "/home/airflow/.local/lib/python3.12/site-packages/urllib3/connection.py", line 243, in connect
    self.sock = self._new_conn()
                ^^^^^^^^^^^^^^^^
  File "/home/airflow/.local/lib/python3.12/site-packages/urllib3/connection.py", line 218, in _new_conn
    raise NewConnectionError(
urllib3.exceptions.NewConnectionError: <urllib3.connection.HTTPConnection object at 0x7286304c8110>: Failed to establish a new connection: [Errno 111] Connection refused

The above exception was the direct cause of the following exception:

Traceback (most recent call last):
  File "/home/airflow/.local/lib/python3.12/site-packages/airflow/models/taskinstance.py", line 2479, in _run_raw_task
    self._execute_task_with_callbacks(context, test_mode, session=session)
  File "/home/airflow/.local/lib/python3.12/site-packages/airflow/models/taskinstance.py", line 2676, in _execute_task_with_callbacks
    result = self._execute_task(context, task_orig)
             ^^^^^^^^^^^^^^^^^^^^^^^^^^^^^^^^^^^^^^
  File "/home/airflow/.local/lib/python3.12/site-packages/airflow/models/taskinstance.py", line 2701, in _execute_task
    return _execute_task(self, context, task_orig)
           ^^^^^^^^^^^^^^^^^^^^^^^^^^^^^^^^^^^^^^^
  File "/home/airflow/.local/lib/python3.12/site-packages/airflow/models/taskinstance.py", line 465, in _execute_task
    result = _execute_callable(context=context, **execute_callable_kwargs)
             ^^^^^^^^^^^^^^^^^^^^^^^^^^^^^^^^^^^^^^^^^^^^^^^^^^^^^^^^^^^^^
  File "/home/airflow/.local/lib/python3.12/site-packages/airflow/models/taskinstance.py", line 432, in _execute_callable
    return execute_callable(context=context, **execute_callable_kwargs)
           ^^^^^^^^^^^^^^^^^^^^^^^^^^^^^^^^^^^^^^^^^^^^^^^^^^^^^^^^^^^^
  File "/home/airflow/.local/lib/python3.12/site-packages/airflow/models/baseoperator.py", line 401, in wrapper
    return func(self, *args, **kwargs)
           ^^^^^^^^^^^^^^^^^^^^^^^^^^^
  File "/home/airflow/.local/lib/python3.12/site-packages/airflow/operators/python.py", line 235, in execute
    return_value = self.execute_callable()
                   ^^^^^^^^^^^^^^^^^^^^^^^
  File "/home/airflow/.local/lib/python3.12/site-packages/airflow/operators/python.py", line 252, in execute_callable
    return self.python_callable(*self.op_args, **self.op_kwargs)
           ^^^^^^^^^^^^^^^^^^^^^^^^^^^^^^^^^^^^^^^^^^^^^^^^^^^^^
  File "/opt/airflow/dags/gps/custom_dags/motower_daily.py", line 84, in clean_congestion
    data = cleaning_congestion(CLIENT, kwargs['ingest_date'])
           ^^^^^^^^^^^^^^^^^^^^^^^^^^^^^^^^^^^^^^^^^^^^^^^^^^
  File "/opt/airflow/dags/gps/common/motower_daily.py", line 289, in cleaning_congestion
    if not client.bucket_exists(objet["bucket"]):
           ^^^^^^^^^^^^^^^^^^^^^^^^^^^^^^^^^^^^^
  File "/home/airflow/.local/lib/python3.12/site-packages/minio/api.py", line 696, in bucket_exists
    self._execute("HEAD", bucket_name)
  File "/home/airflow/.local/lib/python3.12/site-packages/minio/api.py", line 437, in _execute
    region = self._get_region(bucket_name)
             ^^^^^^^^^^^^^^^^^^^^^^^^^^^^^
  File "/home/airflow/.local/lib/python3.12/site-packages/minio/api.py", line 494, in _get_region
    response = self._url_open(
               ^^^^^^^^^^^^^^^
  File "/home/airflow/.local/lib/python3.12/site-packages/minio/api.py", line 302, in _url_open
    response = self._http.urlopen(
               ^^^^^^^^^^^^^^^^^^^
  File "/home/airflow/.local/lib/python3.12/site-packages/urllib3/poolmanager.py", line 443, in urlopen
    response = conn.urlopen(method, u.request_uri, **kw)
               ^^^^^^^^^^^^^^^^^^^^^^^^^^^^^^^^^^^^^^^^^
  File "/home/airflow/.local/lib/python3.12/site-packages/urllib3/connectionpool.py", line 875, in urlopen
    return self.urlopen(
           ^^^^^^^^^^^^^
  File "/home/airflow/.local/lib/python3.12/site-packages/urllib3/connectionpool.py", line 875, in urlopen
    return self.urlopen(
           ^^^^^^^^^^^^^
  File "/home/airflow/.local/lib/python3.12/site-packages/urllib3/connectionpool.py", line 875, in urlopen
    return self.urlopen(
           ^^^^^^^^^^^^^
  [Previous line repeated 2 more times]
  File "/home/airflow/.local/lib/python3.12/site-packages/urllib3/connectionpool.py", line 845, in urlopen
    retries = retries.increment(
              ^^^^^^^^^^^^^^^^^^
  File "/home/airflow/.local/lib/python3.12/site-packages/urllib3/util/retry.py", line 515, in increment
    raise MaxRetryError(_pool, url, reason) from reason  # type: ignore[arg-type]
    ^^^^^^^^^^^^^^^^^^^^^^^^^^^^^^^^^^^^^^^^^^^^^^^^^^^
urllib3.exceptions.MaxRetryError: HTTPConnectionPool(host='minio', port=80): Max retries exceeded with url: /motower?location= (Caused by NewConnectionError('<urllib3.connection.HTTPConnection object at 0x7286304c8110>: Failed to establish a new connection: [Errno 111] Connection refused'))

During handling of the above exception, another exception occurred:

Traceback (most recent call last):
  File "/home/airflow/.local/lib/python3.12/site-packages/airflow/models/taskinstance.py", line 1063, in _email_alert
    send_email(task.email, subject, html_content)
  File "/home/airflow/.local/lib/python3.12/site-packages/airflow/utils/email.py", line 80, in send_email
    return backend(
           ^^^^^^^^
  File "/home/airflow/.local/lib/python3.12/site-packages/airflow/utils/email.py", line 154, in send_email_smtp
    send_mime_email(e_from=mail_from, e_to=recipients, mime_msg=msg, conn_id=conn_id, dryrun=dryrun)
  File "/home/airflow/.local/lib/python3.12/site-packages/airflow/utils/email.py", line 273, in send_mime_email
    smtp_conn = _get_smtp_connection(smtp_host, smtp_port, smtp_timeout, smtp_ssl)
                ^^^^^^^^^^^^^^^^^^^^^^^^^^^^^^^^^^^^^^^^^^^^^^^^^^^^^^^^^^^^^^^^^^
  File "/home/airflow/.local/lib/python3.12/site-packages/airflow/utils/email.py", line 317, in _get_smtp_connection
    return smtplib.SMTP(host=host, port=port, timeout=timeout)
           ^^^^^^^^^^^^^^^^^^^^^^^^^^^^^^^^^^^^^^^^^^^^^^^^^^^
  File "/usr/local/lib/python3.12/smtplib.py", line 255, in __init__
    (code, msg) = self.connect(host, port)
                  ^^^^^^^^^^^^^^^^^^^^^^^^
  File "/usr/local/lib/python3.12/smtplib.py", line 341, in connect
    self.sock = self._get_socket(host, port, self.timeout)
                ^^^^^^^^^^^^^^^^^^^^^^^^^^^^^^^^^^^^^^^^^^
  File "/usr/local/lib/python3.12/smtplib.py", line 312, in _get_socket
    return socket.create_connection((host, port), timeout,
           ^^^^^^^^^^^^^^^^^^^^^^^^^^^^^^^^^^^^^^^^^^^^^^^
  File "/usr/local/lib/python3.12/socket.py", line 853, in create_connection
    raise exceptions[0]
  File "/usr/local/lib/python3.12/socket.py", line 838, in create_connection
    sock.connect(sa)
ConnectionRefusedError: [Errno 111] Connection refused

During handling of the above exception, another exception occurred:

Traceback (most recent call last):
  File "/home/airflow/.local/lib/python3.12/site-packages/airflow/models/taskinstance.py", line 877, in _handle_failure
    task_instance.email_alert(error, failure_context["task"])
  File "/home/airflow/.local/lib/python3.12/site-packages/airflow/models/taskinstance.py", line 3163, in email_alert
    _email_alert(task_instance=self, exception=exception, task=task)
  File "/home/airflow/.local/lib/python3.12/site-packages/airflow/models/taskinstance.py", line 1065, in _email_alert
    send_email(task.email, subject, html_content_err)
  File "/home/airflow/.local/lib/python3.12/site-packages/airflow/utils/email.py", line 80, in send_email
    return backend(
           ^^^^^^^^
  File "/home/airflow/.local/lib/python3.12/site-packages/airflow/utils/email.py", line 154, in send_email_smtp
    send_mime_email(e_from=mail_from, e_to=recipients, mime_msg=msg, conn_id=conn_id, dryrun=dryrun)
  File "/home/airflow/.local/lib/python3.12/site-packages/airflow/utils/email.py", line 273, in send_mime_email
    smtp_conn = _get_smtp_connection(smtp_host, smtp_port, smtp_timeout, smtp_ssl)
                ^^^^^^^^^^^^^^^^^^^^^^^^^^^^^^^^^^^^^^^^^^^^^^^^^^^^^^^^^^^^^^^^^^
  File "/home/airflow/.local/lib/python3.12/site-packages/airflow/utils/email.py", line 317, in _get_smtp_connection
    return smtplib.SMTP(host=host, port=port, timeout=timeout)
           ^^^^^^^^^^^^^^^^^^^^^^^^^^^^^^^^^^^^^^^^^^^^^^^^^^^
  File "/usr/local/lib/python3.12/smtplib.py", line 255, in __init__
    (code, msg) = self.connect(host, port)
                  ^^^^^^^^^^^^^^^^^^^^^^^^
  File "/usr/local/lib/python3.12/smtplib.py", line 341, in connect
    self.sock = self._get_socket(host, port, self.timeout)
                ^^^^^^^^^^^^^^^^^^^^^^^^^^^^^^^^^^^^^^^^^^
  File "/usr/local/lib/python3.12/smtplib.py", line 312, in _get_socket
    return socket.create_connection((host, port), timeout,
           ^^^^^^^^^^^^^^^^^^^^^^^^^^^^^^^^^^^^^^^^^^^^^^^
  File "/usr/local/lib/python3.12/socket.py", line 853, in create_connection
    raise exceptions[0]
  File "/usr/local/lib/python3.12/socket.py", line 838, in create_connection
    sock.connect(sa)
ConnectionRefusedError: [Errno 111] Connection refused
[2024-07-22T16:57:02.255+0000] {standard_task_runner.py:110} ERROR - Failed to execute job 64 for task gen_congestion_task (HTTPConnectionPool(host='minio', port=80): Max retries exceeded with url: /motower?location= (Caused by NewConnectionError('<urllib3.connection.HTTPConnection object at 0x7286304c8110>: Failed to establish a new connection: [Errno 111] Connection refused')); 889)
[2024-07-22T16:57:02.293+0000] {local_task_job_runner.py:243} INFO - Task exited with return code 1
[2024-07-22T16:57:02.310+0000] {taskinstance.py:3503} INFO - 0 downstream tasks scheduled from follow-on schedule check
[2024-07-22T16:57:02.312+0000] {local_task_job_runner.py:222} INFO - ::endgroup::
[2024-07-22T17:16:09.355+0000] {local_task_job_runner.py:120} INFO - ::group::Pre task execution logs
[2024-07-22T17:16:09.386+0000] {taskinstance.py:2076} INFO - Dependencies all met for dep_context=non-requeueable deps ti=<TaskInstance: motower_daily_prod.gen_congestion_task scheduled__2024-06-25T06:00:00+00:00 [queued]>
[2024-07-22T17:16:09.399+0000] {taskinstance.py:2076} INFO - Dependencies all met for dep_context=requeueable deps ti=<TaskInstance: motower_daily_prod.gen_congestion_task scheduled__2024-06-25T06:00:00+00:00 [queued]>
[2024-07-22T17:16:09.399+0000] {taskinstance.py:2306} INFO - Starting attempt 1 of 1
[2024-07-22T17:16:09.418+0000] {taskinstance.py:2330} INFO - Executing <Task(PythonOperator): gen_congestion_task> on 2024-06-25 06:00:00+00:00
[2024-07-22T17:16:09.431+0000] {warnings.py:112} WARNING - /home/***/.local/lib/python3.12/site-packages/***/task/task_runner/standard_task_runner.py:62: DeprecationWarning: This process (pid=1260) is multi-threaded, use of fork() may lead to deadlocks in the child.
  pid = os.fork()

[2024-07-22T17:16:09.433+0000] {standard_task_runner.py:64} INFO - Started process 1278 to run task
[2024-07-22T17:16:09.433+0000] {standard_task_runner.py:90} INFO - Running: ['***', 'tasks', 'run', 'motower_daily_prod', 'gen_congestion_task', 'scheduled__2024-06-25T06:00:00+00:00', '--job-id', '115', '--raw', '--subdir', 'DAGS_FOLDER/gps/custom_dags/motower_daily.py', '--cfg-path', '/tmp/tmpa5c1p8ev']
[2024-07-22T17:16:09.437+0000] {standard_task_runner.py:91} INFO - Job 115: Subtask gen_congestion_task
[2024-07-22T17:16:09.501+0000] {task_command.py:426} INFO - Running <TaskInstance: motower_daily_prod.gen_congestion_task scheduled__2024-06-25T06:00:00+00:00 [running]> on host 5e959f2258db
[2024-07-22T17:16:09.621+0000] {taskinstance.py:2648} INFO - Exporting env vars: AIRFLOW_CTX_DAG_EMAIL='richmond.kongo@orange.com,assane.diop@orange.com,cyrille1.danho@orange.com,mohamed2.sylla@orange.com,amadou.diomande@orange.com,Jonas.kouame@orange.com,armand.kablan@orange.com,anicet.azombade@orange.com,etienne.kouadio@orange.com,bertine.kouakou@orange.com,florentine.kouakou@orange.com,ange.phaceli@orange.com,soulegame.soro@orange.com,innocent.yengo@orange.com' AIRFLOW_CTX_DAG_OWNER='***' AIRFLOW_CTX_DAG_ID='motower_daily_prod' AIRFLOW_CTX_TASK_ID='gen_congestion_task' AIRFLOW_CTX_EXECUTION_DATE='2024-06-25T06:00:00+00:00' AIRFLOW_CTX_TRY_NUMBER='1' AIRFLOW_CTX_DAG_RUN_ID='scheduled__2024-06-25T06:00:00+00:00'
[2024-07-22T17:16:09.622+0000] {taskinstance.py:430} INFO - ::endgroup::
[2024-07-22T17:16:09.643+0000] {connectionpool.py:872} WARNING - Retrying (Retry(total=4, connect=None, read=None, redirect=None, status=None)) after connection broken by 'NewConnectionError('<urllib3.connection.HTTPConnection object at 0x72863031d3d0>: Failed to establish a new connection: [Errno 111] Connection refused')': /motower?location=
[2024-07-22T17:16:10.045+0000] {connectionpool.py:872} WARNING - Retrying (Retry(total=3, connect=None, read=None, redirect=None, status=None)) after connection broken by 'NewConnectionError('<urllib3.connection.HTTPConnection object at 0x72863031d9a0>: Failed to establish a new connection: [Errno 111] Connection refused')': /motower?location=
[2024-07-22T17:16:10.847+0000] {connectionpool.py:872} WARNING - Retrying (Retry(total=2, connect=None, read=None, redirect=None, status=None)) after connection broken by 'NewConnectionError('<urllib3.connection.HTTPConnection object at 0x72863031e210>: Failed to establish a new connection: [Errno 111] Connection refused')': /motower?location=
[2024-07-22T17:16:12.449+0000] {connectionpool.py:872} WARNING - Retrying (Retry(total=1, connect=None, read=None, redirect=None, status=None)) after connection broken by 'NewConnectionError('<urllib3.connection.HTTPConnection object at 0x72863031e690>: Failed to establish a new connection: [Errno 111] Connection refused')': /motower?location=
[2024-07-22T17:16:15.651+0000] {connectionpool.py:872} WARNING - Retrying (Retry(total=0, connect=None, read=None, redirect=None, status=None)) after connection broken by 'NewConnectionError('<urllib3.connection.HTTPConnection object at 0x72863031eb70>: Failed to establish a new connection: [Errno 111] Connection refused')': /motower?location=
[2024-07-22T17:16:15.652+0000] {taskinstance.py:441} INFO - ::group::Post task execution logs
[2024-07-22T17:16:15.653+0000] {taskinstance.py:2905} ERROR - Task failed with exception
Traceback (most recent call last):
  File "/home/airflow/.local/lib/python3.12/site-packages/urllib3/connection.py", line 203, in _new_conn
    sock = connection.create_connection(
           ^^^^^^^^^^^^^^^^^^^^^^^^^^^^^
  File "/home/airflow/.local/lib/python3.12/site-packages/urllib3/util/connection.py", line 85, in create_connection
    raise err
  File "/home/airflow/.local/lib/python3.12/site-packages/urllib3/util/connection.py", line 73, in create_connection
    sock.connect(sa)
ConnectionRefusedError: [Errno 111] Connection refused

The above exception was the direct cause of the following exception:

Traceback (most recent call last):
  File "/home/airflow/.local/lib/python3.12/site-packages/urllib3/connectionpool.py", line 791, in urlopen
    response = self._make_request(
               ^^^^^^^^^^^^^^^^^^^
  File "/home/airflow/.local/lib/python3.12/site-packages/urllib3/connectionpool.py", line 497, in _make_request
    conn.request(
  File "/home/airflow/.local/lib/python3.12/site-packages/urllib3/connection.py", line 395, in request
    self.endheaders()
  File "/usr/local/lib/python3.12/http/client.py", line 1331, in endheaders
    self._send_output(message_body, encode_chunked=encode_chunked)
  File "/usr/local/lib/python3.12/http/client.py", line 1091, in _send_output
    self.send(msg)
  File "/usr/local/lib/python3.12/http/client.py", line 1035, in send
    self.connect()
  File "/home/airflow/.local/lib/python3.12/site-packages/urllib3/connection.py", line 243, in connect
    self.sock = self._new_conn()
                ^^^^^^^^^^^^^^^^
  File "/home/airflow/.local/lib/python3.12/site-packages/urllib3/connection.py", line 218, in _new_conn
    raise NewConnectionError(
urllib3.exceptions.NewConnectionError: <urllib3.connection.HTTPConnection object at 0x72863031f020>: Failed to establish a new connection: [Errno 111] Connection refused

The above exception was the direct cause of the following exception:

Traceback (most recent call last):
  File "/home/airflow/.local/lib/python3.12/site-packages/airflow/models/taskinstance.py", line 465, in _execute_task
    result = _execute_callable(context=context, **execute_callable_kwargs)
             ^^^^^^^^^^^^^^^^^^^^^^^^^^^^^^^^^^^^^^^^^^^^^^^^^^^^^^^^^^^^^
  File "/home/airflow/.local/lib/python3.12/site-packages/airflow/models/taskinstance.py", line 432, in _execute_callable
    return execute_callable(context=context, **execute_callable_kwargs)
           ^^^^^^^^^^^^^^^^^^^^^^^^^^^^^^^^^^^^^^^^^^^^^^^^^^^^^^^^^^^^
  File "/home/airflow/.local/lib/python3.12/site-packages/airflow/models/baseoperator.py", line 401, in wrapper
    return func(self, *args, **kwargs)
           ^^^^^^^^^^^^^^^^^^^^^^^^^^^
  File "/home/airflow/.local/lib/python3.12/site-packages/airflow/operators/python.py", line 235, in execute
    return_value = self.execute_callable()
                   ^^^^^^^^^^^^^^^^^^^^^^^
  File "/home/airflow/.local/lib/python3.12/site-packages/airflow/operators/python.py", line 252, in execute_callable
    return self.python_callable(*self.op_args, **self.op_kwargs)
           ^^^^^^^^^^^^^^^^^^^^^^^^^^^^^^^^^^^^^^^^^^^^^^^^^^^^^
  File "/opt/airflow/dags/gps/custom_dags/motower_daily.py", line 85, in clean_congestion
    data = cleaning_congestion(CLIENT, kwargs['ingest_date'])
           ^^^^^^^^^^^^^^^^^^^^^^^^^^^^^^^^^^^^^^^^^^^^^^^^^^
  File "/opt/airflow/dags/gps/common/motower_daily.py", line 289, in cleaning_congestion
    if not client.bucket_exists(objet["bucket"]):
           ^^^^^^^^^^^^^^^^^^^^^^^^^^^^^^^^^^^^^
  File "/home/airflow/.local/lib/python3.12/site-packages/minio/api.py", line 696, in bucket_exists
    self._execute("HEAD", bucket_name)
  File "/home/airflow/.local/lib/python3.12/site-packages/minio/api.py", line 437, in _execute
    region = self._get_region(bucket_name)
             ^^^^^^^^^^^^^^^^^^^^^^^^^^^^^
  File "/home/airflow/.local/lib/python3.12/site-packages/minio/api.py", line 494, in _get_region
    response = self._url_open(
               ^^^^^^^^^^^^^^^
  File "/home/airflow/.local/lib/python3.12/site-packages/minio/api.py", line 302, in _url_open
    response = self._http.urlopen(
               ^^^^^^^^^^^^^^^^^^^
  File "/home/airflow/.local/lib/python3.12/site-packages/urllib3/poolmanager.py", line 443, in urlopen
    response = conn.urlopen(method, u.request_uri, **kw)
               ^^^^^^^^^^^^^^^^^^^^^^^^^^^^^^^^^^^^^^^^^
  File "/home/airflow/.local/lib/python3.12/site-packages/urllib3/connectionpool.py", line 875, in urlopen
    return self.urlopen(
           ^^^^^^^^^^^^^
  File "/home/airflow/.local/lib/python3.12/site-packages/urllib3/connectionpool.py", line 875, in urlopen
    return self.urlopen(
           ^^^^^^^^^^^^^
  File "/home/airflow/.local/lib/python3.12/site-packages/urllib3/connectionpool.py", line 875, in urlopen
    return self.urlopen(
           ^^^^^^^^^^^^^
  [Previous line repeated 2 more times]
  File "/home/airflow/.local/lib/python3.12/site-packages/urllib3/connectionpool.py", line 845, in urlopen
    retries = retries.increment(
              ^^^^^^^^^^^^^^^^^^
  File "/home/airflow/.local/lib/python3.12/site-packages/urllib3/util/retry.py", line 515, in increment
    raise MaxRetryError(_pool, url, reason) from reason  # type: ignore[arg-type]
    ^^^^^^^^^^^^^^^^^^^^^^^^^^^^^^^^^^^^^^^^^^^^^^^^^^^
urllib3.exceptions.MaxRetryError: HTTPConnectionPool(host='minio', port=80): Max retries exceeded with url: /motower?location= (Caused by NewConnectionError('<urllib3.connection.HTTPConnection object at 0x72863031f020>: Failed to establish a new connection: [Errno 111] Connection refused'))
[2024-07-22T17:16:15.667+0000] {taskinstance.py:1206} INFO - Marking task as FAILED. dag_id=motower_daily_prod, task_id=gen_congestion_task, run_id=scheduled__2024-06-25T06:00:00+00:00, execution_date=20240625T060000, start_date=20240722T171609, end_date=20240722T171615
[2024-07-22T17:16:15.682+0000] {warnings.py:112} WARNING - /home/***/.local/lib/python3.12/site-packages/***/utils/email.py:154: RemovedInAirflow3Warning: Fetching SMTP credentials from configuration variables will be deprecated in a future release. Please set credentials using a connection instead.
  send_mime_email(e_from=mail_from, e_to=recipients, mime_msg=msg, conn_id=conn_id, dryrun=dryrun)

[2024-07-22T17:16:15.682+0000] {configuration.py:1053} WARNING - section/key [smtp/smtp_user] not found in config
[2024-07-22T17:16:15.683+0000] {email.py:271} INFO - Email alerting: attempt 1
[2024-07-22T17:16:15.691+0000] {configuration.py:1053} WARNING - section/key [smtp/smtp_user] not found in config
[2024-07-22T17:16:15.691+0000] {email.py:271} INFO - Email alerting: attempt 1
[2024-07-22T17:16:15.692+0000] {taskinstance.py:879} ERROR - Failed to send email to: ['richmond.kongo@orange.com', 'assane.diop@orange.com', 'cyrille1.danho@orange.com', 'mohamed2.sylla@orange.com', 'amadou.diomande@orange.com', 'Jonas.kouame@orange.com', 'armand.kablan@orange.com', 'anicet.azombade@orange.com', 'etienne.kouadio@orange.com', 'bertine.kouakou@orange.com', 'florentine.kouakou@orange.com', 'ange.phaceli@orange.com', 'soulegame.soro@orange.com', 'innocent.yengo@orange.com']
Traceback (most recent call last):
  File "/home/airflow/.local/lib/python3.12/site-packages/urllib3/connection.py", line 203, in _new_conn
    sock = connection.create_connection(
           ^^^^^^^^^^^^^^^^^^^^^^^^^^^^^
  File "/home/airflow/.local/lib/python3.12/site-packages/urllib3/util/connection.py", line 85, in create_connection
    raise err
  File "/home/airflow/.local/lib/python3.12/site-packages/urllib3/util/connection.py", line 73, in create_connection
    sock.connect(sa)
ConnectionRefusedError: [Errno 111] Connection refused

The above exception was the direct cause of the following exception:

Traceback (most recent call last):
  File "/home/airflow/.local/lib/python3.12/site-packages/urllib3/connectionpool.py", line 791, in urlopen
    response = self._make_request(
               ^^^^^^^^^^^^^^^^^^^
  File "/home/airflow/.local/lib/python3.12/site-packages/urllib3/connectionpool.py", line 497, in _make_request
    conn.request(
  File "/home/airflow/.local/lib/python3.12/site-packages/urllib3/connection.py", line 395, in request
    self.endheaders()
  File "/usr/local/lib/python3.12/http/client.py", line 1331, in endheaders
    self._send_output(message_body, encode_chunked=encode_chunked)
  File "/usr/local/lib/python3.12/http/client.py", line 1091, in _send_output
    self.send(msg)
  File "/usr/local/lib/python3.12/http/client.py", line 1035, in send
    self.connect()
  File "/home/airflow/.local/lib/python3.12/site-packages/urllib3/connection.py", line 243, in connect
    self.sock = self._new_conn()
                ^^^^^^^^^^^^^^^^
  File "/home/airflow/.local/lib/python3.12/site-packages/urllib3/connection.py", line 218, in _new_conn
    raise NewConnectionError(
urllib3.exceptions.NewConnectionError: <urllib3.connection.HTTPConnection object at 0x72863031f020>: Failed to establish a new connection: [Errno 111] Connection refused

The above exception was the direct cause of the following exception:

Traceback (most recent call last):
  File "/home/airflow/.local/lib/python3.12/site-packages/airflow/models/taskinstance.py", line 2479, in _run_raw_task
    self._execute_task_with_callbacks(context, test_mode, session=session)
  File "/home/airflow/.local/lib/python3.12/site-packages/airflow/models/taskinstance.py", line 2676, in _execute_task_with_callbacks
    result = self._execute_task(context, task_orig)
             ^^^^^^^^^^^^^^^^^^^^^^^^^^^^^^^^^^^^^^
  File "/home/airflow/.local/lib/python3.12/site-packages/airflow/models/taskinstance.py", line 2701, in _execute_task
    return _execute_task(self, context, task_orig)
           ^^^^^^^^^^^^^^^^^^^^^^^^^^^^^^^^^^^^^^^
  File "/home/airflow/.local/lib/python3.12/site-packages/airflow/models/taskinstance.py", line 465, in _execute_task
    result = _execute_callable(context=context, **execute_callable_kwargs)
             ^^^^^^^^^^^^^^^^^^^^^^^^^^^^^^^^^^^^^^^^^^^^^^^^^^^^^^^^^^^^^
  File "/home/airflow/.local/lib/python3.12/site-packages/airflow/models/taskinstance.py", line 432, in _execute_callable
    return execute_callable(context=context, **execute_callable_kwargs)
           ^^^^^^^^^^^^^^^^^^^^^^^^^^^^^^^^^^^^^^^^^^^^^^^^^^^^^^^^^^^^
  File "/home/airflow/.local/lib/python3.12/site-packages/airflow/models/baseoperator.py", line 401, in wrapper
    return func(self, *args, **kwargs)
           ^^^^^^^^^^^^^^^^^^^^^^^^^^^
  File "/home/airflow/.local/lib/python3.12/site-packages/airflow/operators/python.py", line 235, in execute
    return_value = self.execute_callable()
                   ^^^^^^^^^^^^^^^^^^^^^^^
  File "/home/airflow/.local/lib/python3.12/site-packages/airflow/operators/python.py", line 252, in execute_callable
    return self.python_callable(*self.op_args, **self.op_kwargs)
           ^^^^^^^^^^^^^^^^^^^^^^^^^^^^^^^^^^^^^^^^^^^^^^^^^^^^^
  File "/opt/airflow/dags/gps/custom_dags/motower_daily.py", line 85, in clean_congestion
    data = cleaning_congestion(CLIENT, kwargs['ingest_date'])
           ^^^^^^^^^^^^^^^^^^^^^^^^^^^^^^^^^^^^^^^^^^^^^^^^^^
  File "/opt/airflow/dags/gps/common/motower_daily.py", line 289, in cleaning_congestion
    if not client.bucket_exists(objet["bucket"]):
           ^^^^^^^^^^^^^^^^^^^^^^^^^^^^^^^^^^^^^
  File "/home/airflow/.local/lib/python3.12/site-packages/minio/api.py", line 696, in bucket_exists
    self._execute("HEAD", bucket_name)
  File "/home/airflow/.local/lib/python3.12/site-packages/minio/api.py", line 437, in _execute
    region = self._get_region(bucket_name)
             ^^^^^^^^^^^^^^^^^^^^^^^^^^^^^
  File "/home/airflow/.local/lib/python3.12/site-packages/minio/api.py", line 494, in _get_region
    response = self._url_open(
               ^^^^^^^^^^^^^^^
  File "/home/airflow/.local/lib/python3.12/site-packages/minio/api.py", line 302, in _url_open
    response = self._http.urlopen(
               ^^^^^^^^^^^^^^^^^^^
  File "/home/airflow/.local/lib/python3.12/site-packages/urllib3/poolmanager.py", line 443, in urlopen
    response = conn.urlopen(method, u.request_uri, **kw)
               ^^^^^^^^^^^^^^^^^^^^^^^^^^^^^^^^^^^^^^^^^
  File "/home/airflow/.local/lib/python3.12/site-packages/urllib3/connectionpool.py", line 875, in urlopen
    return self.urlopen(
           ^^^^^^^^^^^^^
  File "/home/airflow/.local/lib/python3.12/site-packages/urllib3/connectionpool.py", line 875, in urlopen
    return self.urlopen(
           ^^^^^^^^^^^^^
  File "/home/airflow/.local/lib/python3.12/site-packages/urllib3/connectionpool.py", line 875, in urlopen
    return self.urlopen(
           ^^^^^^^^^^^^^
  [Previous line repeated 2 more times]
  File "/home/airflow/.local/lib/python3.12/site-packages/urllib3/connectionpool.py", line 845, in urlopen
    retries = retries.increment(
              ^^^^^^^^^^^^^^^^^^
  File "/home/airflow/.local/lib/python3.12/site-packages/urllib3/util/retry.py", line 515, in increment
    raise MaxRetryError(_pool, url, reason) from reason  # type: ignore[arg-type]
    ^^^^^^^^^^^^^^^^^^^^^^^^^^^^^^^^^^^^^^^^^^^^^^^^^^^
urllib3.exceptions.MaxRetryError: HTTPConnectionPool(host='minio', port=80): Max retries exceeded with url: /motower?location= (Caused by NewConnectionError('<urllib3.connection.HTTPConnection object at 0x72863031f020>: Failed to establish a new connection: [Errno 111] Connection refused'))

During handling of the above exception, another exception occurred:

Traceback (most recent call last):
  File "/home/airflow/.local/lib/python3.12/site-packages/airflow/models/taskinstance.py", line 1063, in _email_alert
    send_email(task.email, subject, html_content)
  File "/home/airflow/.local/lib/python3.12/site-packages/airflow/utils/email.py", line 80, in send_email
    return backend(
           ^^^^^^^^
  File "/home/airflow/.local/lib/python3.12/site-packages/airflow/utils/email.py", line 154, in send_email_smtp
    send_mime_email(e_from=mail_from, e_to=recipients, mime_msg=msg, conn_id=conn_id, dryrun=dryrun)
  File "/home/airflow/.local/lib/python3.12/site-packages/airflow/utils/email.py", line 273, in send_mime_email
    smtp_conn = _get_smtp_connection(smtp_host, smtp_port, smtp_timeout, smtp_ssl)
                ^^^^^^^^^^^^^^^^^^^^^^^^^^^^^^^^^^^^^^^^^^^^^^^^^^^^^^^^^^^^^^^^^^
  File "/home/airflow/.local/lib/python3.12/site-packages/airflow/utils/email.py", line 317, in _get_smtp_connection
    return smtplib.SMTP(host=host, port=port, timeout=timeout)
           ^^^^^^^^^^^^^^^^^^^^^^^^^^^^^^^^^^^^^^^^^^^^^^^^^^^
  File "/usr/local/lib/python3.12/smtplib.py", line 255, in __init__
    (code, msg) = self.connect(host, port)
                  ^^^^^^^^^^^^^^^^^^^^^^^^
  File "/usr/local/lib/python3.12/smtplib.py", line 341, in connect
    self.sock = self._get_socket(host, port, self.timeout)
                ^^^^^^^^^^^^^^^^^^^^^^^^^^^^^^^^^^^^^^^^^^
  File "/usr/local/lib/python3.12/smtplib.py", line 312, in _get_socket
    return socket.create_connection((host, port), timeout,
           ^^^^^^^^^^^^^^^^^^^^^^^^^^^^^^^^^^^^^^^^^^^^^^^
  File "/usr/local/lib/python3.12/socket.py", line 853, in create_connection
    raise exceptions[0]
  File "/usr/local/lib/python3.12/socket.py", line 838, in create_connection
    sock.connect(sa)
ConnectionRefusedError: [Errno 111] Connection refused

During handling of the above exception, another exception occurred:

Traceback (most recent call last):
  File "/home/airflow/.local/lib/python3.12/site-packages/airflow/models/taskinstance.py", line 877, in _handle_failure
    task_instance.email_alert(error, failure_context["task"])
  File "/home/airflow/.local/lib/python3.12/site-packages/airflow/models/taskinstance.py", line 3163, in email_alert
    _email_alert(task_instance=self, exception=exception, task=task)
  File "/home/airflow/.local/lib/python3.12/site-packages/airflow/models/taskinstance.py", line 1065, in _email_alert
    send_email(task.email, subject, html_content_err)
  File "/home/airflow/.local/lib/python3.12/site-packages/airflow/utils/email.py", line 80, in send_email
    return backend(
           ^^^^^^^^
  File "/home/airflow/.local/lib/python3.12/site-packages/airflow/utils/email.py", line 154, in send_email_smtp
    send_mime_email(e_from=mail_from, e_to=recipients, mime_msg=msg, conn_id=conn_id, dryrun=dryrun)
  File "/home/airflow/.local/lib/python3.12/site-packages/airflow/utils/email.py", line 273, in send_mime_email
    smtp_conn = _get_smtp_connection(smtp_host, smtp_port, smtp_timeout, smtp_ssl)
                ^^^^^^^^^^^^^^^^^^^^^^^^^^^^^^^^^^^^^^^^^^^^^^^^^^^^^^^^^^^^^^^^^^
  File "/home/airflow/.local/lib/python3.12/site-packages/airflow/utils/email.py", line 317, in _get_smtp_connection
    return smtplib.SMTP(host=host, port=port, timeout=timeout)
           ^^^^^^^^^^^^^^^^^^^^^^^^^^^^^^^^^^^^^^^^^^^^^^^^^^^
  File "/usr/local/lib/python3.12/smtplib.py", line 255, in __init__
    (code, msg) = self.connect(host, port)
                  ^^^^^^^^^^^^^^^^^^^^^^^^
  File "/usr/local/lib/python3.12/smtplib.py", line 341, in connect
    self.sock = self._get_socket(host, port, self.timeout)
                ^^^^^^^^^^^^^^^^^^^^^^^^^^^^^^^^^^^^^^^^^^
  File "/usr/local/lib/python3.12/smtplib.py", line 312, in _get_socket
    return socket.create_connection((host, port), timeout,
           ^^^^^^^^^^^^^^^^^^^^^^^^^^^^^^^^^^^^^^^^^^^^^^^
  File "/usr/local/lib/python3.12/socket.py", line 853, in create_connection
    raise exceptions[0]
  File "/usr/local/lib/python3.12/socket.py", line 838, in create_connection
    sock.connect(sa)
ConnectionRefusedError: [Errno 111] Connection refused
[2024-07-22T17:16:15.710+0000] {standard_task_runner.py:110} ERROR - Failed to execute job 115 for task gen_congestion_task (HTTPConnectionPool(host='minio', port=80): Max retries exceeded with url: /motower?location= (Caused by NewConnectionError('<urllib3.connection.HTTPConnection object at 0x72863031f020>: Failed to establish a new connection: [Errno 111] Connection refused')); 1278)
[2024-07-22T17:16:15.752+0000] {local_task_job_runner.py:243} INFO - Task exited with return code 1
[2024-07-22T17:16:15.772+0000] {taskinstance.py:3503} INFO - 0 downstream tasks scheduled from follow-on schedule check
[2024-07-22T17:16:15.774+0000] {local_task_job_runner.py:222} INFO - ::endgroup::
[2024-07-22T17:43:22.391+0000] {local_task_job_runner.py:120} INFO - ::group::Pre task execution logs
[2024-07-22T17:43:22.717+0000] {taskinstance.py:2076} INFO - Dependencies all met for dep_context=non-requeueable deps ti=<TaskInstance: motower_daily_prod.gen_congestion_task scheduled__2024-06-25T06:00:00+00:00 [queued]>
[2024-07-22T17:43:22.732+0000] {taskinstance.py:2076} INFO - Dependencies all met for dep_context=requeueable deps ti=<TaskInstance: motower_daily_prod.gen_congestion_task scheduled__2024-06-25T06:00:00+00:00 [queued]>
[2024-07-22T17:43:22.732+0000] {taskinstance.py:2306} INFO - Starting attempt 1 of 1
[2024-07-22T17:43:22.752+0000] {taskinstance.py:2330} INFO - Executing <Task(PythonOperator): gen_congestion_task> on 2024-06-25 06:00:00+00:00
[2024-07-22T17:43:22.766+0000] {warnings.py:112} WARNING - /home/***/.local/lib/python3.12/site-packages/***/task/task_runner/standard_task_runner.py:62: DeprecationWarning: This process (pid=1717) is multi-threaded, use of fork() may lead to deadlocks in the child.
  pid = os.fork()

[2024-07-22T17:43:22.767+0000] {standard_task_runner.py:64} INFO - Started process 1735 to run task
[2024-07-22T17:43:22.768+0000] {standard_task_runner.py:90} INFO - Running: ['***', 'tasks', 'run', 'motower_daily_prod', 'gen_congestion_task', 'scheduled__2024-06-25T06:00:00+00:00', '--job-id', '146', '--raw', '--subdir', 'DAGS_FOLDER/gps/custom_dags/motower_daily.py', '--cfg-path', '/tmp/tmps2gq2jhv']
[2024-07-22T17:43:22.771+0000] {standard_task_runner.py:91} INFO - Job 146: Subtask gen_congestion_task
[2024-07-22T17:43:22.830+0000] {task_command.py:426} INFO - Running <TaskInstance: motower_daily_prod.gen_congestion_task scheduled__2024-06-25T06:00:00+00:00 [running]> on host 5e959f2258db
[2024-07-22T17:43:22.937+0000] {taskinstance.py:2648} INFO - Exporting env vars: AIRFLOW_CTX_DAG_EMAIL='richmond.kongo@orange.com,assane.diop@orange.com,cyrille1.danho@orange.com,mohamed2.sylla@orange.com,amadou.diomande@orange.com,Jonas.kouame@orange.com,armand.kablan@orange.com,anicet.azombade@orange.com,etienne.kouadio@orange.com,bertine.kouakou@orange.com,florentine.kouakou@orange.com,ange.phaceli@orange.com,soulegame.soro@orange.com,innocent.yengo@orange.com' AIRFLOW_CTX_DAG_OWNER='***' AIRFLOW_CTX_DAG_ID='motower_daily_prod' AIRFLOW_CTX_TASK_ID='gen_congestion_task' AIRFLOW_CTX_EXECUTION_DATE='2024-06-25T06:00:00+00:00' AIRFLOW_CTX_TRY_NUMBER='1' AIRFLOW_CTX_DAG_RUN_ID='scheduled__2024-06-25T06:00:00+00:00'
[2024-07-22T17:43:22.938+0000] {taskinstance.py:430} INFO - ::endgroup::
[2024-07-22T17:43:23.269+0000] {python.py:237} INFO - Done. Returned value was: None
[2024-07-22T17:43:23.270+0000] {taskinstance.py:441} INFO - ::group::Post task execution logs
[2024-07-22T17:43:23.279+0000] {taskinstance.py:1206} INFO - Marking task as SUCCESS. dag_id=motower_daily_prod, task_id=gen_congestion_task, run_id=scheduled__2024-06-25T06:00:00+00:00, execution_date=20240625T060000, start_date=20240722T174322, end_date=20240722T174323
[2024-07-22T17:43:23.310+0000] {local_task_job_runner.py:243} INFO - Task exited with return code 0
[2024-07-22T17:43:23.318+0000] {local_task_job_runner.py:222} INFO - ::endgroup::
