[2024-07-22T16:56:55.578+0000] {local_task_job_runner.py:120} INFO - ::group::Pre task execution logs
[2024-07-22T16:56:55.919+0000] {taskinstance.py:2076} INFO - Dependencies all met for dep_context=non-requeueable deps ti=<TaskInstance: motower_daily_prod.extracta scheduled__2024-06-26T06:00:00+00:00 [queued]>
[2024-07-22T16:56:55.936+0000] {taskinstance.py:2076} INFO - Dependencies all met for dep_context=requeueable deps ti=<TaskInstance: motower_daily_prod.extracta scheduled__2024-06-26T06:00:00+00:00 [queued]>
[2024-07-22T16:56:55.937+0000] {taskinstance.py:2306} INFO - Starting attempt 1 of 1
[2024-07-22T16:56:55.957+0000] {taskinstance.py:2330} INFO - Executing <Task(PythonOperator): extracta> on 2024-06-26 06:00:00+00:00
[2024-07-22T16:56:55.974+0000] {warnings.py:112} WARNING - /home/***/.local/lib/python3.12/site-packages/***/task/task_runner/standard_task_runner.py:62: DeprecationWarning: This process (pid=870) is multi-threaded, use of fork() may lead to deadlocks in the child.
  pid = os.fork()

[2024-07-22T16:56:55.978+0000] {standard_task_runner.py:64} INFO - Started process 890 to run task
[2024-07-22T16:56:55.978+0000] {standard_task_runner.py:90} INFO - Running: ['***', 'tasks', 'run', 'motower_daily_prod', 'extracta', 'scheduled__2024-06-26T06:00:00+00:00', '--job-id', '61', '--raw', '--subdir', 'DAGS_FOLDER/gps/custom_dags/motower_daily.py', '--cfg-path', '/tmp/tmpr310gg58']
[2024-07-22T16:56:55.980+0000] {standard_task_runner.py:91} INFO - Job 61: Subtask extracta
[2024-07-22T16:56:56.041+0000] {task_command.py:426} INFO - Running <TaskInstance: motower_daily_prod.extracta scheduled__2024-06-26T06:00:00+00:00 [running]> on host 5e959f2258db
[2024-07-22T16:56:56.162+0000] {taskinstance.py:2648} INFO - Exporting env vars: AIRFLOW_CTX_DAG_EMAIL='richmond.kongo@orange.com,assane.diop@orange.com,cyrille1.danho@orange.com,mohamed2.sylla@orange.com,amadou.diomande@orange.com,Jonas.kouame@orange.com,armand.kablan@orange.com,anicet.azombade@orange.com,etienne.kouadio@orange.com,bertine.kouakou@orange.com,florentine.kouakou@orange.com,ange.phaceli@orange.com,soulegame.soro@orange.com,innocent.yengo@orange.com' AIRFLOW_CTX_DAG_OWNER='***' AIRFLOW_CTX_DAG_ID='motower_daily_prod' AIRFLOW_CTX_TASK_ID='extracta' AIRFLOW_CTX_EXECUTION_DATE='2024-06-26T06:00:00+00:00' AIRFLOW_CTX_TRY_NUMBER='1' AIRFLOW_CTX_DAG_RUN_ID='scheduled__2024-06-26T06:00:00+00:00'
[2024-07-22T16:56:56.164+0000] {taskinstance.py:430} INFO - ::endgroup::
[2024-07-22T16:56:56.188+0000] {extract.py:127} INFO - Getting data of the table dtm_motower_gsm 
[2024-07-22T16:56:56.188+0000] {extract.py:128} INFO - where date is 2024-06-25
[2024-07-22T16:56:56.189+0000] {extract.py:103} INFO - get data to date 20240625
[2024-07-22T16:56:56.195+0000] {warnings.py:112} WARNING - /opt/***/dags/gps/common/extract.py:104: UserWarning: pandas only supports SQLAlchemy connectable (engine/connection) or database string URI or sqlite3 DBAPI2 connection. Other DBAPI2 objects are not tested. Please consider using SQLAlchemy.
  df_ = pd.read_sql_query(sql_query, conn, params=params)

[2024-07-22T16:56:56.238+0000] {rwminio.py:19} INFO - start to save data
[2024-07-22T16:56:56.242+0000] {connectionpool.py:872} WARNING - Retrying (Retry(total=4, connect=None, read=None, redirect=None, status=None)) after connection broken by 'NewConnectionError('<urllib3.connection.HTTPConnection object at 0x7286304b97c0>: Failed to establish a new connection: [Errno 111] Connection refused')': /motower?location=
[2024-07-22T16:56:56.643+0000] {connectionpool.py:872} WARNING - Retrying (Retry(total=3, connect=None, read=None, redirect=None, status=None)) after connection broken by 'NewConnectionError('<urllib3.connection.HTTPConnection object at 0x7286304e00b0>: Failed to establish a new connection: [Errno 111] Connection refused')': /motower?location=
[2024-07-22T16:56:57.445+0000] {connectionpool.py:872} WARNING - Retrying (Retry(total=2, connect=None, read=None, redirect=None, status=None)) after connection broken by 'NewConnectionError('<urllib3.connection.HTTPConnection object at 0x7286304e0380>: Failed to establish a new connection: [Errno 111] Connection refused')': /motower?location=
[2024-07-22T16:56:59.046+0000] {connectionpool.py:872} WARNING - Retrying (Retry(total=1, connect=None, read=None, redirect=None, status=None)) after connection broken by 'NewConnectionError('<urllib3.connection.HTTPConnection object at 0x7286304e0830>: Failed to establish a new connection: [Errno 111] Connection refused')': /motower?location=
[2024-07-22T16:57:02.248+0000] {connectionpool.py:872} WARNING - Retrying (Retry(total=0, connect=None, read=None, redirect=None, status=None)) after connection broken by 'NewConnectionError('<urllib3.connection.HTTPConnection object at 0x7286304e0c50>: Failed to establish a new connection: [Errno 111] Connection refused')': /motower?location=
[2024-07-22T16:57:02.249+0000] {rwminio.py:36} ERROR - Error saving data to Minio with error: HTTPConnectionPool(host='minio', port=80): Max retries exceeded with url: /motower?location= (Caused by NewConnectionError('<urllib3.connection.HTTPConnection object at 0x7286304e1370>: Failed to establish a new connection: [Errno 111] Connection refused'))
[2024-07-22T16:57:02.250+0000] {python.py:237} INFO - Done. Returned value was: None
[2024-07-22T16:57:02.250+0000] {taskinstance.py:441} INFO - ::group::Post task execution logs
[2024-07-22T16:57:02.262+0000] {taskinstance.py:1206} INFO - Marking task as SUCCESS. dag_id=motower_daily_prod, task_id=extracta, run_id=scheduled__2024-06-26T06:00:00+00:00, execution_date=20240626T060000, start_date=20240722T165655, end_date=20240722T165702
[2024-07-22T16:57:02.333+0000] {local_task_job_runner.py:243} INFO - Task exited with return code 0
[2024-07-22T16:57:02.344+0000] {local_task_job_runner.py:222} INFO - ::endgroup::
[2024-07-22T17:16:09.031+0000] {local_task_job_runner.py:120} INFO - ::group::Pre task execution logs
[2024-07-22T17:16:09.335+0000] {taskinstance.py:2076} INFO - Dependencies all met for dep_context=non-requeueable deps ti=<TaskInstance: motower_daily_prod.extracta scheduled__2024-06-26T06:00:00+00:00 [queued]>
[2024-07-22T17:16:09.351+0000] {taskinstance.py:2076} INFO - Dependencies all met for dep_context=requeueable deps ti=<TaskInstance: motower_daily_prod.extracta scheduled__2024-06-26T06:00:00+00:00 [queued]>
[2024-07-22T17:16:09.351+0000] {taskinstance.py:2306} INFO - Starting attempt 1 of 1
[2024-07-22T17:16:09.367+0000] {taskinstance.py:2330} INFO - Executing <Task(PythonOperator): extracta> on 2024-06-26 06:00:00+00:00
[2024-07-22T17:16:09.381+0000] {warnings.py:112} WARNING - /home/***/.local/lib/python3.12/site-packages/***/task/task_runner/standard_task_runner.py:62: DeprecationWarning: This process (pid=1257) is multi-threaded, use of fork() may lead to deadlocks in the child.
  pid = os.fork()

[2024-07-22T17:16:09.383+0000] {standard_task_runner.py:64} INFO - Started process 1276 to run task
[2024-07-22T17:16:09.382+0000] {standard_task_runner.py:90} INFO - Running: ['***', 'tasks', 'run', 'motower_daily_prod', 'extracta', 'scheduled__2024-06-26T06:00:00+00:00', '--job-id', '110', '--raw', '--subdir', 'DAGS_FOLDER/gps/custom_dags/motower_daily.py', '--cfg-path', '/tmp/tmp0s0638jn']
[2024-07-22T17:16:09.384+0000] {standard_task_runner.py:91} INFO - Job 110: Subtask extracta
[2024-07-22T17:16:09.441+0000] {task_command.py:426} INFO - Running <TaskInstance: motower_daily_prod.extracta scheduled__2024-06-26T06:00:00+00:00 [running]> on host 5e959f2258db
[2024-07-22T17:16:09.561+0000] {taskinstance.py:2648} INFO - Exporting env vars: AIRFLOW_CTX_DAG_EMAIL='richmond.kongo@orange.com,assane.diop@orange.com,cyrille1.danho@orange.com,mohamed2.sylla@orange.com,amadou.diomande@orange.com,Jonas.kouame@orange.com,armand.kablan@orange.com,anicet.azombade@orange.com,etienne.kouadio@orange.com,bertine.kouakou@orange.com,florentine.kouakou@orange.com,ange.phaceli@orange.com,soulegame.soro@orange.com,innocent.yengo@orange.com' AIRFLOW_CTX_DAG_OWNER='***' AIRFLOW_CTX_DAG_ID='motower_daily_prod' AIRFLOW_CTX_TASK_ID='extracta' AIRFLOW_CTX_EXECUTION_DATE='2024-06-26T06:00:00+00:00' AIRFLOW_CTX_TRY_NUMBER='1' AIRFLOW_CTX_DAG_RUN_ID='scheduled__2024-06-26T06:00:00+00:00'
[2024-07-22T17:16:09.562+0000] {taskinstance.py:430} INFO - ::endgroup::
[2024-07-22T17:16:09.587+0000] {extract.py:127} INFO - Getting data of the table dtm_motower_gsm 
[2024-07-22T17:16:09.588+0000] {extract.py:128} INFO - where date is 2024-06-25
[2024-07-22T17:16:09.588+0000] {extract.py:103} INFO - get data to date 20240625
[2024-07-22T17:16:09.594+0000] {warnings.py:112} WARNING - /opt/***/dags/gps/common/extract.py:104: UserWarning: pandas only supports SQLAlchemy connectable (engine/connection) or database string URI or sqlite3 DBAPI2 connection. Other DBAPI2 objects are not tested. Please consider using SQLAlchemy.
  df_ = pd.read_sql_query(sql_query, conn, params=params)

[2024-07-22T17:16:09.632+0000] {rwminio.py:19} INFO - start to save data
[2024-07-22T17:16:09.635+0000] {connectionpool.py:872} WARNING - Retrying (Retry(total=4, connect=None, read=None, redirect=None, status=None)) after connection broken by 'NewConnectionError('<urllib3.connection.HTTPConnection object at 0x7286303df710>: Failed to establish a new connection: [Errno 111] Connection refused')': /motower?location=
[2024-07-22T17:16:10.037+0000] {connectionpool.py:872} WARNING - Retrying (Retry(total=3, connect=None, read=None, redirect=None, status=None)) after connection broken by 'NewConnectionError('<urllib3.connection.HTTPConnection object at 0x7286303111c0>: Failed to establish a new connection: [Errno 111] Connection refused')': /motower?location=
[2024-07-22T17:16:10.839+0000] {connectionpool.py:872} WARNING - Retrying (Retry(total=2, connect=None, read=None, redirect=None, status=None)) after connection broken by 'NewConnectionError('<urllib3.connection.HTTPConnection object at 0x7286303116d0>: Failed to establish a new connection: [Errno 111] Connection refused')': /motower?location=
[2024-07-22T17:16:12.441+0000] {connectionpool.py:872} WARNING - Retrying (Retry(total=1, connect=None, read=None, redirect=None, status=None)) after connection broken by 'NewConnectionError('<urllib3.connection.HTTPConnection object at 0x7286303118e0>: Failed to establish a new connection: [Errno 111] Connection refused')': /motower?location=
[2024-07-22T17:16:15.644+0000] {connectionpool.py:872} WARNING - Retrying (Retry(total=0, connect=None, read=None, redirect=None, status=None)) after connection broken by 'NewConnectionError('<urllib3.connection.HTTPConnection object at 0x728630311b80>: Failed to establish a new connection: [Errno 111] Connection refused')': /motower?location=
[2024-07-22T17:16:15.646+0000] {rwminio.py:36} ERROR - Error saving data to Minio with error: HTTPConnectionPool(host='minio', port=80): Max retries exceeded with url: /motower?location= (Caused by NewConnectionError('<urllib3.connection.HTTPConnection object at 0x728630311eb0>: Failed to establish a new connection: [Errno 111] Connection refused'))
[2024-07-22T17:16:15.647+0000] {python.py:237} INFO - Done. Returned value was: None
[2024-07-22T17:16:15.647+0000] {taskinstance.py:441} INFO - ::group::Post task execution logs
[2024-07-22T17:16:15.659+0000] {taskinstance.py:1206} INFO - Marking task as SUCCESS. dag_id=motower_daily_prod, task_id=extracta, run_id=scheduled__2024-06-26T06:00:00+00:00, execution_date=20240626T060000, start_date=20240722T171609, end_date=20240722T171615
[2024-07-22T17:16:15.697+0000] {local_task_job_runner.py:243} INFO - Task exited with return code 0
[2024-07-22T17:16:15.726+0000] {taskinstance.py:3503} INFO - 0 downstream tasks scheduled from follow-on schedule check
[2024-07-22T17:16:15.728+0000] {local_task_job_runner.py:222} INFO - ::endgroup::
[2024-07-22T17:43:22.374+0000] {local_task_job_runner.py:120} INFO - ::group::Pre task execution logs
[2024-07-22T17:43:22.706+0000] {taskinstance.py:2076} INFO - Dependencies all met for dep_context=non-requeueable deps ti=<TaskInstance: motower_daily_prod.extracta scheduled__2024-06-26T06:00:00+00:00 [queued]>
[2024-07-22T17:43:22.719+0000] {taskinstance.py:2076} INFO - Dependencies all met for dep_context=requeueable deps ti=<TaskInstance: motower_daily_prod.extracta scheduled__2024-06-26T06:00:00+00:00 [queued]>
[2024-07-22T17:43:22.719+0000] {taskinstance.py:2306} INFO - Starting attempt 1 of 1
[2024-07-22T17:43:22.732+0000] {taskinstance.py:2330} INFO - Executing <Task(PythonOperator): extracta> on 2024-06-26 06:00:00+00:00
[2024-07-22T17:43:22.747+0000] {warnings.py:112} WARNING - /home/***/.local/lib/python3.12/site-packages/***/task/task_runner/standard_task_runner.py:62: DeprecationWarning: This process (pid=1720) is multi-threaded, use of fork() may lead to deadlocks in the child.
  pid = os.fork()

[2024-07-22T17:43:22.748+0000] {standard_task_runner.py:64} INFO - Started process 1733 to run task
[2024-07-22T17:43:22.748+0000] {standard_task_runner.py:90} INFO - Running: ['***', 'tasks', 'run', 'motower_daily_prod', 'extracta', 'scheduled__2024-06-26T06:00:00+00:00', '--job-id', '145', '--raw', '--subdir', 'DAGS_FOLDER/gps/custom_dags/motower_daily.py', '--cfg-path', '/tmp/tmpnl8v_d_d']
[2024-07-22T17:43:22.750+0000] {standard_task_runner.py:91} INFO - Job 145: Subtask extracta
[2024-07-22T17:43:22.813+0000] {task_command.py:426} INFO - Running <TaskInstance: motower_daily_prod.extracta scheduled__2024-06-26T06:00:00+00:00 [running]> on host 5e959f2258db
[2024-07-22T17:43:22.932+0000] {taskinstance.py:2648} INFO - Exporting env vars: AIRFLOW_CTX_DAG_EMAIL='richmond.kongo@orange.com,assane.diop@orange.com,cyrille1.danho@orange.com,mohamed2.sylla@orange.com,amadou.diomande@orange.com,Jonas.kouame@orange.com,armand.kablan@orange.com,anicet.azombade@orange.com,etienne.kouadio@orange.com,bertine.kouakou@orange.com,florentine.kouakou@orange.com,ange.phaceli@orange.com,soulegame.soro@orange.com,innocent.yengo@orange.com' AIRFLOW_CTX_DAG_OWNER='***' AIRFLOW_CTX_DAG_ID='motower_daily_prod' AIRFLOW_CTX_TASK_ID='extracta' AIRFLOW_CTX_EXECUTION_DATE='2024-06-26T06:00:00+00:00' AIRFLOW_CTX_TRY_NUMBER='1' AIRFLOW_CTX_DAG_RUN_ID='scheduled__2024-06-26T06:00:00+00:00'
[2024-07-22T17:43:22.934+0000] {taskinstance.py:430} INFO - ::endgroup::
[2024-07-22T17:43:22.958+0000] {extract.py:127} INFO - Getting data of the table dtm_motower_gsm 
[2024-07-22T17:43:22.959+0000] {extract.py:128} INFO - where date is 2024-06-25
[2024-07-22T17:43:22.960+0000] {extract.py:103} INFO - get data to date 20240625
[2024-07-22T17:43:22.969+0000] {warnings.py:112} WARNING - /opt/***/dags/gps/common/extract.py:104: UserWarning: pandas only supports SQLAlchemy connectable (engine/connection) or database string URI or sqlite3 DBAPI2 connection. Other DBAPI2 objects are not tested. Please consider using SQLAlchemy.
  df_ = pd.read_sql_query(sql_query, conn, params=params)

[2024-07-22T17:43:23.004+0000] {rwminio.py:19} INFO - start to save data
[2024-07-22T17:43:23.047+0000] {rwminio.py:34} INFO - data in minio ok
[2024-07-22T17:43:23.048+0000] {python.py:237} INFO - Done. Returned value was: None
[2024-07-22T17:43:23.049+0000] {taskinstance.py:441} INFO - ::group::Post task execution logs
[2024-07-22T17:43:23.063+0000] {taskinstance.py:1206} INFO - Marking task as SUCCESS. dag_id=motower_daily_prod, task_id=extracta, run_id=scheduled__2024-06-26T06:00:00+00:00, execution_date=20240626T060000, start_date=20240722T174322, end_date=20240722T174323
[2024-07-22T17:43:23.131+0000] {local_task_job_runner.py:243} INFO - Task exited with return code 0
[2024-07-22T17:43:23.141+0000] {local_task_job_runner.py:222} INFO - ::endgroup::
