[2024-07-25T08:35:07.513+0000] {local_task_job_runner.py:120} INFO - ::group::Pre task execution logs
[2024-07-25T08:35:07.536+0000] {taskinstance.py:2076} INFO - Dependencies all met for dep_context=non-requeueable deps ti=<TaskInstance: enrich_prod.cleaning.cleaning_caparc manual__2024-07-25T08:35:05.225868+00:00 [queued]>
[2024-07-25T08:35:07.543+0000] {taskinstance.py:2076} INFO - Dependencies all met for dep_context=requeueable deps ti=<TaskInstance: enrich_prod.cleaning.cleaning_caparc manual__2024-07-25T08:35:05.225868+00:00 [queued]>
[2024-07-25T08:35:07.543+0000] {taskinstance.py:2306} INFO - Starting attempt 1 of 1
[2024-07-25T08:35:07.560+0000] {taskinstance.py:2330} INFO - Executing <Task(PythonOperator): cleaning.cleaning_caparc> on 2024-07-25 08:35:05.225868+00:00
[2024-07-25T08:35:07.573+0000] {warnings.py:112} WARNING - /home/***/.local/lib/python3.12/site-packages/***/task/task_runner/standard_task_runner.py:62: DeprecationWarning: This process (pid=2839) is multi-threaded, use of fork() may lead to deadlocks in the child.
  pid = os.fork()

[2024-07-25T08:35:07.574+0000] {standard_task_runner.py:64} INFO - Started process 2851 to run task
[2024-07-25T08:35:07.574+0000] {standard_task_runner.py:90} INFO - Running: ['***', 'tasks', 'run', 'enrich_prod', 'cleaning.cleaning_caparc', 'manual__2024-07-25T08:35:05.225868+00:00', '--job-id', '973', '--raw', '--subdir', 'DAGS_FOLDER/gps/custom_dags/enrich.py', '--cfg-path', '/tmp/tmpald_dniv']
[2024-07-25T08:35:07.576+0000] {standard_task_runner.py:91} INFO - Job 973: Subtask cleaning.cleaning_caparc
[2024-07-25T08:35:07.619+0000] {task_command.py:426} INFO - Running <TaskInstance: enrich_prod.cleaning.cleaning_caparc manual__2024-07-25T08:35:05.225868+00:00 [running]> on host b3845fb494d4
[2024-07-25T08:35:07.702+0000] {taskinstance.py:2648} INFO - Exporting env vars: AIRFLOW_CTX_DAG_EMAIL='richmond.kongo@orange.com,assane.diop@orange.com,cyrille1.danho@orange.com,mohamed2.sylla@orange.com,amadou.diomande@orange.com,Jonas.kouame@orange.com,armand.kablan@orange.com,anicet.azombade@orange.com,etienne.kouadio@orange.com,bertine.kouakou@orange.com,florentine.kouakou@orange.com,ange.phaceli@orange.com,soulegame.soro@orange.com,innocent.yengo@orange.com' AIRFLOW_CTX_DAG_OWNER='***' AIRFLOW_CTX_DAG_ID='enrich_prod' AIRFLOW_CTX_TASK_ID='cleaning.cleaning_caparc' AIRFLOW_CTX_EXECUTION_DATE='2024-07-25T08:35:05.225868+00:00' AIRFLOW_CTX_TRY_NUMBER='1' AIRFLOW_CTX_DAG_RUN_ID='manual__2024-07-25T08:35:05.225868+00:00'
[2024-07-25T08:35:07.704+0000] {taskinstance.py:430} INFO - ::endgroup::
[2024-07-25T08:35:08.098+0000] {cleaning.py:287} INFO - DATA VALIDATION
[2024-07-25T08:35:08.113+0000] {cleaning.py:295} INFO - DAILY KPI -       day_id       ca_voix       ca_data      parc  parc_data   parc_2g  parc_3g  parc_4g  parc_5g  parc_other      ca_total
0   20240601  5.327182e+08  8.044059e+08  16715871    9176426  12042566   875452  5841327   297932     1379325  1.395652e+09
1   20240602  4.822626e+08  7.120804e+08  16714097    9177438  12057840   876499  5949531   319188     1385238  1.241494e+09
2   20240603  5.767417e+08  7.912384e+08  16699131    9186215  12010574   873099  5756054   283564     1374011  1.416856e+09
3   20240604  7.685736e+08  1.330852e+09  16665974    9196769  12058171   874454  5846039   292170     1381447  2.153703e+09
4   20240605  5.338739e+08  6.537754e+08  16660757    9203792  12064542   874622  5863012   293647     1383269  1.238126e+09
5   20240606  5.204942e+08  6.904167e+08  16650735    9208133  12082131   874665  5885569   295719     1385939  1.253289e+09
6   20240607  6.764668e+08  8.043372e+08  16696220    9200361  12037120   873949  5873157   296128     1384633  1.526502e+09
7   20240608  5.269060e+08  7.500433e+08  16690914    9266472  12017040   872927  5865224   302963     1382339  1.326831e+09
8   20240609  4.886769e+08  7.143445e+08  16683492    9268730  12140247   877375  6059788   330959     1401896  1.245116e+09
9   20240610  5.499279e+08  7.507506e+08  16683048    9277896         0        0        0        0           0  1.347035e+09
10  20240611  7.147300e+08  1.274972e+09  16682024    9286426         0        0        0        0           0  2.116512e+09
11  20240612  5.370959e+08  6.475457e+08  16685206    9316317  12132594   875120  5930993   299683     1398335  1.272913e+09
12  20240613  5.068124e+08  6.639765e+08  16635386    9319941  12181396   876383  5996878   306444     1406477  1.210888e+09
13  20240614  6.888568e+08  8.104376e+08  16695810    9331698  12101150   874668  5946004   303922     1400844  1.543841e+09
14  20240615  5.835887e+08  7.961630e+08  16702991    9333757  12084521   873372  5910578   301919     1398522  1.423788e+09
15  20240616  5.713497e+08  8.007501e+08  16699581    9318089  12080216   874715  6002819   328526     1405469  1.420801e+09
16  20240617  5.883282e+08  7.914348e+08  16705048    9384367  12077678   873823  5982250   325860     1403999  1.423402e+09
17  20240618  7.176500e+08  1.221908e+09  16714464    9324897  12054106   871416  5854949   302163     1395861  1.987056e+09
18  20240619  5.203883e+08  6.657753e+08  16722769    9342134  12110945   873222  5954466   307840     1404891  1.237131e+09
19  20240620  5.053236e+08  7.248778e+08  16734454    9416167  12136259   873738  5984699   310091     1410049  1.269207e+09
20  20240621  6.412472e+08  8.142664e+08  16754054    9429272  12111954   872939  5985774   311254     1409427  1.496332e+09
21  20240622  4.923264e+08  7.658733e+08  16703455    9435343  12136156   873032  5997956   315277     1412008  1.365722e+09
22  20240623  4.612004e+08  7.240631e+08  16721647    9435626  11992936   851891  6063282   339113     1399668  1.247311e+09
23  20240624  5.165637e+08  7.650778e+08  16733340    9443567  11943670   842089  5930353   309964     1387765  1.338748e+09
24  20240625  6.664774e+08  1.243799e+09  16753745    9453602  11948494   841665  5929920   308836     1388920  1.970652e+09
25  20240626  5.175478e+08  6.679043e+08  16776596    9460144  11955042   841559  5948098   311950     1391040  1.223150e+09
26  20240627  4.995955e+08  7.077792e+08  16800991    9466269  12068544   856998  5974798   310410     1405516  1.246005e+09
27  20240628  6.507343e+08  8.325999e+08  16824214    9475436  12082356   864321  5969856   309967     1410795  1.524851e+09
28  20240629  5.171829e+08  7.928949e+08  16838645    9477332  12112307   864624  6002840   317214     1415064  1.349544e+09
29  20240630  4.691776e+08  7.443228e+08  16844166    9476468  12119527   865313  6112501   341521     1421884  1.254197e+09
[2024-07-25T08:35:08.113+0000] {cleaning.py:296} INFO - Le CA mensuel est de 43066654487.41
[2024-07-25T08:35:08.113+0000] {logging_mixin.py:188} INFO - http://10.242.36.139.sslip.io/api/alerting
[2024-07-25T08:35:23.142+0000] {taskinstance.py:441} INFO - ::group::Post task execution logs
[2024-07-25T08:35:23.143+0000] {taskinstance.py:2905} ERROR - Task failed with exception
Traceback (most recent call last):
  File "/home/airflow/.local/lib/python3.12/site-packages/urllib3/connection.py", line 203, in _new_conn
    sock = connection.create_connection(
           ^^^^^^^^^^^^^^^^^^^^^^^^^^^^^
  File "/home/airflow/.local/lib/python3.12/site-packages/urllib3/util/connection.py", line 85, in create_connection
    raise err
  File "/home/airflow/.local/lib/python3.12/site-packages/urllib3/util/connection.py", line 73, in create_connection
    sock.connect(sa)
TimeoutError: timed out

The above exception was the direct cause of the following exception:

Traceback (most recent call last):
  File "/home/airflow/.local/lib/python3.12/site-packages/urllib3/connectionpool.py", line 791, in urlopen
    response = self._make_request(
               ^^^^^^^^^^^^^^^^^^^
  File "/home/airflow/.local/lib/python3.12/site-packages/urllib3/connectionpool.py", line 497, in _make_request
    conn.request(
  File "/home/airflow/.local/lib/python3.12/site-packages/urllib3/connection.py", line 395, in request
    self.endheaders()
  File "/usr/local/lib/python3.12/http/client.py", line 1331, in endheaders
    self._send_output(message_body, encode_chunked=encode_chunked)
  File "/usr/local/lib/python3.12/http/client.py", line 1091, in _send_output
    self.send(msg)
  File "/usr/local/lib/python3.12/http/client.py", line 1035, in send
    self.connect()
  File "/home/airflow/.local/lib/python3.12/site-packages/urllib3/connection.py", line 243, in connect
    self.sock = self._new_conn()
                ^^^^^^^^^^^^^^^^
  File "/home/airflow/.local/lib/python3.12/site-packages/urllib3/connection.py", line 212, in _new_conn
    raise ConnectTimeoutError(
urllib3.exceptions.ConnectTimeoutError: (<urllib3.connection.HTTPConnection object at 0x73206e8332c0>, 'Connection to 10.242.36.139.sslip.io timed out. (connect timeout=15)')

The above exception was the direct cause of the following exception:

Traceback (most recent call last):
  File "/home/airflow/.local/lib/python3.12/site-packages/requests/adapters.py", line 667, in send
    resp = conn.urlopen(
           ^^^^^^^^^^^^^
  File "/home/airflow/.local/lib/python3.12/site-packages/urllib3/connectionpool.py", line 845, in urlopen
    retries = retries.increment(
              ^^^^^^^^^^^^^^^^^^
  File "/home/airflow/.local/lib/python3.12/site-packages/urllib3/util/retry.py", line 515, in increment
    raise MaxRetryError(_pool, url, reason) from reason  # type: ignore[arg-type]
    ^^^^^^^^^^^^^^^^^^^^^^^^^^^^^^^^^^^^^^^^^^^^^^^^^^^
urllib3.exceptions.MaxRetryError: HTTPConnectionPool(host='10.242.36.139.sslip.io', port=80): Max retries exceeded with url: /api/alerting (Caused by ConnectTimeoutError(<urllib3.connection.HTTPConnection object at 0x73206e8332c0>, 'Connection to 10.242.36.139.sslip.io timed out. (connect timeout=15)'))

During handling of the above exception, another exception occurred:

Traceback (most recent call last):
  File "/home/airflow/.local/lib/python3.12/site-packages/airflow/models/taskinstance.py", line 465, in _execute_task
    result = _execute_callable(context=context, **execute_callable_kwargs)
             ^^^^^^^^^^^^^^^^^^^^^^^^^^^^^^^^^^^^^^^^^^^^^^^^^^^^^^^^^^^^^
  File "/home/airflow/.local/lib/python3.12/site-packages/airflow/models/taskinstance.py", line 432, in _execute_callable
    return execute_callable(context=context, **execute_callable_kwargs)
           ^^^^^^^^^^^^^^^^^^^^^^^^^^^^^^^^^^^^^^^^^^^^^^^^^^^^^^^^^^^^
  File "/home/airflow/.local/lib/python3.12/site-packages/airflow/models/baseoperator.py", line 401, in wrapper
    return func(self, *args, **kwargs)
           ^^^^^^^^^^^^^^^^^^^^^^^^^^^
  File "/home/airflow/.local/lib/python3.12/site-packages/airflow/operators/python.py", line 235, in execute
    return_value = self.execute_callable()
                   ^^^^^^^^^^^^^^^^^^^^^^^
  File "/home/airflow/.local/lib/python3.12/site-packages/airflow/operators/python.py", line 252, in execute_callable
    return self.python_callable(*self.op_args, **self.op_kwargs)
           ^^^^^^^^^^^^^^^^^^^^^^^^^^^^^^^^^^^^^^^^^^^^^^^^^^^^^
  File "/opt/airflow/dags/gps/common/cleaning.py", line 299, in cleaning_ca_parc
    validate_column(df=df_for_validation, file_type="CAPARC", col=col, host=smtp_host, port=smtp_port, user=smtp_user, receivers=get_receivers("CA_SITES"))
                                                                                                                                 ^^^^^^^^^^^^^^^^^^^^^^^^^
  File "/opt/airflow/dags/gps/common/alerting.py", line 17, in get_receivers
    objets = requests.get(CONFIG["api_mails"], timeout=15).json()
             ^^^^^^^^^^^^^^^^^^^^^^^^^^^^^^^^^^^^^^^^^^^^^
  File "/home/airflow/.local/lib/python3.12/site-packages/requests/api.py", line 73, in get
    return request("get", url, params=params, **kwargs)
           ^^^^^^^^^^^^^^^^^^^^^^^^^^^^^^^^^^^^^^^^^^^^
  File "/home/airflow/.local/lib/python3.12/site-packages/requests/api.py", line 59, in request
    return session.request(method=method, url=url, **kwargs)
           ^^^^^^^^^^^^^^^^^^^^^^^^^^^^^^^^^^^^^^^^^^^^^^^^^
  File "/home/airflow/.local/lib/python3.12/site-packages/requests/sessions.py", line 589, in request
    resp = self.send(prep, **send_kwargs)
           ^^^^^^^^^^^^^^^^^^^^^^^^^^^^^^
  File "/home/airflow/.local/lib/python3.12/site-packages/requests/sessions.py", line 703, in send
    r = adapter.send(request, **kwargs)
        ^^^^^^^^^^^^^^^^^^^^^^^^^^^^^^^
  File "/home/airflow/.local/lib/python3.12/site-packages/requests/adapters.py", line 688, in send
    raise ConnectTimeout(e, request=request)
requests.exceptions.ConnectTimeout: HTTPConnectionPool(host='10.242.36.139.sslip.io', port=80): Max retries exceeded with url: /api/alerting (Caused by ConnectTimeoutError(<urllib3.connection.HTTPConnection object at 0x73206e8332c0>, 'Connection to 10.242.36.139.sslip.io timed out. (connect timeout=15)'))
[2024-07-25T08:35:23.157+0000] {taskinstance.py:1206} INFO - Marking task as FAILED. dag_id=enrich_prod, task_id=cleaning.cleaning_caparc, run_id=manual__2024-07-25T08:35:05.225868+00:00, execution_date=20240725T083505, start_date=20240725T083507, end_date=20240725T083523
[2024-07-25T08:35:23.168+0000] {warnings.py:112} WARNING - /home/***/.local/lib/python3.12/site-packages/***/utils/email.py:154: RemovedInAirflow3Warning: Fetching SMTP credentials from configuration variables will be deprecated in a future release. Please set credentials using a connection instead.
  send_mime_email(e_from=mail_from, e_to=recipients, mime_msg=msg, conn_id=conn_id, dryrun=dryrun)

[2024-07-25T08:35:23.168+0000] {configuration.py:1053} WARNING - section/key [smtp/smtp_user] not found in config
[2024-07-25T08:35:23.168+0000] {email.py:271} INFO - Email alerting: attempt 1
[2024-07-25T08:35:23.175+0000] {configuration.py:1053} WARNING - section/key [smtp/smtp_user] not found in config
[2024-07-25T08:35:23.175+0000] {email.py:271} INFO - Email alerting: attempt 1
[2024-07-25T08:35:23.175+0000] {taskinstance.py:879} ERROR - Failed to send email to: ['richmond.kongo@orange.com', 'assane.diop@orange.com', 'cyrille1.danho@orange.com', 'mohamed2.sylla@orange.com', 'amadou.diomande@orange.com', 'Jonas.kouame@orange.com', 'armand.kablan@orange.com', 'anicet.azombade@orange.com', 'etienne.kouadio@orange.com', 'bertine.kouakou@orange.com', 'florentine.kouakou@orange.com', 'ange.phaceli@orange.com', 'soulegame.soro@orange.com', 'innocent.yengo@orange.com']
Traceback (most recent call last):
  File "/home/airflow/.local/lib/python3.12/site-packages/urllib3/connection.py", line 203, in _new_conn
    sock = connection.create_connection(
           ^^^^^^^^^^^^^^^^^^^^^^^^^^^^^
  File "/home/airflow/.local/lib/python3.12/site-packages/urllib3/util/connection.py", line 85, in create_connection
    raise err
  File "/home/airflow/.local/lib/python3.12/site-packages/urllib3/util/connection.py", line 73, in create_connection
    sock.connect(sa)
TimeoutError: timed out

The above exception was the direct cause of the following exception:

Traceback (most recent call last):
  File "/home/airflow/.local/lib/python3.12/site-packages/urllib3/connectionpool.py", line 791, in urlopen
    response = self._make_request(
               ^^^^^^^^^^^^^^^^^^^
  File "/home/airflow/.local/lib/python3.12/site-packages/urllib3/connectionpool.py", line 497, in _make_request
    conn.request(
  File "/home/airflow/.local/lib/python3.12/site-packages/urllib3/connection.py", line 395, in request
    self.endheaders()
  File "/usr/local/lib/python3.12/http/client.py", line 1331, in endheaders
    self._send_output(message_body, encode_chunked=encode_chunked)
  File "/usr/local/lib/python3.12/http/client.py", line 1091, in _send_output
    self.send(msg)
  File "/usr/local/lib/python3.12/http/client.py", line 1035, in send
    self.connect()
  File "/home/airflow/.local/lib/python3.12/site-packages/urllib3/connection.py", line 243, in connect
    self.sock = self._new_conn()
                ^^^^^^^^^^^^^^^^
  File "/home/airflow/.local/lib/python3.12/site-packages/urllib3/connection.py", line 212, in _new_conn
    raise ConnectTimeoutError(
urllib3.exceptions.ConnectTimeoutError: (<urllib3.connection.HTTPConnection object at 0x73206e8332c0>, 'Connection to 10.242.36.139.sslip.io timed out. (connect timeout=15)')

The above exception was the direct cause of the following exception:

Traceback (most recent call last):
  File "/home/airflow/.local/lib/python3.12/site-packages/requests/adapters.py", line 667, in send
    resp = conn.urlopen(
           ^^^^^^^^^^^^^
  File "/home/airflow/.local/lib/python3.12/site-packages/urllib3/connectionpool.py", line 845, in urlopen
    retries = retries.increment(
              ^^^^^^^^^^^^^^^^^^
  File "/home/airflow/.local/lib/python3.12/site-packages/urllib3/util/retry.py", line 515, in increment
    raise MaxRetryError(_pool, url, reason) from reason  # type: ignore[arg-type]
    ^^^^^^^^^^^^^^^^^^^^^^^^^^^^^^^^^^^^^^^^^^^^^^^^^^^
urllib3.exceptions.MaxRetryError: HTTPConnectionPool(host='10.242.36.139.sslip.io', port=80): Max retries exceeded with url: /api/alerting (Caused by ConnectTimeoutError(<urllib3.connection.HTTPConnection object at 0x73206e8332c0>, 'Connection to 10.242.36.139.sslip.io timed out. (connect timeout=15)'))

During handling of the above exception, another exception occurred:

Traceback (most recent call last):
  File "/home/airflow/.local/lib/python3.12/site-packages/airflow/models/taskinstance.py", line 2479, in _run_raw_task
    self._execute_task_with_callbacks(context, test_mode, session=session)
  File "/home/airflow/.local/lib/python3.12/site-packages/airflow/models/taskinstance.py", line 2676, in _execute_task_with_callbacks
    result = self._execute_task(context, task_orig)
             ^^^^^^^^^^^^^^^^^^^^^^^^^^^^^^^^^^^^^^
  File "/home/airflow/.local/lib/python3.12/site-packages/airflow/models/taskinstance.py", line 2701, in _execute_task
    return _execute_task(self, context, task_orig)
           ^^^^^^^^^^^^^^^^^^^^^^^^^^^^^^^^^^^^^^^
  File "/home/airflow/.local/lib/python3.12/site-packages/airflow/models/taskinstance.py", line 465, in _execute_task
    result = _execute_callable(context=context, **execute_callable_kwargs)
             ^^^^^^^^^^^^^^^^^^^^^^^^^^^^^^^^^^^^^^^^^^^^^^^^^^^^^^^^^^^^^
  File "/home/airflow/.local/lib/python3.12/site-packages/airflow/models/taskinstance.py", line 432, in _execute_callable
    return execute_callable(context=context, **execute_callable_kwargs)
           ^^^^^^^^^^^^^^^^^^^^^^^^^^^^^^^^^^^^^^^^^^^^^^^^^^^^^^^^^^^^
  File "/home/airflow/.local/lib/python3.12/site-packages/airflow/models/baseoperator.py", line 401, in wrapper
    return func(self, *args, **kwargs)
           ^^^^^^^^^^^^^^^^^^^^^^^^^^^
  File "/home/airflow/.local/lib/python3.12/site-packages/airflow/operators/python.py", line 235, in execute
    return_value = self.execute_callable()
                   ^^^^^^^^^^^^^^^^^^^^^^^
  File "/home/airflow/.local/lib/python3.12/site-packages/airflow/operators/python.py", line 252, in execute_callable
    return self.python_callable(*self.op_args, **self.op_kwargs)
           ^^^^^^^^^^^^^^^^^^^^^^^^^^^^^^^^^^^^^^^^^^^^^^^^^^^^^
  File "/opt/airflow/dags/gps/common/cleaning.py", line 299, in cleaning_ca_parc
    validate_column(df=df_for_validation, file_type="CAPARC", col=col, host=smtp_host, port=smtp_port, user=smtp_user, receivers=get_receivers("CA_SITES"))
                                                                                                                                 ^^^^^^^^^^^^^^^^^^^^^^^^^
  File "/opt/airflow/dags/gps/common/alerting.py", line 17, in get_receivers
    objets = requests.get(CONFIG["api_mails"], timeout=15).json()
             ^^^^^^^^^^^^^^^^^^^^^^^^^^^^^^^^^^^^^^^^^^^^^
  File "/home/airflow/.local/lib/python3.12/site-packages/requests/api.py", line 73, in get
    return request("get", url, params=params, **kwargs)
           ^^^^^^^^^^^^^^^^^^^^^^^^^^^^^^^^^^^^^^^^^^^^
  File "/home/airflow/.local/lib/python3.12/site-packages/requests/api.py", line 59, in request
    return session.request(method=method, url=url, **kwargs)
           ^^^^^^^^^^^^^^^^^^^^^^^^^^^^^^^^^^^^^^^^^^^^^^^^^
  File "/home/airflow/.local/lib/python3.12/site-packages/requests/sessions.py", line 589, in request
    resp = self.send(prep, **send_kwargs)
           ^^^^^^^^^^^^^^^^^^^^^^^^^^^^^^
  File "/home/airflow/.local/lib/python3.12/site-packages/requests/sessions.py", line 703, in send
    r = adapter.send(request, **kwargs)
        ^^^^^^^^^^^^^^^^^^^^^^^^^^^^^^^
  File "/home/airflow/.local/lib/python3.12/site-packages/requests/adapters.py", line 688, in send
    raise ConnectTimeout(e, request=request)
requests.exceptions.ConnectTimeout: HTTPConnectionPool(host='10.242.36.139.sslip.io', port=80): Max retries exceeded with url: /api/alerting (Caused by ConnectTimeoutError(<urllib3.connection.HTTPConnection object at 0x73206e8332c0>, 'Connection to 10.242.36.139.sslip.io timed out. (connect timeout=15)'))

During handling of the above exception, another exception occurred:

Traceback (most recent call last):
  File "/home/airflow/.local/lib/python3.12/site-packages/airflow/models/taskinstance.py", line 1063, in _email_alert
    send_email(task.email, subject, html_content)
  File "/home/airflow/.local/lib/python3.12/site-packages/airflow/utils/email.py", line 80, in send_email
    return backend(
           ^^^^^^^^
  File "/home/airflow/.local/lib/python3.12/site-packages/airflow/utils/email.py", line 154, in send_email_smtp
    send_mime_email(e_from=mail_from, e_to=recipients, mime_msg=msg, conn_id=conn_id, dryrun=dryrun)
  File "/home/airflow/.local/lib/python3.12/site-packages/airflow/utils/email.py", line 273, in send_mime_email
    smtp_conn = _get_smtp_connection(smtp_host, smtp_port, smtp_timeout, smtp_ssl)
                ^^^^^^^^^^^^^^^^^^^^^^^^^^^^^^^^^^^^^^^^^^^^^^^^^^^^^^^^^^^^^^^^^^
  File "/home/airflow/.local/lib/python3.12/site-packages/airflow/utils/email.py", line 317, in _get_smtp_connection
    return smtplib.SMTP(host=host, port=port, timeout=timeout)
           ^^^^^^^^^^^^^^^^^^^^^^^^^^^^^^^^^^^^^^^^^^^^^^^^^^^
  File "/usr/local/lib/python3.12/smtplib.py", line 255, in __init__
    (code, msg) = self.connect(host, port)
                  ^^^^^^^^^^^^^^^^^^^^^^^^
  File "/usr/local/lib/python3.12/smtplib.py", line 341, in connect
    self.sock = self._get_socket(host, port, self.timeout)
                ^^^^^^^^^^^^^^^^^^^^^^^^^^^^^^^^^^^^^^^^^^
  File "/usr/local/lib/python3.12/smtplib.py", line 312, in _get_socket
    return socket.create_connection((host, port), timeout,
           ^^^^^^^^^^^^^^^^^^^^^^^^^^^^^^^^^^^^^^^^^^^^^^^
  File "/usr/local/lib/python3.12/socket.py", line 853, in create_connection
    raise exceptions[0]
  File "/usr/local/lib/python3.12/socket.py", line 838, in create_connection
    sock.connect(sa)
ConnectionRefusedError: [Errno 111] Connection refused

During handling of the above exception, another exception occurred:

Traceback (most recent call last):
  File "/home/airflow/.local/lib/python3.12/site-packages/airflow/models/taskinstance.py", line 877, in _handle_failure
    task_instance.email_alert(error, failure_context["task"])
  File "/home/airflow/.local/lib/python3.12/site-packages/airflow/models/taskinstance.py", line 3163, in email_alert
    _email_alert(task_instance=self, exception=exception, task=task)
  File "/home/airflow/.local/lib/python3.12/site-packages/airflow/models/taskinstance.py", line 1065, in _email_alert
    send_email(task.email, subject, html_content_err)
  File "/home/airflow/.local/lib/python3.12/site-packages/airflow/utils/email.py", line 80, in send_email
    return backend(
           ^^^^^^^^
  File "/home/airflow/.local/lib/python3.12/site-packages/airflow/utils/email.py", line 154, in send_email_smtp
    send_mime_email(e_from=mail_from, e_to=recipients, mime_msg=msg, conn_id=conn_id, dryrun=dryrun)
  File "/home/airflow/.local/lib/python3.12/site-packages/airflow/utils/email.py", line 273, in send_mime_email
    smtp_conn = _get_smtp_connection(smtp_host, smtp_port, smtp_timeout, smtp_ssl)
                ^^^^^^^^^^^^^^^^^^^^^^^^^^^^^^^^^^^^^^^^^^^^^^^^^^^^^^^^^^^^^^^^^^
  File "/home/airflow/.local/lib/python3.12/site-packages/airflow/utils/email.py", line 317, in _get_smtp_connection
    return smtplib.SMTP(host=host, port=port, timeout=timeout)
           ^^^^^^^^^^^^^^^^^^^^^^^^^^^^^^^^^^^^^^^^^^^^^^^^^^^
  File "/usr/local/lib/python3.12/smtplib.py", line 255, in __init__
    (code, msg) = self.connect(host, port)
                  ^^^^^^^^^^^^^^^^^^^^^^^^
  File "/usr/local/lib/python3.12/smtplib.py", line 341, in connect
    self.sock = self._get_socket(host, port, self.timeout)
                ^^^^^^^^^^^^^^^^^^^^^^^^^^^^^^^^^^^^^^^^^^
  File "/usr/local/lib/python3.12/smtplib.py", line 312, in _get_socket
    return socket.create_connection((host, port), timeout,
           ^^^^^^^^^^^^^^^^^^^^^^^^^^^^^^^^^^^^^^^^^^^^^^^
  File "/usr/local/lib/python3.12/socket.py", line 853, in create_connection
    raise exceptions[0]
  File "/usr/local/lib/python3.12/socket.py", line 838, in create_connection
    sock.connect(sa)
ConnectionRefusedError: [Errno 111] Connection refused
[2024-07-25T08:35:23.192+0000] {standard_task_runner.py:110} ERROR - Failed to execute job 973 for task cleaning.cleaning_caparc (HTTPConnectionPool(host='10.242.36.139.sslip.io', port=80): Max retries exceeded with url: /api/alerting (Caused by ConnectTimeoutError(<urllib3.connection.HTTPConnection object at 0x73206e8332c0>, 'Connection to 10.242.36.139.sslip.io timed out. (connect timeout=15)')); 2851)
[2024-07-25T08:35:23.207+0000] {local_task_job_runner.py:243} INFO - Task exited with return code 1
[2024-07-25T08:35:23.216+0000] {local_task_job_runner.py:222} INFO - ::endgroup::
