[2024-07-25T13:13:04.839+0000] {local_task_job_runner.py:120} INFO - ::group::Pre task execution logs
[2024-07-25T13:13:04.865+0000] {taskinstance.py:2076} INFO - Dependencies all met for dep_context=non-requeueable deps ti=<TaskInstance: motower_daily_prod.motower_dcaparc scheduled__2024-06-04T06:00:00+00:00 [queued]>
[2024-07-25T13:13:04.872+0000] {taskinstance.py:2076} INFO - Dependencies all met for dep_context=requeueable deps ti=<TaskInstance: motower_daily_prod.motower_dcaparc scheduled__2024-06-04T06:00:00+00:00 [queued]>
[2024-07-25T13:13:04.873+0000] {taskinstance.py:2306} INFO - Starting attempt 4 of 4
[2024-07-25T13:13:04.882+0000] {taskinstance.py:2330} INFO - Executing <Task(PythonOperator): motower_dcaparc> on 2024-06-04 06:00:00+00:00
[2024-07-25T13:13:04.891+0000] {warnings.py:112} WARNING - /home/***/.local/lib/python3.12/site-packages/***/task/task_runner/standard_task_runner.py:62: DeprecationWarning: This process (pid=10965) is multi-threaded, use of fork() may lead to deadlocks in the child.
  pid = os.fork()

[2024-07-25T13:13:04.892+0000] {standard_task_runner.py:64} INFO - Started process 10967 to run task
[2024-07-25T13:13:04.893+0000] {standard_task_runner.py:90} INFO - Running: ['***', 'tasks', 'run', 'motower_daily_prod', 'motower_dcaparc', 'scheduled__2024-06-04T06:00:00+00:00', '--job-id', '2482', '--raw', '--subdir', 'DAGS_FOLDER/gps/custom_dags/motower_daily.py', '--cfg-path', '/tmp/tmp6v9fdlf8']
[2024-07-25T13:13:04.895+0000] {standard_task_runner.py:91} INFO - Job 2482: Subtask motower_dcaparc
[2024-07-25T13:13:04.934+0000] {task_command.py:426} INFO - Running <TaskInstance: motower_daily_prod.motower_dcaparc scheduled__2024-06-04T06:00:00+00:00 [running]> on host b3845fb494d4
[2024-07-25T13:13:05.022+0000] {taskinstance.py:2648} INFO - Exporting env vars: AIRFLOW_CTX_DAG_EMAIL='richmond.kongo@orange.com,assane.diop@orange.com,cyrille1.danho@orange.com,mohamed2.sylla@orange.com,amadou.diomande@orange.com,Jonas.kouame@orange.com,armand.kablan@orange.com,anicet.azombade@orange.com,etienne.kouadio@orange.com,bertine.kouakou@orange.com,florentine.kouakou@orange.com,ange.phaceli@orange.com,soulegame.soro@orange.com,innocent.yengo@orange.com' AIRFLOW_CTX_DAG_OWNER='***' AIRFLOW_CTX_DAG_ID='motower_daily_prod' AIRFLOW_CTX_TASK_ID='motower_dcaparc' AIRFLOW_CTX_EXECUTION_DATE='2024-06-04T06:00:00+00:00' AIRFLOW_CTX_TRY_NUMBER='4' AIRFLOW_CTX_DAG_RUN_ID='scheduled__2024-06-04T06:00:00+00:00'
[2024-07-25T13:13:05.023+0000] {taskinstance.py:430} INFO - ::endgroup::
[2024-07-25T13:13:05.035+0000] {motower_daily.py:106} INFO - get last modified bdd sites cleaned
[2024-07-25T13:13:05.043+0000] {motower_daily.py:117} INFO - READING BASE_SITES-cleaned/2024/06/02.csv
[2024-07-25T13:13:05.085+0000] {data_validation.py:28} INFO - START VALIDATION 
[2024-07-25T13:13:05.086+0000] {data_validation.py:40} INFO - VALID ACTIFS SITES 3107
[2024-07-25T13:13:05.086+0000] {motower_daily.py:127} INFO - GET CA PARC FILE OF THE DAY 2024-06-03
[2024-07-25T13:13:05.086+0000] {motower_daily.py:131} INFO - READING ca-parc/2024/06/03.csv
[2024-07-25T13:13:05.104+0000] {motower_daily.py:136} INFO - DAILY KPI -      day_id       ca_voix       ca_data      parc  parc_data   parc_2g  parc_3g  parc_4g  parc_5g  parc_other      ca_total
0  20240603  5.767417e+08  7.912384e+08  16699131    9186215  12010574   873099  5756054   283564     1374011  1.416856e+09
[2024-07-25T13:13:05.105+0000] {data_validation.py:11} INFO - START VALIDATION OF COLUMN ca_total
[2024-07-25T13:13:05.105+0000] {data_validation.py:20} INFO - DATA OF COLUMN ca_total ARE VALID
[2024-07-25T13:13:05.106+0000] {data_validation.py:11} INFO - START VALIDATION OF COLUMN ca_voix
[2024-07-25T13:13:05.106+0000] {data_validation.py:20} INFO - DATA OF COLUMN ca_voix ARE VALID
[2024-07-25T13:13:05.106+0000] {data_validation.py:11} INFO - START VALIDATION OF COLUMN ca_data
[2024-07-25T13:13:05.107+0000] {data_validation.py:20} INFO - DATA OF COLUMN ca_data ARE VALID
[2024-07-25T13:13:05.107+0000] {data_validation.py:11} INFO - START VALIDATION OF COLUMN parc
[2024-07-25T13:13:05.107+0000] {data_validation.py:20} INFO - DATA OF COLUMN parc ARE VALID
[2024-07-25T13:13:05.108+0000] {data_validation.py:11} INFO - START VALIDATION OF COLUMN parc_data
[2024-07-25T13:13:05.108+0000] {data_validation.py:20} INFO - DATA OF COLUMN parc_data ARE VALID
[2024-07-25T13:13:05.108+0000] {motower_daily.py:139} INFO - MERGING BDD AND CA
[2024-07-25T13:13:05.111+0000] {motower_daily.py:141} INFO - prepare final daily data
[2024-07-25T13:13:05.112+0000] {logging_mixin.py:188} INFO - Index(['site', 'site bts', 'site physique', 'code oci', 'gestionnaire',
       'proprietaire', 'autre code', 'code esco', 'code ihs', 'longitude',
       'latitude', 'type du site', 'statut', 'couche en service',
       'technologie sans tdd', 'technologie', 'date mes 2g', 'date mes',
       'date mes 3g', 'date mes 4g', 'annee construction pylone',
       'statut sharing', 'statut proprietaire', 'statut partage',
       'geo localite', 'commune', 'departement', 'region', 'district',
       'partenaires', 'localisation', 'equipementier telecom', 'ville',
       'quartier', 'type baie', 'hauteur batiment', 'tower type',
       'tower location', 'type geolocalite', 'tower height', 'type site ihs',
       'type energie', 'projet', 'id quartier', 'id geolocalite', 'clutter',
       'position site', 'type indoor', 'decoupage', 'sous coloc', 'tenant',
       'type de cable', 'mois', 'code oci id', 'day_id', 'id_site', 'ca_voix',
       'ca_data', 'ca_total', 'trafic_voix_in', 'trafic_data_in', 'parc',
       'parc_data', 'parc_2g', 'parc_3g', 'parc_4g', 'parc_5g', 'parc_other',
       'jour'],
      dtype='object')
[2024-07-25T13:13:05.114+0000] {warnings.py:112} WARNING - /opt/***/dags/gps/common/motower_daily.py:148: SettingWithCopyWarning: 
A value is trying to be set on a copy of a slice from a DataFrame

See the caveats in the documentation: https://pandas.pydata.org/pandas-docs/stable/user_guide/indexing.html#returning-a-view-versus-a-copy
  df_final.rename(columns=DAILY_CAPARC_COL, inplace=True)

[2024-07-25T13:13:05.115+0000] {warnings.py:112} WARNING - /opt/***/dags/gps/common/motower_daily.py:149: SettingWithCopyWarning: 
A value is trying to be set on a copy of a slice from a DataFrame.
Try using .loc[row_indexer,col_indexer] = value instead

See the caveats in the documentation: https://pandas.pydata.org/pandas-docs/stable/user_guide/indexing.html#returning-a-view-versus-a-copy
  df_final["trafic_data_in_mo"] = df_final["trafic_data_in"] / 1000

[2024-07-25T13:13:05.116+0000] {warnings.py:112} WARNING - /opt/***/dags/gps/common/motower_daily.py:150: SettingWithCopyWarning: 
A value is trying to be set on a copy of a slice from a DataFrame.
Try using .loc[row_indexer,col_indexer] = value instead

See the caveats in the documentation: https://pandas.pydata.org/pandas-docs/stable/user_guide/indexing.html#returning-a-view-versus-a-copy
  df_final["ca_norm"] = None

[2024-07-25T13:13:05.116+0000] {warnings.py:112} WARNING - /opt/***/dags/gps/common/motower_daily.py:151: SettingWithCopyWarning: 
A value is trying to be set on a copy of a slice from a DataFrame.
Try using .loc[row_indexer,col_indexer] = value instead

See the caveats in the documentation: https://pandas.pydata.org/pandas-docs/stable/user_guide/indexing.html#returning-a-view-versus-a-copy
  df_final["ca_mtd"] = None

[2024-07-25T13:13:05.117+0000] {warnings.py:112} WARNING - /opt/***/dags/gps/common/motower_daily.py:152: SettingWithCopyWarning: 
A value is trying to be set on a copy of a slice from a DataFrame.
Try using .loc[row_indexer,col_indexer] = value instead

See the caveats in the documentation: https://pandas.pydata.org/pandas-docs/stable/user_guide/indexing.html#returning-a-view-versus-a-copy
  df_final["segment"] = None

[2024-07-25T13:13:05.117+0000] {warnings.py:112} WARNING - /opt/***/dags/gps/common/motower_daily.py:153: SettingWithCopyWarning: 
A value is trying to be set on a copy of a slice from a DataFrame.
Try using .loc[row_indexer,col_indexer] = value instead

See the caveats in the documentation: https://pandas.pydata.org/pandas-docs/stable/user_guide/indexing.html#returning-a-view-versus-a-copy
  df_final["previous_segment"] = None

[2024-07-25T13:13:05.118+0000] {warnings.py:112} WARNING - /opt/***/dags/gps/common/motower_daily.py:154: SettingWithCopyWarning: 
A value is trying to be set on a copy of a slice from a DataFrame.
Try using .loc[row_indexer,col_indexer] = value instead

See the caveats in the documentation: https://pandas.pydata.org/pandas-docs/stable/user_guide/indexing.html#returning-a-view-versus-a-copy
  df_final["evolution_segment"] = None

[2024-07-25T13:13:05.118+0000] {logging_mixin.py:188} INFO - 6
[2024-07-25T13:13:05.118+0000] {logging_mixin.py:188} INFO - 2024-06-03 00:00:00
[2024-07-25T13:13:05.118+0000] {logging_mixin.py:188} INFO - Start date<exec_date
[2024-07-25T13:13:05.122+0000] {warnings.py:112} WARNING - /opt/***/dags/gps/common/motower_daily.py:164: UserWarning: pandas only supports SQLAlchemy connectable (engine/connection) or database string URI or sqlite3 DBAPI2 connection. Other DBAPI2 objects are not tested. Please consider using SQLAlchemy.
  daily_month_df = pd.read_sql_query(sql_query, CONN, params=(mois, date))

[2024-07-25T13:13:05.215+0000] {warnings.py:112} WARNING - /opt/***/dags/gps/common/motower_daily.py:165: FutureWarning: The behavior of DataFrame concatenation with empty or all-NA entries is deprecated. In a future version, this will no longer exclude empty or all-NA columns when determining the result dtypes. To retain the old behavior, exclude the relevant entries before the concat operation.
  month_data = pd.concat([daily_month_df, df_final])

[2024-07-25T13:13:05.229+0000] {warnings.py:112} WARNING - /opt/***/dags/gps/common/motower_daily.py:169: UserWarning: pandas only supports SQLAlchemy connectable (engine/connection) or database string URI or sqlite3 DBAPI2 connection. Other DBAPI2 objects are not tested. Please consider using SQLAlchemy.
  last_month = pd.read_sql_query(sql_query, CONN, params=(lmonth.month,exec_date.day))

[2024-07-25T13:13:05.281+0000] {logging_mixin.py:188} INFO - (3107, 39)
[2024-07-25T13:13:05.289+0000] {motower_daily.py:175} INFO - ADD  SEGMENT
[2024-07-25T13:13:05.929+0000] {logging_mixin.py:188} INFO - hello
[2024-07-25T13:13:05.929+0000] {motower_daily.py:182} INFO - ADD PREVIOUS SEGMENT
[2024-07-25T13:13:05.941+0000] {logging_mixin.py:188} INFO - ########################################################################
[2024-07-25T13:13:05.965+0000] {logging_mixin.py:188} INFO -       id       jour code_oci  ...  previous_segment evolution_segment segment_y
3074 NaN 2024-06-03  OCI3190  ...                                None          

[1 rows x 40 columns]
[2024-07-25T13:13:05.966+0000] {motower_daily.py:188} INFO - ADD EVOLUTION SEGMENT
[2024-07-25T13:13:06.065+0000] {taskinstance.py:441} INFO - ::group::Post task execution logs
[2024-07-25T13:13:06.065+0000] {taskinstance.py:2905} ERROR - Task failed with exception
Traceback (most recent call last):
  File "/home/airflow/.local/lib/python3.12/site-packages/airflow/models/taskinstance.py", line 465, in _execute_task
    result = _execute_callable(context=context, **execute_callable_kwargs)
             ^^^^^^^^^^^^^^^^^^^^^^^^^^^^^^^^^^^^^^^^^^^^^^^^^^^^^^^^^^^^^
  File "/home/airflow/.local/lib/python3.12/site-packages/airflow/models/taskinstance.py", line 432, in _execute_callable
    return execute_callable(context=context, **execute_callable_kwargs)
           ^^^^^^^^^^^^^^^^^^^^^^^^^^^^^^^^^^^^^^^^^^^^^^^^^^^^^^^^^^^^
  File "/home/airflow/.local/lib/python3.12/site-packages/airflow/models/baseoperator.py", line 401, in wrapper
    return func(self, *args, **kwargs)
           ^^^^^^^^^^^^^^^^^^^^^^^^^^^
  File "/home/airflow/.local/lib/python3.12/site-packages/airflow/operators/python.py", line 235, in execute
    return_value = self.execute_callable()
                   ^^^^^^^^^^^^^^^^^^^^^^^
  File "/home/airflow/.local/lib/python3.12/site-packages/airflow/operators/python.py", line 252, in execute_callable
    return self.python_callable(*self.op_args, **self.op_kwargs)
           ^^^^^^^^^^^^^^^^^^^^^^^^^^^^^^^^^^^^^^^^^^^^^^^^^^^^^
  File "/opt/airflow/dags/gps/custom_dags/motower_daily.py", line 113, in gen_motower_daily
    data = generate_daily_caparc(
       ^^^^^^^^^^^^^^^^^^^^^^
  File "/opt/airflow/dags/gps/common/motower_daily.py", line 189, in generate_daily_caparc
    df_final = df_final.apply(func=compute_evolution, axis=1)
               ^^^^^^^^^^^^^^^^^^^^^^^^^^^^^^^^^^^^^^^^^^^^^^
  File "/home/airflow/.local/lib/python3.12/site-packages/pandas/core/frame.py", line 10034, in apply
    return op.apply().__finalize__(self, method="apply")
           ^^^^^^^^^^
  File "/home/airflow/.local/lib/python3.12/site-packages/pandas/core/apply.py", line 837, in apply
    return self.apply_standard()
           ^^^^^^^^^^^^^^^^^^^^^
  File "/home/airflow/.local/lib/python3.12/site-packages/pandas/core/apply.py", line 965, in apply_standard
    results, res_index = self.apply_series_generator()
                         ^^^^^^^^^^^^^^^^^^^^^^^^^^^^^
  File "/home/airflow/.local/lib/python3.12/site-packages/pandas/core/apply.py", line 981, in apply_series_generator
    results[i] = self.func(v, *self.args, **self.kwargs)
                 ^^^^^^^^^^^^^^^^^^^^^^^^^^^^^^^^^^^^^^^
  File "/opt/airflow/dags/gps/common/motower_daily.py", line 92, in compute_evolution
    if current_segment  > previous_segment:
       ^^^^^^^^^^^^^^^^^^^^^^^^^^^^^^^^^^^
TypeError: '>' not supported between instances of 'int' and 'NoneType'
[2024-07-25T13:13:06.077+0000] {taskinstance.py:1206} INFO - Marking task as FAILED. dag_id=motower_daily_prod, task_id=motower_dcaparc, run_id=scheduled__2024-06-04T06:00:00+00:00, execution_date=20240604T060000, start_date=20240725T131304, end_date=20240725T131306
[2024-07-25T13:13:06.094+0000] {warnings.py:112} WARNING - /home/***/.local/lib/python3.12/site-packages/***/utils/email.py:154: RemovedInAirflow3Warning: Fetching SMTP credentials from configuration variables will be deprecated in a future release. Please set credentials using a connection instead.
  send_mime_email(e_from=mail_from, e_to=recipients, mime_msg=msg, conn_id=conn_id, dryrun=dryrun)

[2024-07-25T13:13:06.094+0000] {configuration.py:1053} WARNING - section/key [smtp/smtp_user] not found in config
[2024-07-25T13:13:06.095+0000] {email.py:271} INFO - Email alerting: attempt 1
[2024-07-25T13:13:06.103+0000] {configuration.py:1053} WARNING - section/key [smtp/smtp_user] not found in config
[2024-07-25T13:13:06.104+0000] {email.py:271} INFO - Email alerting: attempt 1
[2024-07-25T13:13:06.104+0000] {taskinstance.py:879} ERROR - Failed to send email to: ['richmond.kongo@orange.com', 'assane.diop@orange.com', 'cyrille1.danho@orange.com', 'mohamed2.sylla@orange.com', 'amadou.diomande@orange.com', 'Jonas.kouame@orange.com', 'armand.kablan@orange.com', 'anicet.azombade@orange.com', 'etienne.kouadio@orange.com', 'bertine.kouakou@orange.com', 'florentine.kouakou@orange.com', 'ange.phaceli@orange.com', 'soulegame.soro@orange.com', 'innocent.yengo@orange.com']
Traceback (most recent call last):
  File "/home/airflow/.local/lib/python3.12/site-packages/airflow/models/taskinstance.py", line 2479, in _run_raw_task
    self._execute_task_with_callbacks(context, test_mode, session=session)
  File "/home/airflow/.local/lib/python3.12/site-packages/airflow/models/taskinstance.py", line 2676, in _execute_task_with_callbacks
    result = self._execute_task(context, task_orig)
             ^^^^^^^^^^^^^^^^^^^^^^^^^^^^^^^^^^^^^^
  File "/home/airflow/.local/lib/python3.12/site-packages/airflow/models/taskinstance.py", line 2701, in _execute_task
    return _execute_task(self, context, task_orig)
           ^^^^^^^^^^^^^^^^^^^^^^^^^^^^^^^^^^^^^^^
  File "/home/airflow/.local/lib/python3.12/site-packages/airflow/models/taskinstance.py", line 465, in _execute_task
    result = _execute_callable(context=context, **execute_callable_kwargs)
             ^^^^^^^^^^^^^^^^^^^^^^^^^^^^^^^^^^^^^^^^^^^^^^^^^^^^^^^^^^^^^
  File "/home/airflow/.local/lib/python3.12/site-packages/airflow/models/taskinstance.py", line 432, in _execute_callable
    return execute_callable(context=context, **execute_callable_kwargs)
           ^^^^^^^^^^^^^^^^^^^^^^^^^^^^^^^^^^^^^^^^^^^^^^^^^^^^^^^^^^^^
  File "/home/airflow/.local/lib/python3.12/site-packages/airflow/models/baseoperator.py", line 401, in wrapper
    return func(self, *args, **kwargs)
           ^^^^^^^^^^^^^^^^^^^^^^^^^^^
  File "/home/airflow/.local/lib/python3.12/site-packages/airflow/operators/python.py", line 235, in execute
    return_value = self.execute_callable()
                   ^^^^^^^^^^^^^^^^^^^^^^^
  File "/home/airflow/.local/lib/python3.12/site-packages/airflow/operators/python.py", line 252, in execute_callable
    return self.python_callable(*self.op_args, **self.op_kwargs)
           ^^^^^^^^^^^^^^^^^^^^^^^^^^^^^^^^^^^^^^^^^^^^^^^^^^^^^
  File "/opt/airflow/dags/gps/custom_dags/motower_daily.py", line 113, in gen_motower_daily
    data = generate_daily_caparc(
       ^^^^^^^^^^^^^^^^^^^^^^
  File "/opt/airflow/dags/gps/common/motower_daily.py", line 189, in generate_daily_caparc
    df_final = df_final.apply(func=compute_evolution, axis=1)
               ^^^^^^^^^^^^^^^^^^^^^^^^^^^^^^^^^^^^^^^^^^^^^^
  File "/home/airflow/.local/lib/python3.12/site-packages/pandas/core/frame.py", line 10034, in apply
    return op.apply().__finalize__(self, method="apply")
           ^^^^^^^^^^
  File "/home/airflow/.local/lib/python3.12/site-packages/pandas/core/apply.py", line 837, in apply
    return self.apply_standard()
           ^^^^^^^^^^^^^^^^^^^^^
  File "/home/airflow/.local/lib/python3.12/site-packages/pandas/core/apply.py", line 965, in apply_standard
    results, res_index = self.apply_series_generator()
                         ^^^^^^^^^^^^^^^^^^^^^^^^^^^^^
  File "/home/airflow/.local/lib/python3.12/site-packages/pandas/core/apply.py", line 981, in apply_series_generator
    results[i] = self.func(v, *self.args, **self.kwargs)
                 ^^^^^^^^^^^^^^^^^^^^^^^^^^^^^^^^^^^^^^^
  File "/opt/airflow/dags/gps/common/motower_daily.py", line 92, in compute_evolution
    if current_segment  > previous_segment:
       ^^^^^^^^^^^^^^^^^^^^^^^^^^^^^^^^^^^
TypeError: '>' not supported between instances of 'int' and 'NoneType'

During handling of the above exception, another exception occurred:

Traceback (most recent call last):
  File "/home/airflow/.local/lib/python3.12/site-packages/airflow/models/taskinstance.py", line 1063, in _email_alert
    send_email(task.email, subject, html_content)
  File "/home/airflow/.local/lib/python3.12/site-packages/airflow/utils/email.py", line 80, in send_email
    return backend(
           ^^^^^^^^
  File "/home/airflow/.local/lib/python3.12/site-packages/airflow/utils/email.py", line 154, in send_email_smtp
    send_mime_email(e_from=mail_from, e_to=recipients, mime_msg=msg, conn_id=conn_id, dryrun=dryrun)
  File "/home/airflow/.local/lib/python3.12/site-packages/airflow/utils/email.py", line 273, in send_mime_email
    smtp_conn = _get_smtp_connection(smtp_host, smtp_port, smtp_timeout, smtp_ssl)
                ^^^^^^^^^^^^^^^^^^^^^^^^^^^^^^^^^^^^^^^^^^^^^^^^^^^^^^^^^^^^^^^^^^
  File "/home/airflow/.local/lib/python3.12/site-packages/airflow/utils/email.py", line 317, in _get_smtp_connection
    return smtplib.SMTP(host=host, port=port, timeout=timeout)
           ^^^^^^^^^^^^^^^^^^^^^^^^^^^^^^^^^^^^^^^^^^^^^^^^^^^
  File "/usr/local/lib/python3.12/smtplib.py", line 255, in __init__
    (code, msg) = self.connect(host, port)
                  ^^^^^^^^^^^^^^^^^^^^^^^^
  File "/usr/local/lib/python3.12/smtplib.py", line 341, in connect
    self.sock = self._get_socket(host, port, self.timeout)
                ^^^^^^^^^^^^^^^^^^^^^^^^^^^^^^^^^^^^^^^^^^
  File "/usr/local/lib/python3.12/smtplib.py", line 312, in _get_socket
    return socket.create_connection((host, port), timeout,
           ^^^^^^^^^^^^^^^^^^^^^^^^^^^^^^^^^^^^^^^^^^^^^^^
  File "/usr/local/lib/python3.12/socket.py", line 853, in create_connection
    raise exceptions[0]
  File "/usr/local/lib/python3.12/socket.py", line 838, in create_connection
    sock.connect(sa)
ConnectionRefusedError: [Errno 111] Connection refused

During handling of the above exception, another exception occurred:

Traceback (most recent call last):
  File "/home/airflow/.local/lib/python3.12/site-packages/airflow/models/taskinstance.py", line 877, in _handle_failure
    task_instance.email_alert(error, failure_context["task"])
  File "/home/airflow/.local/lib/python3.12/site-packages/airflow/models/taskinstance.py", line 3163, in email_alert
    _email_alert(task_instance=self, exception=exception, task=task)
  File "/home/airflow/.local/lib/python3.12/site-packages/airflow/models/taskinstance.py", line 1065, in _email_alert
    send_email(task.email, subject, html_content_err)
  File "/home/airflow/.local/lib/python3.12/site-packages/airflow/utils/email.py", line 80, in send_email
    return backend(
           ^^^^^^^^
  File "/home/airflow/.local/lib/python3.12/site-packages/airflow/utils/email.py", line 154, in send_email_smtp
    send_mime_email(e_from=mail_from, e_to=recipients, mime_msg=msg, conn_id=conn_id, dryrun=dryrun)
  File "/home/airflow/.local/lib/python3.12/site-packages/airflow/utils/email.py", line 273, in send_mime_email
    smtp_conn = _get_smtp_connection(smtp_host, smtp_port, smtp_timeout, smtp_ssl)
                ^^^^^^^^^^^^^^^^^^^^^^^^^^^^^^^^^^^^^^^^^^^^^^^^^^^^^^^^^^^^^^^^^^
  File "/home/airflow/.local/lib/python3.12/site-packages/airflow/utils/email.py", line 317, in _get_smtp_connection
    return smtplib.SMTP(host=host, port=port, timeout=timeout)
           ^^^^^^^^^^^^^^^^^^^^^^^^^^^^^^^^^^^^^^^^^^^^^^^^^^^
  File "/usr/local/lib/python3.12/smtplib.py", line 255, in __init__
    (code, msg) = self.connect(host, port)
                  ^^^^^^^^^^^^^^^^^^^^^^^^
  File "/usr/local/lib/python3.12/smtplib.py", line 341, in connect
    self.sock = self._get_socket(host, port, self.timeout)
                ^^^^^^^^^^^^^^^^^^^^^^^^^^^^^^^^^^^^^^^^^^
  File "/usr/local/lib/python3.12/smtplib.py", line 312, in _get_socket
    return socket.create_connection((host, port), timeout,
           ^^^^^^^^^^^^^^^^^^^^^^^^^^^^^^^^^^^^^^^^^^^^^^^
  File "/usr/local/lib/python3.12/socket.py", line 853, in create_connection
    raise exceptions[0]
  File "/usr/local/lib/python3.12/socket.py", line 838, in create_connection
    sock.connect(sa)
ConnectionRefusedError: [Errno 111] Connection refused
[2024-07-25T13:13:06.109+0000] {alerting.py:71} INFO - send alert mail to richmond.kongo@orange.com, assane.diop@orange.com, cyrille1.danho@orange.com, mohamed2.sylla@orange.com, amadou.diomande@orange.com, Jonas.kouame@orange.com, armand.kablan@orange.com, anicet.azombade@orange.com, etienne.kouadio@orange.com, bertine.kouakou@orange.com, florentine.kouakou@orange.com, ange.phaceli@orange.com, soulegame.soro@orange.com, innocent.yengo@orange.com
[2024-07-25T13:13:06.109+0000] {alerting.py:30} INFO - Sending mail ... 
[2024-07-25T13:13:06.109+0000] {alerting.py:38} ERROR - Failed to send email: please run connect() first
[2024-07-25T13:13:06.124+0000] {standard_task_runner.py:110} ERROR - Failed to execute job 2482 for task motower_dcaparc ('>' not supported between instances of 'int' and 'NoneType'; 10967)
[2024-07-25T13:13:06.188+0000] {local_task_job_runner.py:243} INFO - Task exited with return code 1
[2024-07-25T13:13:06.207+0000] {taskinstance.py:3503} INFO - 0 downstream tasks scheduled from follow-on schedule check
[2024-07-25T13:13:06.208+0000] {local_task_job_runner.py:222} INFO - ::endgroup::
