[2024-07-22T16:28:06.563+0000] {local_task_job_runner.py:120} INFO - ::group::Pre task execution logs
[2024-07-22T16:28:06.778+0000] {taskinstance.py:2076} INFO - Dependencies all met for dep_context=non-requeueable deps ti=<TaskInstance: motower_daily_prod.sensor_congestion scheduled__2024-07-09T06:00:00+00:00 [queued]>
[2024-07-22T16:28:06.786+0000] {taskinstance.py:2076} INFO - Dependencies all met for dep_context=requeueable deps ti=<TaskInstance: motower_daily_prod.sensor_congestion scheduled__2024-07-09T06:00:00+00:00 [queued]>
[2024-07-22T16:28:06.786+0000] {taskinstance.py:2306} INFO - Starting attempt 1 of 1
[2024-07-22T16:28:06.797+0000] {taskinstance.py:2330} INFO - Executing <Task(PythonSensor): sensor_congestion> on 2024-07-09 06:00:00+00:00
[2024-07-22T16:28:06.806+0000] {warnings.py:112} WARNING - /home/***/.local/lib/python3.12/site-packages/***/task/task_runner/standard_task_runner.py:62: DeprecationWarning: This process (pid=361) is multi-threaded, use of fork() may lead to deadlocks in the child.
  pid = os.fork()

[2024-07-22T16:28:06.807+0000] {standard_task_runner.py:64} INFO - Started process 367 to run task
[2024-07-22T16:28:06.807+0000] {standard_task_runner.py:90} INFO - Running: ['***', 'tasks', 'run', 'motower_daily_prod', 'sensor_congestion', 'scheduled__2024-07-09T06:00:00+00:00', '--job-id', '18', '--raw', '--subdir', 'DAGS_FOLDER/gps/custom_dags/motower_daily.py', '--cfg-path', '/tmp/tmpqr5xpe4p']
[2024-07-22T16:28:06.809+0000] {standard_task_runner.py:91} INFO - Job 18: Subtask sensor_congestion
[2024-07-22T16:28:06.843+0000] {task_command.py:426} INFO - Running <TaskInstance: motower_daily_prod.sensor_congestion scheduled__2024-07-09T06:00:00+00:00 [running]> on host 5e959f2258db
[2024-07-22T16:28:06.925+0000] {taskinstance.py:2648} INFO - Exporting env vars: AIRFLOW_CTX_DAG_EMAIL='richmond.kongo@orange.com,assane.diop@orange.com,cyrille1.danho@orange.com,mohamed2.sylla@orange.com,amadou.diomande@orange.com,Jonas.kouame@orange.com,armand.kablan@orange.com,anicet.azombade@orange.com,etienne.kouadio@orange.com,bertine.kouakou@orange.com,florentine.kouakou@orange.com,ange.phaceli@orange.com,soulegame.soro@orange.com,innocent.yengo@orange.com' AIRFLOW_CTX_DAG_OWNER='***' AIRFLOW_CTX_DAG_ID='motower_daily_prod' AIRFLOW_CTX_TASK_ID='sensor_congestion' AIRFLOW_CTX_EXECUTION_DATE='2024-07-09T06:00:00+00:00' AIRFLOW_CTX_TRY_NUMBER='1' AIRFLOW_CTX_DAG_RUN_ID='scheduled__2024-07-09T06:00:00+00:00'
[2024-07-22T16:28:06.925+0000] {taskinstance.py:430} INFO - ::endgroup::
[2024-07-22T16:28:06.934+0000] {python.py:75} INFO - Poking callable: <function check_data_in_table at 0x728653a12ca0>
[2024-07-22T16:28:06.937+0000] {extract.py:127} INFO - Getting data of the table ks_hebdo_tdb_radio_drsi 
[2024-07-22T16:28:06.937+0000] {extract.py:128} INFO - where date is 2024-07-08
[2024-07-22T16:28:06.938+0000] {extract.py:99} INFO - get data to date 28 and year 2024
[2024-07-22T16:28:06.941+0000] {warnings.py:112} WARNING - /opt/***/dags/gps/common/extract.py:100: UserWarning: pandas only supports SQLAlchemy connectable (engine/connection) or database string URI or sqlite3 DBAPI2 connection. Other DBAPI2 objects are not tested. Please consider using SQLAlchemy.
  df_ = pd.read_sql_query(sql_query, conn, params=params)

[2024-07-22T16:28:32.062+0000] {local_task_job_runner.py:313} WARNING - State of this instance has been externally set to None. Terminating instance.
[2024-07-22T16:28:32.064+0000] {local_task_job_runner.py:222} INFO - ::endgroup::
[2024-07-22T16:28:32.065+0000] {process_utils.py:132} INFO - Sending 15 to group 367. PIDs of all processes in the group: [367]
[2024-07-22T16:28:32.065+0000] {process_utils.py:87} INFO - Sending the signal 15 to group 367
[2024-07-22T16:28:32.065+0000] {taskinstance.py:2611} ERROR - Received SIGTERM. Terminating subprocesses.
[2024-07-22T16:28:32.066+0000] {taskinstance.py:441} INFO - ::group::Post task execution logs
[2024-07-22T16:28:32.076+0000] {taskinstance.py:2905} ERROR - Task failed with exception
Traceback (most recent call last):
  File "/home/airflow/.local/lib/python3.12/site-packages/airflow/models/taskinstance.py", line 465, in _execute_task
    result = _execute_callable(context=context, **execute_callable_kwargs)
             ^^^^^^^^^^^^^^^^^^^^^^^^^^^^^^^^^^^^^^^^^^^^^^^^^^^^^^^^^^^^^
  File "/home/airflow/.local/lib/python3.12/site-packages/airflow/models/taskinstance.py", line 432, in _execute_callable
    return execute_callable(context=context, **execute_callable_kwargs)
           ^^^^^^^^^^^^^^^^^^^^^^^^^^^^^^^^^^^^^^^^^^^^^^^^^^^^^^^^^^^^
  File "/home/airflow/.local/lib/python3.12/site-packages/airflow/models/baseoperator.py", line 401, in wrapper
    return func(self, *args, **kwargs)
           ^^^^^^^^^^^^^^^^^^^^^^^^^^^
  File "/home/airflow/.local/lib/python3.12/site-packages/airflow/sensors/base.py", line 292, in execute
    time.sleep(self._get_next_poke_interval(started_at, run_duration, poke_count))
  File "/home/airflow/.local/lib/python3.12/site-packages/airflow/models/taskinstance.py", line 2613, in signal_handler
    raise AirflowTaskTerminated("Task received SIGTERM signal")
airflow.exceptions.AirflowTaskTerminated: Task received SIGTERM signal
[2024-07-22T16:28:32.080+0000] {taskinstance.py:1206} INFO - Marking task as FAILED. dag_id=motower_daily_prod, task_id=sensor_congestion, run_id=scheduled__2024-07-09T06:00:00+00:00, execution_date=20240709T060000, start_date=20240722T162806, end_date=20240722T162832
[2024-07-22T16:28:32.090+0000] {warnings.py:112} WARNING - /home/***/.local/lib/python3.12/site-packages/***/utils/email.py:154: RemovedInAirflow3Warning: Fetching SMTP credentials from configuration variables will be deprecated in a future release. Please set credentials using a connection instead.
  send_mime_email(e_from=mail_from, e_to=recipients, mime_msg=msg, conn_id=conn_id, dryrun=dryrun)

[2024-07-22T16:28:32.091+0000] {configuration.py:1053} WARNING - section/key [smtp/smtp_user] not found in config
[2024-07-22T16:28:32.091+0000] {email.py:271} INFO - Email alerting: attempt 1
[2024-07-22T16:28:32.099+0000] {configuration.py:1053} WARNING - section/key [smtp/smtp_user] not found in config
[2024-07-22T16:28:32.099+0000] {email.py:271} INFO - Email alerting: attempt 1
[2024-07-22T16:28:32.099+0000] {taskinstance.py:879} ERROR - Failed to send email to: ['richmond.kongo@orange.com', 'assane.diop@orange.com', 'cyrille1.danho@orange.com', 'mohamed2.sylla@orange.com', 'amadou.diomande@orange.com', 'Jonas.kouame@orange.com', 'armand.kablan@orange.com', 'anicet.azombade@orange.com', 'etienne.kouadio@orange.com', 'bertine.kouakou@orange.com', 'florentine.kouakou@orange.com', 'ange.phaceli@orange.com', 'soulegame.soro@orange.com', 'innocent.yengo@orange.com']
Traceback (most recent call last):
  File "/home/airflow/.local/lib/python3.12/site-packages/airflow/models/taskinstance.py", line 2479, in _run_raw_task
    self._execute_task_with_callbacks(context, test_mode, session=session)
  File "/home/airflow/.local/lib/python3.12/site-packages/airflow/models/taskinstance.py", line 2676, in _execute_task_with_callbacks
    result = self._execute_task(context, task_orig)
             ^^^^^^^^^^^^^^^^^^^^^^^^^^^^^^^^^^^^^^
  File "/home/airflow/.local/lib/python3.12/site-packages/airflow/models/taskinstance.py", line 2701, in _execute_task
    return _execute_task(self, context, task_orig)
           ^^^^^^^^^^^^^^^^^^^^^^^^^^^^^^^^^^^^^^^
  File "/home/airflow/.local/lib/python3.12/site-packages/airflow/models/taskinstance.py", line 465, in _execute_task
    result = _execute_callable(context=context, **execute_callable_kwargs)
             ^^^^^^^^^^^^^^^^^^^^^^^^^^^^^^^^^^^^^^^^^^^^^^^^^^^^^^^^^^^^^
  File "/home/airflow/.local/lib/python3.12/site-packages/airflow/models/taskinstance.py", line 432, in _execute_callable
    return execute_callable(context=context, **execute_callable_kwargs)
           ^^^^^^^^^^^^^^^^^^^^^^^^^^^^^^^^^^^^^^^^^^^^^^^^^^^^^^^^^^^^
  File "/home/airflow/.local/lib/python3.12/site-packages/airflow/models/baseoperator.py", line 401, in wrapper
    return func(self, *args, **kwargs)
           ^^^^^^^^^^^^^^^^^^^^^^^^^^^
  File "/home/airflow/.local/lib/python3.12/site-packages/airflow/sensors/base.py", line 292, in execute
    time.sleep(self._get_next_poke_interval(started_at, run_duration, poke_count))
  File "/home/airflow/.local/lib/python3.12/site-packages/airflow/models/taskinstance.py", line 2613, in signal_handler
    raise AirflowTaskTerminated("Task received SIGTERM signal")
airflow.exceptions.AirflowTaskTerminated: Task received SIGTERM signal

During handling of the above exception, another exception occurred:

Traceback (most recent call last):
  File "/home/airflow/.local/lib/python3.12/site-packages/airflow/models/taskinstance.py", line 1063, in _email_alert
    send_email(task.email, subject, html_content)
  File "/home/airflow/.local/lib/python3.12/site-packages/airflow/utils/email.py", line 80, in send_email
    return backend(
           ^^^^^^^^
  File "/home/airflow/.local/lib/python3.12/site-packages/airflow/utils/email.py", line 154, in send_email_smtp
    send_mime_email(e_from=mail_from, e_to=recipients, mime_msg=msg, conn_id=conn_id, dryrun=dryrun)
  File "/home/airflow/.local/lib/python3.12/site-packages/airflow/utils/email.py", line 273, in send_mime_email
    smtp_conn = _get_smtp_connection(smtp_host, smtp_port, smtp_timeout, smtp_ssl)
                ^^^^^^^^^^^^^^^^^^^^^^^^^^^^^^^^^^^^^^^^^^^^^^^^^^^^^^^^^^^^^^^^^^
  File "/home/airflow/.local/lib/python3.12/site-packages/airflow/utils/email.py", line 317, in _get_smtp_connection
    return smtplib.SMTP(host=host, port=port, timeout=timeout)
           ^^^^^^^^^^^^^^^^^^^^^^^^^^^^^^^^^^^^^^^^^^^^^^^^^^^
  File "/usr/local/lib/python3.12/smtplib.py", line 255, in __init__
    (code, msg) = self.connect(host, port)
                  ^^^^^^^^^^^^^^^^^^^^^^^^
  File "/usr/local/lib/python3.12/smtplib.py", line 341, in connect
    self.sock = self._get_socket(host, port, self.timeout)
                ^^^^^^^^^^^^^^^^^^^^^^^^^^^^^^^^^^^^^^^^^^
  File "/usr/local/lib/python3.12/smtplib.py", line 312, in _get_socket
    return socket.create_connection((host, port), timeout,
           ^^^^^^^^^^^^^^^^^^^^^^^^^^^^^^^^^^^^^^^^^^^^^^^
  File "/usr/local/lib/python3.12/socket.py", line 853, in create_connection
    raise exceptions[0]
  File "/usr/local/lib/python3.12/socket.py", line 838, in create_connection
    sock.connect(sa)
ConnectionRefusedError: [Errno 111] Connection refused

During handling of the above exception, another exception occurred:

Traceback (most recent call last):
  File "/home/airflow/.local/lib/python3.12/site-packages/airflow/models/taskinstance.py", line 877, in _handle_failure
    task_instance.email_alert(error, failure_context["task"])
  File "/home/airflow/.local/lib/python3.12/site-packages/airflow/models/taskinstance.py", line 3163, in email_alert
    _email_alert(task_instance=self, exception=exception, task=task)
  File "/home/airflow/.local/lib/python3.12/site-packages/airflow/models/taskinstance.py", line 1065, in _email_alert
    send_email(task.email, subject, html_content_err)
  File "/home/airflow/.local/lib/python3.12/site-packages/airflow/utils/email.py", line 80, in send_email
    return backend(
           ^^^^^^^^
  File "/home/airflow/.local/lib/python3.12/site-packages/airflow/utils/email.py", line 154, in send_email_smtp
    send_mime_email(e_from=mail_from, e_to=recipients, mime_msg=msg, conn_id=conn_id, dryrun=dryrun)
  File "/home/airflow/.local/lib/python3.12/site-packages/airflow/utils/email.py", line 273, in send_mime_email
    smtp_conn = _get_smtp_connection(smtp_host, smtp_port, smtp_timeout, smtp_ssl)
                ^^^^^^^^^^^^^^^^^^^^^^^^^^^^^^^^^^^^^^^^^^^^^^^^^^^^^^^^^^^^^^^^^^
  File "/home/airflow/.local/lib/python3.12/site-packages/airflow/utils/email.py", line 317, in _get_smtp_connection
    return smtplib.SMTP(host=host, port=port, timeout=timeout)
           ^^^^^^^^^^^^^^^^^^^^^^^^^^^^^^^^^^^^^^^^^^^^^^^^^^^
  File "/usr/local/lib/python3.12/smtplib.py", line 255, in __init__
    (code, msg) = self.connect(host, port)
                  ^^^^^^^^^^^^^^^^^^^^^^^^
  File "/usr/local/lib/python3.12/smtplib.py", line 341, in connect
    self.sock = self._get_socket(host, port, self.timeout)
                ^^^^^^^^^^^^^^^^^^^^^^^^^^^^^^^^^^^^^^^^^^
  File "/usr/local/lib/python3.12/smtplib.py", line 312, in _get_socket
    return socket.create_connection((host, port), timeout,
           ^^^^^^^^^^^^^^^^^^^^^^^^^^^^^^^^^^^^^^^^^^^^^^^
  File "/usr/local/lib/python3.12/socket.py", line 853, in create_connection
    raise exceptions[0]
  File "/usr/local/lib/python3.12/socket.py", line 838, in create_connection
    sock.connect(sa)
ConnectionRefusedError: [Errno 111] Connection refused
[2024-07-22T16:28:32.102+0000] {alerting.py:71} INFO - send alert mail to richmond.kongo@orange.com, assane.diop@orange.com, cyrille1.danho@orange.com, mohamed2.sylla@orange.com, amadou.diomande@orange.com, Jonas.kouame@orange.com, armand.kablan@orange.com, anicet.azombade@orange.com, etienne.kouadio@orange.com, bertine.kouakou@orange.com, florentine.kouakou@orange.com, ange.phaceli@orange.com, soulegame.soro@orange.com, innocent.yengo@orange.com
[2024-07-22T16:28:32.102+0000] {alerting.py:30} INFO - Sending mail ... 
[2024-07-22T16:28:32.103+0000] {alerting.py:38} ERROR - Failed to send email: please run connect() first
[2024-07-22T16:28:32.157+0000] {process_utils.py:80} INFO - Process psutil.Process(pid=367, status='terminated', exitcode=2, started='16:28:05') (367) terminated with exit code 2
[2024-07-22T16:29:05.371+0000] {local_task_job_runner.py:120} INFO - ::group::Pre task execution logs
[2024-07-22T16:29:05.585+0000] {taskinstance.py:2076} INFO - Dependencies all met for dep_context=non-requeueable deps ti=<TaskInstance: motower_daily_prod.sensor_congestion scheduled__2024-07-09T06:00:00+00:00 [queued]>
[2024-07-22T16:29:05.593+0000] {taskinstance.py:2076} INFO - Dependencies all met for dep_context=requeueable deps ti=<TaskInstance: motower_daily_prod.sensor_congestion scheduled__2024-07-09T06:00:00+00:00 [queued]>
[2024-07-22T16:29:05.593+0000] {taskinstance.py:2306} INFO - Starting attempt 1 of 1
[2024-07-22T16:29:05.603+0000] {taskinstance.py:2330} INFO - Executing <Task(PythonSensor): sensor_congestion> on 2024-07-09 06:00:00+00:00
[2024-07-22T16:29:05.612+0000] {warnings.py:112} WARNING - /home/***/.local/lib/python3.12/site-packages/***/task/task_runner/standard_task_runner.py:62: DeprecationWarning: This process (pid=409) is multi-threaded, use of fork() may lead to deadlocks in the child.
  pid = os.fork()

[2024-07-22T16:29:05.613+0000] {standard_task_runner.py:64} INFO - Started process 416 to run task
[2024-07-22T16:29:05.613+0000] {standard_task_runner.py:90} INFO - Running: ['***', 'tasks', 'run', 'motower_daily_prod', 'sensor_congestion', 'scheduled__2024-07-09T06:00:00+00:00', '--job-id', '29', '--raw', '--subdir', 'DAGS_FOLDER/gps/custom_dags/motower_daily.py', '--cfg-path', '/tmp/tmpcjx3lumb']
[2024-07-22T16:29:05.615+0000] {standard_task_runner.py:91} INFO - Job 29: Subtask sensor_congestion
[2024-07-22T16:29:05.650+0000] {task_command.py:426} INFO - Running <TaskInstance: motower_daily_prod.sensor_congestion scheduled__2024-07-09T06:00:00+00:00 [running]> on host 5e959f2258db
[2024-07-22T16:29:05.721+0000] {taskinstance.py:2648} INFO - Exporting env vars: AIRFLOW_CTX_DAG_EMAIL='richmond.kongo@orange.com,assane.diop@orange.com,cyrille1.danho@orange.com,mohamed2.sylla@orange.com,amadou.diomande@orange.com,Jonas.kouame@orange.com,armand.kablan@orange.com,anicet.azombade@orange.com,etienne.kouadio@orange.com,bertine.kouakou@orange.com,florentine.kouakou@orange.com,ange.phaceli@orange.com,soulegame.soro@orange.com,innocent.yengo@orange.com' AIRFLOW_CTX_DAG_OWNER='***' AIRFLOW_CTX_DAG_ID='motower_daily_prod' AIRFLOW_CTX_TASK_ID='sensor_congestion' AIRFLOW_CTX_EXECUTION_DATE='2024-07-09T06:00:00+00:00' AIRFLOW_CTX_TRY_NUMBER='1' AIRFLOW_CTX_DAG_RUN_ID='scheduled__2024-07-09T06:00:00+00:00'
[2024-07-22T16:29:05.722+0000] {taskinstance.py:430} INFO - ::endgroup::
[2024-07-22T16:29:05.731+0000] {python.py:75} INFO - Poking callable: <function check_data_in_table at 0x7286306fb1a0>
[2024-07-22T16:29:05.735+0000] {extract.py:127} INFO - Getting data of the table ks_hebdo_tdb_radio_drsi 
[2024-07-22T16:29:05.735+0000] {extract.py:128} INFO - where date is 2024-07-08
[2024-07-22T16:29:05.736+0000] {extract.py:99} INFO - get data to date 28 and year 2024
[2024-07-22T16:29:05.739+0000] {warnings.py:112} WARNING - /opt/***/dags/gps/common/extract.py:100: UserWarning: pandas only supports SQLAlchemy connectable (engine/connection) or database string URI or sqlite3 DBAPI2 connection. Other DBAPI2 objects are not tested. Please consider using SQLAlchemy.
  df_ = pd.read_sql_query(sql_query, conn, params=params)

[2024-07-22T16:37:00.231+0000] {local_task_job_runner.py:313} WARNING - State of this instance has been externally set to None. Terminating instance.
[2024-07-22T16:37:00.232+0000] {local_task_job_runner.py:222} INFO - ::endgroup::
[2024-07-22T16:37:00.234+0000] {process_utils.py:132} INFO - Sending 15 to group 416. PIDs of all processes in the group: [416]
[2024-07-22T16:37:00.234+0000] {process_utils.py:87} INFO - Sending the signal 15 to group 416
[2024-07-22T16:37:00.234+0000] {taskinstance.py:2611} ERROR - Received SIGTERM. Terminating subprocesses.
[2024-07-22T16:37:00.234+0000] {taskinstance.py:441} INFO - ::group::Post task execution logs
[2024-07-22T16:37:00.243+0000] {taskinstance.py:2905} ERROR - Task failed with exception
Traceback (most recent call last):
  File "/home/airflow/.local/lib/python3.12/site-packages/airflow/models/taskinstance.py", line 465, in _execute_task
    result = _execute_callable(context=context, **execute_callable_kwargs)
             ^^^^^^^^^^^^^^^^^^^^^^^^^^^^^^^^^^^^^^^^^^^^^^^^^^^^^^^^^^^^^
  File "/home/airflow/.local/lib/python3.12/site-packages/airflow/models/taskinstance.py", line 432, in _execute_callable
    return execute_callable(context=context, **execute_callable_kwargs)
           ^^^^^^^^^^^^^^^^^^^^^^^^^^^^^^^^^^^^^^^^^^^^^^^^^^^^^^^^^^^^
  File "/home/airflow/.local/lib/python3.12/site-packages/airflow/models/baseoperator.py", line 401, in wrapper
    return func(self, *args, **kwargs)
           ^^^^^^^^^^^^^^^^^^^^^^^^^^^
  File "/home/airflow/.local/lib/python3.12/site-packages/airflow/sensors/base.py", line 292, in execute
    time.sleep(self._get_next_poke_interval(started_at, run_duration, poke_count))
  File "/home/airflow/.local/lib/python3.12/site-packages/airflow/models/taskinstance.py", line 2613, in signal_handler
    raise AirflowTaskTerminated("Task received SIGTERM signal")
airflow.exceptions.AirflowTaskTerminated: Task received SIGTERM signal
[2024-07-22T16:37:00.246+0000] {taskinstance.py:1206} INFO - Marking task as FAILED. dag_id=motower_daily_prod, task_id=sensor_congestion, run_id=scheduled__2024-07-09T06:00:00+00:00, execution_date=20240709T060000, start_date=20240722T162905, end_date=20240722T163700
[2024-07-22T16:37:00.257+0000] {warnings.py:112} WARNING - /home/***/.local/lib/python3.12/site-packages/***/utils/email.py:154: RemovedInAirflow3Warning: Fetching SMTP credentials from configuration variables will be deprecated in a future release. Please set credentials using a connection instead.
  send_mime_email(e_from=mail_from, e_to=recipients, mime_msg=msg, conn_id=conn_id, dryrun=dryrun)

[2024-07-22T16:37:00.257+0000] {configuration.py:1053} WARNING - section/key [smtp/smtp_user] not found in config
[2024-07-22T16:37:00.257+0000] {email.py:271} INFO - Email alerting: attempt 1
[2024-07-22T16:37:00.264+0000] {configuration.py:1053} WARNING - section/key [smtp/smtp_user] not found in config
[2024-07-22T16:37:00.265+0000] {email.py:271} INFO - Email alerting: attempt 1
[2024-07-22T16:37:00.265+0000] {taskinstance.py:879} ERROR - Failed to send email to: ['richmond.kongo@orange.com', 'assane.diop@orange.com', 'cyrille1.danho@orange.com', 'mohamed2.sylla@orange.com', 'amadou.diomande@orange.com', 'Jonas.kouame@orange.com', 'armand.kablan@orange.com', 'anicet.azombade@orange.com', 'etienne.kouadio@orange.com', 'bertine.kouakou@orange.com', 'florentine.kouakou@orange.com', 'ange.phaceli@orange.com', 'soulegame.soro@orange.com', 'innocent.yengo@orange.com']
Traceback (most recent call last):
  File "/home/airflow/.local/lib/python3.12/site-packages/airflow/models/taskinstance.py", line 2479, in _run_raw_task
    self._execute_task_with_callbacks(context, test_mode, session=session)
  File "/home/airflow/.local/lib/python3.12/site-packages/airflow/models/taskinstance.py", line 2676, in _execute_task_with_callbacks
    result = self._execute_task(context, task_orig)
             ^^^^^^^^^^^^^^^^^^^^^^^^^^^^^^^^^^^^^^
  File "/home/airflow/.local/lib/python3.12/site-packages/airflow/models/taskinstance.py", line 2701, in _execute_task
    return _execute_task(self, context, task_orig)
           ^^^^^^^^^^^^^^^^^^^^^^^^^^^^^^^^^^^^^^^
  File "/home/airflow/.local/lib/python3.12/site-packages/airflow/models/taskinstance.py", line 465, in _execute_task
    result = _execute_callable(context=context, **execute_callable_kwargs)
             ^^^^^^^^^^^^^^^^^^^^^^^^^^^^^^^^^^^^^^^^^^^^^^^^^^^^^^^^^^^^^
  File "/home/airflow/.local/lib/python3.12/site-packages/airflow/models/taskinstance.py", line 432, in _execute_callable
    return execute_callable(context=context, **execute_callable_kwargs)
           ^^^^^^^^^^^^^^^^^^^^^^^^^^^^^^^^^^^^^^^^^^^^^^^^^^^^^^^^^^^^
  File "/home/airflow/.local/lib/python3.12/site-packages/airflow/models/baseoperator.py", line 401, in wrapper
    return func(self, *args, **kwargs)
           ^^^^^^^^^^^^^^^^^^^^^^^^^^^
  File "/home/airflow/.local/lib/python3.12/site-packages/airflow/sensors/base.py", line 292, in execute
    time.sleep(self._get_next_poke_interval(started_at, run_duration, poke_count))
  File "/home/airflow/.local/lib/python3.12/site-packages/airflow/models/taskinstance.py", line 2613, in signal_handler
    raise AirflowTaskTerminated("Task received SIGTERM signal")
airflow.exceptions.AirflowTaskTerminated: Task received SIGTERM signal

During handling of the above exception, another exception occurred:

Traceback (most recent call last):
  File "/home/airflow/.local/lib/python3.12/site-packages/airflow/models/taskinstance.py", line 1063, in _email_alert
    send_email(task.email, subject, html_content)
  File "/home/airflow/.local/lib/python3.12/site-packages/airflow/utils/email.py", line 80, in send_email
    return backend(
           ^^^^^^^^
  File "/home/airflow/.local/lib/python3.12/site-packages/airflow/utils/email.py", line 154, in send_email_smtp
    send_mime_email(e_from=mail_from, e_to=recipients, mime_msg=msg, conn_id=conn_id, dryrun=dryrun)
  File "/home/airflow/.local/lib/python3.12/site-packages/airflow/utils/email.py", line 273, in send_mime_email
    smtp_conn = _get_smtp_connection(smtp_host, smtp_port, smtp_timeout, smtp_ssl)
                ^^^^^^^^^^^^^^^^^^^^^^^^^^^^^^^^^^^^^^^^^^^^^^^^^^^^^^^^^^^^^^^^^^
  File "/home/airflow/.local/lib/python3.12/site-packages/airflow/utils/email.py", line 317, in _get_smtp_connection
    return smtplib.SMTP(host=host, port=port, timeout=timeout)
           ^^^^^^^^^^^^^^^^^^^^^^^^^^^^^^^^^^^^^^^^^^^^^^^^^^^
  File "/usr/local/lib/python3.12/smtplib.py", line 255, in __init__
    (code, msg) = self.connect(host, port)
                  ^^^^^^^^^^^^^^^^^^^^^^^^
  File "/usr/local/lib/python3.12/smtplib.py", line 341, in connect
    self.sock = self._get_socket(host, port, self.timeout)
                ^^^^^^^^^^^^^^^^^^^^^^^^^^^^^^^^^^^^^^^^^^
  File "/usr/local/lib/python3.12/smtplib.py", line 312, in _get_socket
    return socket.create_connection((host, port), timeout,
           ^^^^^^^^^^^^^^^^^^^^^^^^^^^^^^^^^^^^^^^^^^^^^^^
  File "/usr/local/lib/python3.12/socket.py", line 853, in create_connection
    raise exceptions[0]
  File "/usr/local/lib/python3.12/socket.py", line 838, in create_connection
    sock.connect(sa)
ConnectionRefusedError: [Errno 111] Connection refused

During handling of the above exception, another exception occurred:

Traceback (most recent call last):
  File "/home/airflow/.local/lib/python3.12/site-packages/airflow/models/taskinstance.py", line 877, in _handle_failure
    task_instance.email_alert(error, failure_context["task"])
  File "/home/airflow/.local/lib/python3.12/site-packages/airflow/models/taskinstance.py", line 3163, in email_alert
    _email_alert(task_instance=self, exception=exception, task=task)
  File "/home/airflow/.local/lib/python3.12/site-packages/airflow/models/taskinstance.py", line 1065, in _email_alert
    send_email(task.email, subject, html_content_err)
  File "/home/airflow/.local/lib/python3.12/site-packages/airflow/utils/email.py", line 80, in send_email
    return backend(
           ^^^^^^^^
  File "/home/airflow/.local/lib/python3.12/site-packages/airflow/utils/email.py", line 154, in send_email_smtp
    send_mime_email(e_from=mail_from, e_to=recipients, mime_msg=msg, conn_id=conn_id, dryrun=dryrun)
  File "/home/airflow/.local/lib/python3.12/site-packages/airflow/utils/email.py", line 273, in send_mime_email
    smtp_conn = _get_smtp_connection(smtp_host, smtp_port, smtp_timeout, smtp_ssl)
                ^^^^^^^^^^^^^^^^^^^^^^^^^^^^^^^^^^^^^^^^^^^^^^^^^^^^^^^^^^^^^^^^^^
  File "/home/airflow/.local/lib/python3.12/site-packages/airflow/utils/email.py", line 317, in _get_smtp_connection
    return smtplib.SMTP(host=host, port=port, timeout=timeout)
           ^^^^^^^^^^^^^^^^^^^^^^^^^^^^^^^^^^^^^^^^^^^^^^^^^^^
  File "/usr/local/lib/python3.12/smtplib.py", line 255, in __init__
    (code, msg) = self.connect(host, port)
                  ^^^^^^^^^^^^^^^^^^^^^^^^
  File "/usr/local/lib/python3.12/smtplib.py", line 341, in connect
    self.sock = self._get_socket(host, port, self.timeout)
                ^^^^^^^^^^^^^^^^^^^^^^^^^^^^^^^^^^^^^^^^^^
  File "/usr/local/lib/python3.12/smtplib.py", line 312, in _get_socket
    return socket.create_connection((host, port), timeout,
           ^^^^^^^^^^^^^^^^^^^^^^^^^^^^^^^^^^^^^^^^^^^^^^^
  File "/usr/local/lib/python3.12/socket.py", line 853, in create_connection
    raise exceptions[0]
  File "/usr/local/lib/python3.12/socket.py", line 838, in create_connection
    sock.connect(sa)
ConnectionRefusedError: [Errno 111] Connection refused
[2024-07-22T16:37:00.268+0000] {alerting.py:71} INFO - send alert mail to richmond.kongo@orange.com, assane.diop@orange.com, cyrille1.danho@orange.com, mohamed2.sylla@orange.com, amadou.diomande@orange.com, Jonas.kouame@orange.com, armand.kablan@orange.com, anicet.azombade@orange.com, etienne.kouadio@orange.com, bertine.kouakou@orange.com, florentine.kouakou@orange.com, ange.phaceli@orange.com, soulegame.soro@orange.com, innocent.yengo@orange.com
[2024-07-22T16:37:00.268+0000] {alerting.py:30} INFO - Sending mail ... 
[2024-07-22T16:37:00.268+0000] {alerting.py:38} ERROR - Failed to send email: please run connect() first
[2024-07-22T16:37:00.326+0000] {process_utils.py:80} INFO - Process psutil.Process(pid=416, status='terminated', exitcode=2, started='16:29:04') (416) terminated with exit code 2
