[2024-07-23T17:19:00.752+0000] {local_task_job_runner.py:120} INFO - ::group::Pre task execution logs
[2024-07-23T17:19:01.004+0000] {taskinstance.py:2076} INFO - Dependencies all met for dep_context=non-requeueable deps ti=<TaskInstance: enrich_prod.cleaning.cleaning_bdd manual__2024-07-23T17:18:57.112316+00:00 [queued]>
[2024-07-23T17:19:01.012+0000] {taskinstance.py:2076} INFO - Dependencies all met for dep_context=requeueable deps ti=<TaskInstance: enrich_prod.cleaning.cleaning_bdd manual__2024-07-23T17:18:57.112316+00:00 [queued]>
[2024-07-23T17:19:01.012+0000] {taskinstance.py:2306} INFO - Starting attempt 1 of 1
[2024-07-23T17:19:01.023+0000] {taskinstance.py:2330} INFO - Executing <Task(PythonOperator): cleaning.cleaning_bdd> on 2024-07-23 17:18:57.112316+00:00
[2024-07-23T17:19:01.034+0000] {warnings.py:112} WARNING - /home/***/.local/lib/python3.12/site-packages/***/task/task_runner/standard_task_runner.py:62: DeprecationWarning: This process (pid=540) is multi-threaded, use of fork() may lead to deadlocks in the child.
  pid = os.fork()

[2024-07-23T17:19:01.035+0000] {standard_task_runner.py:64} INFO - Started process 546 to run task
[2024-07-23T17:19:01.036+0000] {standard_task_runner.py:90} INFO - Running: ['***', 'tasks', 'run', 'enrich_prod', 'cleaning.cleaning_bdd', 'manual__2024-07-23T17:18:57.112316+00:00', '--job-id', '82', '--raw', '--subdir', 'DAGS_FOLDER/gps/custom_dags/enrich.py', '--cfg-path', '/tmp/tmpxfi63k6e']
[2024-07-23T17:19:01.037+0000] {standard_task_runner.py:91} INFO - Job 82: Subtask cleaning.cleaning_bdd
[2024-07-23T17:19:01.075+0000] {task_command.py:426} INFO - Running <TaskInstance: enrich_prod.cleaning.cleaning_bdd manual__2024-07-23T17:18:57.112316+00:00 [running]> on host 57f550887412
[2024-07-23T17:19:01.147+0000] {taskinstance.py:2648} INFO - Exporting env vars: AIRFLOW_CTX_DAG_EMAIL='richmond.kongo@orange.com,assane.diop@orange.com,cyrille1.danho@orange.com,mohamed2.sylla@orange.com,amadou.diomande@orange.com,Jonas.kouame@orange.com,armand.kablan@orange.com,anicet.azombade@orange.com,etienne.kouadio@orange.com,bertine.kouakou@orange.com,florentine.kouakou@orange.com,ange.phaceli@orange.com,soulegame.soro@orange.com,innocent.yengo@orange.com' AIRFLOW_CTX_DAG_OWNER='***' AIRFLOW_CTX_DAG_ID='enrich_prod' AIRFLOW_CTX_TASK_ID='cleaning.cleaning_bdd' AIRFLOW_CTX_EXECUTION_DATE='2024-07-23T17:18:57.112316+00:00' AIRFLOW_CTX_TRY_NUMBER='1' AIRFLOW_CTX_DAG_RUN_ID='manual__2024-07-23T17:18:57.112316+00:00'
[2024-07-23T17:19:01.148+0000] {taskinstance.py:430} INFO - ::endgroup::
[2024-07-23T17:19:01.164+0000] {cleaning.py:65} INFO - Reading BASE_SITES/BASE_SITES_202406.xlsx
[2024-07-23T17:19:01.165+0000] {cleaning.py:71} INFO -  Read file  BASE_SITES/BASE_SITES_202406.xlsx
[2024-07-23T17:19:01.178+0000] {rwminio.py:94} ERROR - Error reading data to Minio with error: Missing optional dependency 'openpyxl'.  Use pip or conda to install openpyxl.
[2024-07-23T17:19:01.179+0000] {cleaning.py:75} INFO - Checking columns
[2024-07-23T17:19:01.179+0000] {taskinstance.py:441} INFO - ::group::Post task execution logs
[2024-07-23T17:19:01.179+0000] {taskinstance.py:2905} ERROR - Task failed with exception
Traceback (most recent call last):
  File "/home/airflow/.local/lib/python3.12/site-packages/airflow/models/taskinstance.py", line 465, in _execute_task
    result = _execute_callable(context=context, **execute_callable_kwargs)
             ^^^^^^^^^^^^^^^^^^^^^^^^^^^^^^^^^^^^^^^^^^^^^^^^^^^^^^^^^^^^^
  File "/home/airflow/.local/lib/python3.12/site-packages/airflow/models/taskinstance.py", line 432, in _execute_callable
    return execute_callable(context=context, **execute_callable_kwargs)
           ^^^^^^^^^^^^^^^^^^^^^^^^^^^^^^^^^^^^^^^^^^^^^^^^^^^^^^^^^^^^
  File "/home/airflow/.local/lib/python3.12/site-packages/airflow/models/baseoperator.py", line 401, in wrapper
    return func(self, *args, **kwargs)
           ^^^^^^^^^^^^^^^^^^^^^^^^^^^
  File "/home/airflow/.local/lib/python3.12/site-packages/airflow/operators/python.py", line 235, in execute
    return_value = self.execute_callable()
                   ^^^^^^^^^^^^^^^^^^^^^^^
  File "/home/airflow/.local/lib/python3.12/site-packages/airflow/operators/python.py", line 252, in execute_callable
    return self.python_callable(*self.op_args, **self.op_kwargs)
           ^^^^^^^^^^^^^^^^^^^^^^^^^^^^^^^^^^^^^^^^^^^^^^^^^^^^^
  File "/opt/airflow/dags/gps/common/cleaning.py", line 77, in clean_base_sites
    check_columns(df_, required_cols)
  File "/opt/airflow/dags/gps/common/cleaning.py", line 20, in check_columns
    df_.columns = df_.columns.str.lower().str.strip().map(unidecode)
                  ^^^^^^^^^^^
AttributeError: 'NoneType' object has no attribute 'columns'
[2024-07-23T17:19:01.188+0000] {taskinstance.py:1206} INFO - Marking task as FAILED. dag_id=enrich_prod, task_id=cleaning.cleaning_bdd, run_id=manual__2024-07-23T17:18:57.112316+00:00, execution_date=20240723T171857, start_date=20240723T171901, end_date=20240723T171901
[2024-07-23T17:19:01.199+0000] {warnings.py:112} WARNING - /home/***/.local/lib/python3.12/site-packages/***/utils/email.py:154: RemovedInAirflow3Warning: Fetching SMTP credentials from configuration variables will be deprecated in a future release. Please set credentials using a connection instead.
  send_mime_email(e_from=mail_from, e_to=recipients, mime_msg=msg, conn_id=conn_id, dryrun=dryrun)

[2024-07-23T17:19:01.199+0000] {configuration.py:1053} WARNING - section/key [smtp/smtp_user] not found in config
[2024-07-23T17:19:01.199+0000] {email.py:271} INFO - Email alerting: attempt 1
[2024-07-23T17:19:01.205+0000] {configuration.py:1053} WARNING - section/key [smtp/smtp_user] not found in config
[2024-07-23T17:19:01.205+0000] {email.py:271} INFO - Email alerting: attempt 1
[2024-07-23T17:19:01.206+0000] {taskinstance.py:879} ERROR - Failed to send email to: ['richmond.kongo@orange.com', 'assane.diop@orange.com', 'cyrille1.danho@orange.com', 'mohamed2.sylla@orange.com', 'amadou.diomande@orange.com', 'Jonas.kouame@orange.com', 'armand.kablan@orange.com', 'anicet.azombade@orange.com', 'etienne.kouadio@orange.com', 'bertine.kouakou@orange.com', 'florentine.kouakou@orange.com', 'ange.phaceli@orange.com', 'soulegame.soro@orange.com', 'innocent.yengo@orange.com']
Traceback (most recent call last):
  File "/home/airflow/.local/lib/python3.12/site-packages/airflow/models/taskinstance.py", line 2479, in _run_raw_task
    self._execute_task_with_callbacks(context, test_mode, session=session)
  File "/home/airflow/.local/lib/python3.12/site-packages/airflow/models/taskinstance.py", line 2676, in _execute_task_with_callbacks
    result = self._execute_task(context, task_orig)
             ^^^^^^^^^^^^^^^^^^^^^^^^^^^^^^^^^^^^^^
  File "/home/airflow/.local/lib/python3.12/site-packages/airflow/models/taskinstance.py", line 2701, in _execute_task
    return _execute_task(self, context, task_orig)
           ^^^^^^^^^^^^^^^^^^^^^^^^^^^^^^^^^^^^^^^
  File "/home/airflow/.local/lib/python3.12/site-packages/airflow/models/taskinstance.py", line 465, in _execute_task
    result = _execute_callable(context=context, **execute_callable_kwargs)
             ^^^^^^^^^^^^^^^^^^^^^^^^^^^^^^^^^^^^^^^^^^^^^^^^^^^^^^^^^^^^^
  File "/home/airflow/.local/lib/python3.12/site-packages/airflow/models/taskinstance.py", line 432, in _execute_callable
    return execute_callable(context=context, **execute_callable_kwargs)
           ^^^^^^^^^^^^^^^^^^^^^^^^^^^^^^^^^^^^^^^^^^^^^^^^^^^^^^^^^^^^
  File "/home/airflow/.local/lib/python3.12/site-packages/airflow/models/baseoperator.py", line 401, in wrapper
    return func(self, *args, **kwargs)
           ^^^^^^^^^^^^^^^^^^^^^^^^^^^
  File "/home/airflow/.local/lib/python3.12/site-packages/airflow/operators/python.py", line 235, in execute
    return_value = self.execute_callable()
                   ^^^^^^^^^^^^^^^^^^^^^^^
  File "/home/airflow/.local/lib/python3.12/site-packages/airflow/operators/python.py", line 252, in execute_callable
    return self.python_callable(*self.op_args, **self.op_kwargs)
           ^^^^^^^^^^^^^^^^^^^^^^^^^^^^^^^^^^^^^^^^^^^^^^^^^^^^^
  File "/opt/airflow/dags/gps/common/cleaning.py", line 77, in clean_base_sites
    check_columns(df_, required_cols)
  File "/opt/airflow/dags/gps/common/cleaning.py", line 20, in check_columns
    df_.columns = df_.columns.str.lower().str.strip().map(unidecode)
                  ^^^^^^^^^^^
AttributeError: 'NoneType' object has no attribute 'columns'

During handling of the above exception, another exception occurred:

Traceback (most recent call last):
  File "/home/airflow/.local/lib/python3.12/site-packages/airflow/models/taskinstance.py", line 1063, in _email_alert
    send_email(task.email, subject, html_content)
  File "/home/airflow/.local/lib/python3.12/site-packages/airflow/utils/email.py", line 80, in send_email
    return backend(
           ^^^^^^^^
  File "/home/airflow/.local/lib/python3.12/site-packages/airflow/utils/email.py", line 154, in send_email_smtp
    send_mime_email(e_from=mail_from, e_to=recipients, mime_msg=msg, conn_id=conn_id, dryrun=dryrun)
  File "/home/airflow/.local/lib/python3.12/site-packages/airflow/utils/email.py", line 273, in send_mime_email
    smtp_conn = _get_smtp_connection(smtp_host, smtp_port, smtp_timeout, smtp_ssl)
                ^^^^^^^^^^^^^^^^^^^^^^^^^^^^^^^^^^^^^^^^^^^^^^^^^^^^^^^^^^^^^^^^^^
  File "/home/airflow/.local/lib/python3.12/site-packages/airflow/utils/email.py", line 317, in _get_smtp_connection
    return smtplib.SMTP(host=host, port=port, timeout=timeout)
           ^^^^^^^^^^^^^^^^^^^^^^^^^^^^^^^^^^^^^^^^^^^^^^^^^^^
  File "/usr/local/lib/python3.12/smtplib.py", line 255, in __init__
    (code, msg) = self.connect(host, port)
                  ^^^^^^^^^^^^^^^^^^^^^^^^
  File "/usr/local/lib/python3.12/smtplib.py", line 341, in connect
    self.sock = self._get_socket(host, port, self.timeout)
                ^^^^^^^^^^^^^^^^^^^^^^^^^^^^^^^^^^^^^^^^^^
  File "/usr/local/lib/python3.12/smtplib.py", line 312, in _get_socket
    return socket.create_connection((host, port), timeout,
           ^^^^^^^^^^^^^^^^^^^^^^^^^^^^^^^^^^^^^^^^^^^^^^^
  File "/usr/local/lib/python3.12/socket.py", line 853, in create_connection
    raise exceptions[0]
  File "/usr/local/lib/python3.12/socket.py", line 838, in create_connection
    sock.connect(sa)
ConnectionRefusedError: [Errno 111] Connection refused

During handling of the above exception, another exception occurred:

Traceback (most recent call last):
  File "/home/airflow/.local/lib/python3.12/site-packages/airflow/models/taskinstance.py", line 877, in _handle_failure
    task_instance.email_alert(error, failure_context["task"])
  File "/home/airflow/.local/lib/python3.12/site-packages/airflow/models/taskinstance.py", line 3163, in email_alert
    _email_alert(task_instance=self, exception=exception, task=task)
  File "/home/airflow/.local/lib/python3.12/site-packages/airflow/models/taskinstance.py", line 1065, in _email_alert
    send_email(task.email, subject, html_content_err)
  File "/home/airflow/.local/lib/python3.12/site-packages/airflow/utils/email.py", line 80, in send_email
    return backend(
           ^^^^^^^^
  File "/home/airflow/.local/lib/python3.12/site-packages/airflow/utils/email.py", line 154, in send_email_smtp
    send_mime_email(e_from=mail_from, e_to=recipients, mime_msg=msg, conn_id=conn_id, dryrun=dryrun)
  File "/home/airflow/.local/lib/python3.12/site-packages/airflow/utils/email.py", line 273, in send_mime_email
    smtp_conn = _get_smtp_connection(smtp_host, smtp_port, smtp_timeout, smtp_ssl)
                ^^^^^^^^^^^^^^^^^^^^^^^^^^^^^^^^^^^^^^^^^^^^^^^^^^^^^^^^^^^^^^^^^^
  File "/home/airflow/.local/lib/python3.12/site-packages/airflow/utils/email.py", line 317, in _get_smtp_connection
    return smtplib.SMTP(host=host, port=port, timeout=timeout)
           ^^^^^^^^^^^^^^^^^^^^^^^^^^^^^^^^^^^^^^^^^^^^^^^^^^^
  File "/usr/local/lib/python3.12/smtplib.py", line 255, in __init__
    (code, msg) = self.connect(host, port)
                  ^^^^^^^^^^^^^^^^^^^^^^^^
  File "/usr/local/lib/python3.12/smtplib.py", line 341, in connect
    self.sock = self._get_socket(host, port, self.timeout)
                ^^^^^^^^^^^^^^^^^^^^^^^^^^^^^^^^^^^^^^^^^^
  File "/usr/local/lib/python3.12/smtplib.py", line 312, in _get_socket
    return socket.create_connection((host, port), timeout,
           ^^^^^^^^^^^^^^^^^^^^^^^^^^^^^^^^^^^^^^^^^^^^^^^
  File "/usr/local/lib/python3.12/socket.py", line 853, in create_connection
    raise exceptions[0]
  File "/usr/local/lib/python3.12/socket.py", line 838, in create_connection
    sock.connect(sa)
ConnectionRefusedError: [Errno 111] Connection refused
[2024-07-23T17:19:01.209+0000] {alerting.py:71} INFO - send alert mail to richmond.kongo@orange.com, assane.diop@orange.com, cyrille1.danho@orange.com, mohamed2.sylla@orange.com, amadou.diomande@orange.com, Jonas.kouame@orange.com, armand.kablan@orange.com, anicet.azombade@orange.com, etienne.kouadio@orange.com, bertine.kouakou@orange.com, florentine.kouakou@orange.com, ange.phaceli@orange.com, soulegame.soro@orange.com, innocent.yengo@orange.com
[2024-07-23T17:19:01.209+0000] {alerting.py:30} INFO - Sending mail ... 
[2024-07-23T17:19:01.209+0000] {alerting.py:38} ERROR - Failed to send email: please run connect() first
[2024-07-23T17:19:01.220+0000] {standard_task_runner.py:110} ERROR - Failed to execute job 82 for task cleaning.cleaning_bdd ('NoneType' object has no attribute 'columns'; 546)
[2024-07-23T17:19:01.248+0000] {local_task_job_runner.py:243} INFO - Task exited with return code 1
[2024-07-23T17:19:01.258+0000] {local_task_job_runner.py:222} INFO - ::endgroup::
